Workbook
Name per: DATA!#REF!
Name per: #REF!
Name Relative: PERIODS!$C$4:$C$45

Sheet IPCA
S2: CENTRAL BANK - FOCUS MARKET READOUT
S4: ="Annual IPCA " -> Annual IPCA | V4: ="Monthly IPCA " -> Monthly IPCA
B5: Date | C5: =TODAY() -> 45829 | F5: SELECT CURVES | M5: SELECT DATA TYPE | S5: =YEAR(TODAY()) -> 2025 | T5: =IF(ISERROR(_xll.BDP("FCBRPA Index","px last")/100),"-",_xll.BDP("FCBRPA Index","px last")/100) -> 0.0525 | V5: =YEAR($C$5) -> 2025 | W5: =IF(ISERROR(_xll.BDP("FCBRMA Index","px last")/100),"-",_xll.BDP("FCBRMA Index","px last")/100) -> 0.0027
G6: Click on the tickers to select your curve. | S6: 12M | T6: =IF(ISERROR(_xll.BDP("FCBRPC12 Index","px last")/100),"-",_xll.BDP("FCBRPC12 Index","px last")/100) -> 0.0472 | V6: =V5+1 -> 2026 | W6: =T6/12 -> 0.0039333333
B7: Latest update | C7: =DATA!$U$6 -> 45828 | F7: A | G7: YCSW0089 Index | H7: =VLOOKUP(G7,DATA!T9:X10,2,0) -> BM&F Pre x DI Curve | M7: TENOR | O7: End of Month | S7: 24M | T7: =IF(ISERROR(_xll.BDP("FCBRPC13 Index","px last")/100),"-",_xll.BDP("FCBRPC13 Index","px last")/100) -> 0.0373 | V7: =V6+1 -> 2027 | W7: =T7/12 -> 0.0031083333
M8: Select the type of frequency.
B9: IPCA Index | C9: =CALC!F5 -> 7295.46 | F9: B | G9: WLA Index | H9: =VLOOKUP(G9,DATA!T16:X18,2,0) -> ID x IPCA Spread Futures | M9: RATE* | O9: Annualized
M10: *Applies only to the table view.
B11: ANBIMA Index | C11: =CALC!G5 -> 7295.46 | S11: INFLATION PRICE INDICES
S13: IPCA | V13: IGP-M
S14: IPCA YoY | T14: =IF(ISERROR(_xll.BDP("BZPIIPCY Index","px last")/100),"-",_xll.BDP("BZPIIPCY Index","px last")/100) -> 0.0532 | V14: IGP-M YoY | W14: =IF(ISERROR(_xll.BDP("IBREGPMY Index","px last")/100),"-",_xll.BDP("IBREGPMY Index","px last")/100) -> 0.0702
S15: IPCA MoM | T15: =IF(ISERROR(_xll.BDP("BZPIIPCM Index","px last")/100),"-",_xll.BDP("BZPIIPCM Index","px last")/100) -> 0.0026 | V15: IGP-M MoM | W15: =IF(ISERROR(_xll.BDP("IBREGPMM Index","px last")/100),"-",_xll.BDP("IBREGPMM Index","px last")/100) -> -0.0049
S17: IGP-DI | V17: INPC
S18: IGP-DI MoM | T18: =IF(ISERROR(_xll.BDP("IBREGPDM Index","px last")/100),"-",_xll.BDP("IBREGPDM Index","px last")/100) -> -0.0085 | V18: INPC MoM | W18: =IF(ISERROR(_xll.BDP("BZPIINPM Index","px last")/100),"-",_xll.BDP("BZPIINPM Index","px last")/100) -> 0.0035
S19: IGP-DI YoY | T19: =IF(ISERROR(_xll.BDP("IBREGPDY Index","px last")/100),"-",_xll.BDP("IBREGPDY Index","px last")/100) -> 0.0627 | V19: INPC YoY | W19: =IF(ISERROR(_xll.BDP("BZPIINPY Index","px last")/100),"-",_xll.BDP("BZPIINPY Index","px last")/100) -> 0.052
S21: IPC | V21: IPC / FIPE
S22: IPC MoM | T22: =IF(ISERROR(_xll.BDP("IBREPCDM Index","px last")/100),"-",_xll.BDP("IBREPCDM Index","px last")/100) -> 0.0034 | V22: IPC/FIPE MoM | W22: =IF(ISERROR(_xll.BDP("BZCPI Index","px last")/100),"-",_xll.BDP("BZCPI Index","px last")/100) -> 0.0027
S23: IPC YoY | T23: =IF(ISERROR(_xll.BDP("IBREPCMY Index","px last")/100),"-",_xll.BDP("IBREPCMY Index","px last")/100) -> 0.0457 | V23: IPC/FIPE YoY | W23: =IF(ISERROR(_xll.BDP("BZW CPI Index","px last")/100),"-",_xll.BDP("BZW CPI Index","px last")/100) -> 0.0008
S25: IMPLIED INFLATION CURVE ANALYSIS
S27: =CALC!C7 -> Tenor | T27: Curve A | V27: Curve B | W27: Imp. Inflation
S28: =CALC!C8 -> 2025-07-30 | T28: =DATA!I7 -> 14.905143 | V28: =DATA!R7 -> 12.421827 | W28: =_xlfn.IFS($O$9=DATA!$T$34,CALC!H8,IPCA!$O$9=DATA!$T$33,CALC!E8/100) -> 0.022089267
S29: =CALC!C9 -> 2025-08-29 | T29: =DATA!I8 -> 14.933 | V29: =DATA!R8 -> 11.758117 | W29: =_xlfn.IFS($O$9=DATA!$T$34,CALC!H9,IPCA!$O$9=DATA!$T$33,CALC!E9/100) -> 0.028408526
S30: =CALC!C10 -> 2025-09-30 | T30: =DATA!I9 -> 14.947 | V30: =DATA!R9 -> 10.6457 | W30: =_xlfn.IFS($O$9=DATA!$T$34,CALC!H10,IPCA!$O$9=DATA!$T$33,CALC!E10/100) -> 0.038874531
S31: =CALC!C11 -> 2025-10-30 | T31: =DATA!I10 -> 14.954852 | V31: =DATA!R10 -> 10.64822 | W31: =_xlfn.IFS($O$9=DATA!$T$34,CALC!H11,IPCA!$O$9=DATA!$T$33,CALC!E11/100) -> 0.038921838
S32: =CALC!C12 -> 2025-11-28 | T32: =DATA!I11 -> 14.955 | V32: =DATA!R11 -> 10.463594 | W32: =_xlfn.IFS($O$9=DATA!$T$34,CALC!H12,IPCA!$O$9=DATA!$T$33,CALC!E12/100) -> 0.0406596
S33: =CALC!C13 -> 2025-12-30 | T33: =DATA!I12 -> 14.958 | V33: =DATA!R12 -> 10.369619 | W33: =_xlfn.IFS($O$9=DATA!$T$34,CALC!H13,IPCA!$O$9=DATA!$T$33,CALC!E13/100) -> 0.041572862
S34: =CALC!C14 -> 2026-01-30 | T34: =DATA!I13 -> 14.96 | V34: =DATA!R13 -> 10.22527 | W34: =_xlfn.IFS($O$9=DATA!$T$34,CALC!H14,IPCA!$O$9=DATA!$T$33,CALC!E14/100) -> 0.042955033
S35: =CALC!C15 -> 2026-02-27 | T35: =DATA!I14 -> 14.955 | V35: =DATA!R14 -> 10.137143 | W35: =_xlfn.IFS($O$9=DATA!$T$34,CALC!H15,IPCA!$O$9=DATA!$T$33,CALC!E15/100) -> 0.04374416
S36: =CALC!C16 -> 2026-03-30 | T36: =DATA!I15 -> 14.926749 | V36: =DATA!R15 -> 10.063334 | W36: =_xlfn.IFS($O$9=DATA!$T$34,CALC!H16,IPCA!$O$9=DATA!$T$33,CALC!E16/100) -> 0.044187421
S37: =CALC!C17 -> 2026-04-30 | T37: =DATA!I16 -> 14.885 | V37: =DATA!R16 -> 10.011454 | W37: =_xlfn.IFS($O$9=DATA!$T$34,CALC!H17,IPCA!$O$9=DATA!$T$33,CALC!E17/100) -> 0.044300347
S38: =CALC!C18 -> 2026-05-29 | T38: =DATA!I17 -> 14.833 | V38: =DATA!R17 -> 9.973491 | W38: =_xlfn.IFS($O$9=DATA!$T$34,CALC!H18,IPCA!$O$9=DATA!$T$33,CALC!E18/100) -> 0.044188003
S39: =CALC!C19 -> 2026-06-30 | T39: =DATA!I18 -> 14.773 | V39: =DATA!R18 -> 9.9362588 | W39: =_xlfn.IFS($O$9=DATA!$T$34,CALC!H19,IPCA!$O$9=DATA!$T$33,CALC!E19/100) -> 0.043995869
... S47: =CALC!C27 -> 2027-02-26 | T47: =DATA!I26 -> 14.149373 | V47: =DATA!R26 -> 9.1314192 | W47: =_xlfn.IFS($O$9=DATA!$T$34,CALC!H27,IPCA!$O$9=DATA!$T$33,CALC!E27/100) -> 0.045980838
B48: =CURVES!H1 -> ANBIMA | S48: =CALC!C28 -> 2027-03-30 | T48: =DATA!I27 -> 14.082272 | V48: =DATA!R27 -> 8.9822195 | W48: =_xlfn.IFS($O$9=DATA!$T$34,CALC!H28,IPCA!$O$9=DATA!$T$33,CALC!E28/100) -> 0.04679711
S49: =CALC!C29 -> 2027-04-30 | T49: =DATA!I28 -> 14.008389 | V49: =DATA!R28 -> 8.8331308 | W49: =_xlfn.IFS($O$9=DATA!$T$34,CALC!H29,IPCA!$O$9=DATA!$T$33,CALC!E29/100) -> 0.047552227
B50: =CURVES!H2 -> BD | C50: =CURVES!I2 -> ETTJ Pre | D50: =CURVES!K2 -> ETTJ IPCA | E50: =CURVES!M2 -> Imp Inflation | S50: =CALC!C30 -> 2027-05-28 | T50: =DATA!I29 -> 13.944271 | V50: =DATA!R29 -> 8.7164542 | W50: =_xlfn.IFS($O$9=DATA!$T$34,CALC!H30,IPCA!$O$9=DATA!$T$33,CALC!E30/100) -> 0.048086713
B51: =CURVES!H3 -> 126 | C51: =CURVES!J3 -> 15.0421 | D51: =CURVES!L3 -> 11.5598 | E51: =CURVES!M3 -> 3.1214649 | S51: =CALC!C31 -> 2027-06-30 | T51: =DATA!I30 -> 13.872 | V51: =DATA!R30 -> 8.5934877 | W51: =_xlfn.IFS($O$9=DATA!$T$34,CALC!H31,IPCA!$O$9=DATA!$T$33,CALC!E31/100) -> 0.048608
B52: =CURVES!H4 -> 252 | C52: =CURVES!J4 -> 14.7379 | D52: =CURVES!L4 -> 10.231 | E52: =CURVES!M4 -> 4.0885958 | S52: =CALC!C32 -> 2027-07-30 | T52: =DATA!I31 -> 13.812354 | V52: =DATA!R31 -> 8.4931214 | W52: =_xlfn.IFS($O$9=DATA!$T$34,CALC!H32,IPCA!$O$9=DATA!$T$33,CALC!E32/100) -> 0.049028292
B53: =CURVES!H5 -> 504 | C53: =CURVES!J5 -> 13.8657 | D53: =CURVES!L5 -> 8.5642 | E53: =CURVES!M5 -> 4.8832857 | S53: =CALC!C33 -> 2027-08-30 | T53: =DATA!I32 -> 13.761009 | V53: =DATA!R32 -> 8.4114867 | W53: =_xlfn.IFS($O$9=DATA!$T$34,CALC!H33,IPCA!$O$9=DATA!$T$33,CALC!E33/100) -> 0.049344607
B54: =CURVES!H6 -> 756 | C54: =CURVES!J6 -> 13.5352 | D54: =CURVES!L6 -> 7.9858 | E54: =CURVES!M6 -> 5.139009 | S54: =CALC!C34 -> 2027-09-30 | T54: =DATA!I33 -> 13.708 | V54: =DATA!R33 -> 8.3391908 | W54: =_xlfn.IFS($O$9=DATA!$T$34,CALC!H34,IPCA!$O$9=DATA!$T$33,CALC!E34/100) -> 0.049555559
...

Sheet Comparison
B7: CUSTOMIZED DATES: | L7: CURVES
B9: Date 1 | C9: 45268 | E9: IPCA Index | F9: =CALC!$N$5 -> #N/A Requesting Data... | H9: ANBIMA Index | I9: =CALC!$O$5 -> 6716.74 | L9: A | M9: =IPCA!H7 -> BM&F Pre x DI Curve
B11: Date 2 | C11: 45085 | E11: IPCA Index | F11: =CALC!$V$5 -> 6665.28 | H11: ANBIMA Index | I11: =CALC!$W$5 -> 6649.99 | L11: B | M11: =IPCA!H9 -> ID x IPCA Spread Futures
B12: *Set your custom dates
U14: IMPLIED INFLATION CURVE ANALYSIS
U16: ="A Curve as of date: "&_xll.BQL.DATE(DATA!$U$4) -> A Curve as of date: 2023-12-08 | Z16: ="B Curve as of date: "&_xll.BQL.DATE(DATA!$U$5) -> B Curve as of date: 2023-06-07
U18: =CALC!L7 -> Tenor | V18: Curve A | W18: Curve B | X18: Implied | Z18: =CALC!U7 -> Tenor | AA18: Curve A | AB18: Curve B | AC18: Implied
U19: =CALC!L8 -> 2024-01-31 | V19: =DATA!I66 -> 11.699 | W19: =DATA!R66 -> 6.7550594 | X19: =_xlfn.IFS(IPCA!$O$9=DATA!$T$34,CALC!Q8,IPCA!$O$9=DATA!$T$33,CALC!N8/100) -> 0.046311066 | Z19: =CALC!U8 -> 2023-07-28 | AA19: =DATA!I126 -> 13.635495 | AB19: =DATA!R126 -> 12.28583 | AC19: =_xlfn.IFS(IPCA!$O$9=DATA!$T$34,CALC!Z8,IPCA!$O$9=DATA!$T$33,CALC!W8/100) -> 0.012019898
U20: =CALC!L9 -> 2024-02-29 | V20: =DATA!I67 -> 11.504 | W20: =DATA!R67 -> 6.257616 | X20: =_xlfn.IFS(IPCA!$O$9=DATA!$T$34,CALC!Q9,IPCA!$O$9=DATA!$T$33,CALC!N9/100) -> 0.049374192 | Z20: =CALC!U9 -> 2023-08-30 | AA20: =DATA!I127 -> 13.568859 | AB20: =DATA!R127 -> 9.1070385 | AC20: =_xlfn.IFS(IPCA!$O$9=DATA!$T$34,CALC!Z9,IPCA!$O$9=DATA!$T$33,CALC!W9/100) -> 0.040893974
U21: =CALC!L10 -> 2024-03-28 | V21: =DATA!I68 -> 11.374 | W21: =DATA!R68 -> 6.2195967 | X21: =_xlfn.IFS(IPCA!$O$9=DATA!$T$34,CALC!Q10,IPCA!$O$9=DATA!$T$33,CALC!N10/100) -> 0.048525916 | Z21: =CALC!U10 -> 2023-09-29 | AA21: =DATA!I128 -> 13.484 | AB21: =DATA!R128 -> 7.7554755 | AC21: =_xlfn.IFS(IPCA!$O$9=DATA!$T$34,CALC!Z10,IPCA!$O$9=DATA!$T$33,CALC!W10/100) -> 0.053162259
U22: =CALC!L11 -> 2024-04-30 | V22: =DATA!I69 -> 11.199 | W22: =DATA!R69 -> 6.4582085 | X22: =_xlfn.IFS(IPCA!$O$9=DATA!$T$34,CALC!Q11,IPCA!$O$9=DATA!$T$33,CALC!N11/100) -> 0.044531949 | Z22: =CALC!U11 -> 2023-10-30 | AA22: =DATA!I129 -> 13.390864 | AB22: =DATA!R129 -> 7.5827876 | AC22: =_xlfn.IFS(IPCA!$O$9=DATA!$T$34,CALC!Z11,IPCA!$O$9=DATA!$T$33,CALC!W11/100) -> 0.053987039
U23: =CALC!L12 -> 2024-05-31 | V23: =DATA!I70 -> 11.045 | W23: =DATA!R70 -> 6.5053035 | X23: =_xlfn.IFS(IPCA!$O$9=DATA!$T$34,CALC!Q12,IPCA!$O$9=DATA!$T$33,CALC!N12/100) -> 0.042624135 | Z23: =CALC!U12 -> 2023-11-30 | AA23: =DATA!I130 -> 13.242 | AB23: =DATA!R130 -> 8.1077529 | AC23: =_xlfn.IFS(IPCA!$O$9=DATA!$T$34,CALC!Z12,IPCA!$O$9=DATA!$T$33,CALC!W12/100) -> 0.047491942
U24: =CALC!L13 -> 2024-06-28 | V24: =DATA!I71 -> 10.91 | W24: =DATA!R71 -> 6.6082678 | X24: =_xlfn.IFS(IPCA!$O$9=DATA!$T$34,CALC!Q13,IPCA!$O$9=DATA!$T$33,CALC!N13/100) -> 0.040350831 | Z24: =CALC!U13 -> 2023-12-29 | AA24: =DATA!I131 -> 13.088494 | AB24: =DATA!R131 -> 8.8456414 | AC24: =_xlfn.IFS(IPCA!$O$9=DATA!$T$34,CALC!Z13,IPCA!$O$9=DATA!$T$33,CALC!W13/100) -> 0.038980453
U25: =CALC!L14 -> 2024-07-31 | V25: =DATA!I72 -> 10.769 | W25: =DATA!R72 -> 6.7093396 | X25: =_xlfn.IFS(IPCA!$O$9=DATA!$T$34,CALC!Q14,IPCA!$O$9=DATA!$T$33,CALC!N14/100) -> 0.038044096 | Z25: =CALC!U14 -> 2024-01-30 | AA25: =DATA!I132 -> 12.931685 | AB25: =DATA!R132 -> 9.423746 | AC25: =_xlfn.IFS(IPCA!$O$9=DATA!$T$34,CALC!Z14,IPCA!$O$9=DATA!$T$33,CALC!W14/100) -> 0.032058301
U26: =CALC!L15 -> 2024-08-30 | V26: =DATA!I73 -> 10.665 | W26: =DATA!R73 -> 6.6917199 | X26: =_xlfn.IFS(IPCA!$O$9=DATA!$T$34,CALC!Q15,IPCA!$O$9=DATA!$T$33,CALC!N15/100) -> 0.037240754 | Z26: =CALC!U15 -> 2024-02-29 | AA26: =DATA!I133 -> 12.771 | AB26: =DATA!R133 -> 9.6326028 | AC26: =_xlfn.IFS(IPCA!$O$9=DATA!$T$34,CALC!Z15,IPCA!$O$9=DATA!$T$33,CALC!W15/100) -> 0.028626496
U27: =CALC!L16 -> 2024-09-30 | V27: =DATA!I74 -> 10.574 | W27: =DATA!R74 -> 6.5528459 | X27: =_xlfn.IFS(IPCA!$O$9=DATA!$T$34,CALC!Q16,IPCA!$O$9=DATA!$T$33,CALC!N16/100) -> 0.03773859 | Z27: =CALC!U16 -> 2024-03-28 | AA27: =DATA!I134 -> 12.602 | AB27: =DATA!R134 -> 9.5700988 | AC27: =_xlfn.IFS(IPCA!$O$9=DATA!$T$34,CALC!Z16,IPCA!$O$9=DATA!$T$33,CALC!W16/100) -> 0.027670881
U28: =CALC!L17 -> 2024-10-31 | V28: =DATA!I75 -> 10.487 | W28: =DATA!R75 -> 6.3199466 | X28: =_xlfn.IFS(IPCA!$O$9=DATA!$T$34,CALC!Q17,IPCA!$O$9=DATA!$T$33,CALC!N17/100) -> 0.039193525 | Z28: =CALC!U17 -> 2024-04-30 | AA28: =DATA!I135 -> 12.416 | AB28: =DATA!R135 -> 9.2687679 | AC28: =_xlfn.IFS(IPCA!$O$9=DATA!$T$34,CALC!Z17,IPCA!$O$9=DATA!$T$33,CALC!W17/100) -> 0.028802668
U29: =CALC!L18 -> 2024-11-29 | V29: =DATA!I76 -> 10.42 | W29: =DATA!R76 -> 6.1079534 | X29: =_xlfn.IFS(IPCA!$O$9=DATA!$T$34,CALC!Q18,IPCA!$O$9=DATA!$T$33,CALC!N18/100) -> 0.040638297 | Z29: =CALC!U18 -> 2024-05-29 | AA29: =DATA!I136 -> 12.243511 | AB29: =DATA!R136 -> 8.8568929 | AC29: =_xlfn.IFS(IPCA!$O$9=DATA!$T$34,CALC!Z18,IPCA!$O$9=DATA!$T$33,CALC!W18/100) -> 0.031110738
U30: =CALC!L19 -> 2024-12-31 | V30: =DATA!I77 -> 10.356591 | W30: =DATA!R77 -> 5.8994528 | X30: =_xlfn.IFS(IPCA!$O$9=DATA!$T$34,CALC!Q19,IPCA!$O$9=DATA!$T$33,CALC!N19/100) -> 0.042088397 | Z30: =CALC!U19 -> 2024-06-28 | AA30: =DATA!I137 -> 12.070528 | AB30: =DATA!R137 -> 8.3595856 | AC30: =_xlfn.IFS(IPCA!$O$9=DATA!$T$34,CALC!Z19,IPCA!$O$9=DATA!$T$33,CALC!W19/100) -> 0.034246551
... U44: =CALC!L33 -> 2026-02-27 | V44: =DATA!I91 -> 10.013637 | W44: =DATA!R91 -> 5.75 | X44: =_xlfn.IFS(IPCA!$O$9=DATA!$T$34,CALC!Q33,IPCA!$O$9=DATA!$T$33,CALC!N33/100) -> 0.040318084 | Z44: =CALC!U33 -> 2025-08-29 | AA44: =DATA!I151 -> 10.789581 | AB44: =DATA!R151 -> 6.79 | AC44: =_xlfn.IFS(IPCA!$O$9=DATA!$T$34,CALC!Z33,IPCA!$O$9=DATA!$T$33,CALC!W33/100) -> 0.037452771
B45: ="*annualized rate spread: (Date 1: "&_xll.BQL.DATE(DATA!U4)&" - Date 2: "&_xll.BQL.DATE(DATA!U5)&")" -> *annualized rate spread: (Date 1: 2023-12-08 - Date 2: 2023-06-07) | U45: =CALC!L34 -> 2026-03-31 | V45: =DATA!I92 -> 10.026 | W45: =DATA!R92 -> 5.75 | X45: =_xlfn.IFS(IPCA!$O$9=DATA!$T$34,CALC!Q34,IPCA!$O$9=DATA!$T$33,CALC!N34/100) -> 0.040434988 | Z45: =CALC!U34 -> 2025-09-30 | AA45: =DATA!I152 -> 10.75 | AB45: =DATA!R152 -> 6.79 | AC45: =_xlfn.IFS(IPCA!$O$9=DATA!$T$34,CALC!Z34,IPCA!$O$9=DATA!$T$33,CALC!W34/100) -> 0.037082124
U46: =CALC!L35 -> 2026-04-30 | V46: =DATA!I93 -> 10.035384 | W46: =DATA!R93 -> 5.75 | X46: =_xlfn.IFS(IPCA!$O$9=DATA!$T$34,CALC!Q35,IPCA!$O$9=DATA!$T$33,CALC!N35/100) -> 0.040523725 | Z46: =CALC!U35 -> 2025-10-30 | AA46: =DATA!I153 -> 10.704909 | AB46: =DATA!R153 -> 6.79 | AC46: =_xlfn.IFS(IPCA!$O$9=DATA!$T$34,CALC!Z35,IPCA!$O$9=DATA!$T$33,CALC!W35/100) -> 0.036659884
U47: =CALC!L36 -> 2026-05-29 | V47: =DATA!I94 -> 10.043948 | W47: =DATA!R94 -> 5.75 | X47: =_xlfn.IFS(IPCA!$O$9=DATA!$T$34,CALC!Q36,IPCA!$O$9=DATA!$T$33,CALC!N36/100) -> 0.04060471 | Z47: =CALC!U36 -> 2025-11-28 | AA47: =DATA!I154 -> 10.665543 | AB47: =DATA!R154 -> 6.79 | AC47: =_xlfn.IFS(IPCA!$O$9=DATA!$T$34,CALC!Z36,IPCA!$O$9=DATA!$T$33,CALC!W36/100) -> 0.036291258
U48: =CALC!L37 -> 2026-06-30 | V48: =DATA!I95 -> 10.055 | W48: =DATA!R95 -> 5.75 | X48: =_xlfn.IFS(IPCA!$O$9=DATA!$T$34,CALC!Q37,IPCA!$O$9=DATA!$T$33,CALC!N37/100) -> 0.04070922 | Z48: =CALC!U37 -> 2025-12-30 | AA48: =DATA!I155 -> 10.635 | AB48: =DATA!R155 -> 6.79 | AC48: =_xlfn.IFS(IPCA!$O$9=DATA!$T$34,CALC!Z37,IPCA!$O$9=DATA!$T$33,CALC!W37/100) -> 0.036005244
U49: =CALC!L38 -> 2026-07-31 | V49: =DATA!I96 -> 10.071435 | W49: =DATA!R96 -> 5.75 | X49: =_xlfn.IFS(IPCA!$O$9=DATA!$T$34,CALC!Q38,IPCA!$O$9=DATA!$T$33,CALC!N38/100) -> 0.040864636 | Z49: =CALC!U38 -> 2026-01-30 | AA49: =DATA!I156 -> 10.621376 | AB49: =DATA!R156 -> 6.79 | AC49: =_xlfn.IFS(IPCA!$O$9=DATA!$T$34,CALC!Z38,IPCA!$O$9=DATA!$T$33,CALC!W38/100) -> 0.03587767
U50: =CALC!L39 -> 2026-08-31 | V50: =DATA!I97 -> 10.086589 | W50: =DATA!R97 -> 5.75 | X50: =_xlfn.IFS(IPCA!$O$9=DATA!$T$34,CALC!Q39,IPCA!$O$9=DATA!$T$33,CALC!N39/100) -> 0.041007929 | Z50: =CALC!U39 -> 2026-02-27 | AA50: =DATA!I157 -> 10.619572 | AB50: =DATA!R157 -> 6.79 | AC50: =_xlfn.IFS(IPCA!$O$9=DATA!$T$34,CALC!Z39,IPCA!$O$9=DATA!$T$33,CALC!W39/100) -> 0.035860777
U51: =CALC!L40 -> 2026-09-30 | V51: =DATA!I98 -> 10.097 | W51: =DATA!R98 -> 5.75 | X51: =_xlfn.IFS(IPCA!$O$9=DATA!$T$34,CALC!Q40,IPCA!$O$9=DATA!$T$33,CALC!N40/100) -> 0.041106383 | Z51: =CALC!U40 -> 2026-03-30 | AA51: =DATA!I158 -> 10.62005 | AB51: =DATA!R158 -> 6.79 | AC51: =_xlfn.IFS(IPCA!$O$9=DATA!$T$34,CALC!Z40,IPCA!$O$9=DATA!$T$33,CALC!W40/100) -> 0.035865246
U52: =CALC!L41 -> 2026-10-30 | V52: =DATA!I99 -> 10.100081 | W52: =DATA!R99 -> 5.75 | X52: =_xlfn.IFS(IPCA!$O$9=DATA!$T$34,CALC!Q41,IPCA!$O$9=DATA!$T$33,CALC!N41/100) -> 0.041135517 | Z52: =CALC!U41 -> 2026-04-30 | AA52: =DATA!I159 -> 10.616865 | AB52: =DATA!R159 -> 6.79 | AC52: =_xlfn.IFS(IPCA!$O$9=DATA!$T$34,CALC!Z41,IPCA!$O$9=DATA!$T$33,CALC!W41/100) -> 0.035835425
U53: =CALC!L42 -> 2026-11-30 | V53: =DATA!I100 -> 10.101485 | W53: =DATA!R100 -> 5.75 | X53: =_xlfn.IFS(IPCA!$O$9=DATA!$T$34,CALC!Q42,IPCA!$O$9=DATA!$T$33,CALC!N42/100) -> 0.041148791 | Z53: =CALC!U42 -> 2026-05-29 | AA53: =DATA!I160 -> 10.612887 | AB53: =DATA!R160 -> 6.79 | AC53: =_xlfn.IFS(IPCA!$O$9=DATA!$T$34,CALC!Z42,IPCA!$O$9=DATA!$T$33,CALC!W42/100) -> 0.035798169
U54: =CALC!L43 -> 2026-12-31 | V54: =DATA!I101 -> 10.109646 | W54: =DATA!R101 -> 5.75 | X54: =_xlfn.IFS(IPCA!$O$9=DATA!$T$34,CALC!Q43,IPCA!$O$9=DATA!$T$33,CALC!N43/100) -> 0.041225964 | Z54: =CALC!U43 -> 2026-06-30 | AA54: =DATA!I161 -> 10.613 | AB54: =DATA!R161 -> 6.79 | AC54: =_xlfn.IFS(IPCA!$O$9=DATA!$T$34,CALC!Z43,IPCA!$O$9=DATA!$T$33,CALC!W43/100) -> 0.035799232
U55: =CALC!L44 -> 2027-01-29 | V55: =DATA!I102 -> 10.128229 | W55: =DATA!R102 -> 5.75 | X55: =_xlfn.IFS(IPCA!$O$9=DATA!$T$34,CALC!Q44,IPCA!$O$9=DATA!$T$33,CALC!N44/100) -> 0.041401691 | Z55: =CALC!U44 -> 2026-07-30 | AA55: =DATA!I162 -> 10.621489 | AB55: =DATA!R162 -> 6.79 | AC55: =_xlfn.IFS(IPCA!$O$9=DATA!$T$34,CALC!Z44,IPCA!$O$9=DATA!$T$33,CALC!W44/100) -> 0.035878726
U56: =CALC!L45 -> 2027-02-26 | V56: =DATA!I103 -> 10.151127 | W56: =DATA!R103 -> 5.75 | X56: =_xlfn.IFS(IPCA!$O$9=DATA!$T$34,CALC!Q45,IPCA!$O$9=DATA!$T$33,CALC!N45/100) -> 0.041618219 | Z56: =CALC!U45 -> 2026-08-28 | AA56: =DATA!I163 -> 10.633078 | AB56: =DATA!R163 -> 6.79 | AC56: =_xlfn.IFS(IPCA!$O$9=DATA!$T$34,CALC!Z45,IPCA!$O$9=DATA!$T$33,CALC!W45/100) -> 0.035987243
U57: =CALC!L46 -> 2027-03-31 | V57: =DATA!I104 -> 10.181 | W57: =DATA!R104 -> 5.75 | X57: =_xlfn.IFS(IPCA!$O$9=DATA!$T$34,CALC!Q46,IPCA!$O$9=DATA!$T$33,CALC!N46/100) -> 0.041900709 | Z57: =CALC!U46 -> 2026-09-30 | AA57: =DATA!I164 -> 10.642 | AB57: =DATA!R164 -> 6.79 | AC57: =_xlfn.IFS(IPCA!$O$9=DATA!$T$34,CALC!Z46,IPCA!$O$9=DATA!$T$33,CALC!W46/100) -> 0.036070793
... U60: =CALC!L49 -> 2028-12-29 | V60: =DATA!I107 -> 10.542588 | W60: =DATA!R107 -> 5.75 | X60: =_xlfn.IFS(IPCA!$O$9=DATA!$T$34,CALC!Q49,IPCA!$O$9=DATA!$T$33,CALC!N49/100) -> 0.045319983 | Z60: =CALC!U49 -> 2028-06-30 | AA60: =DATA!I167 -> 10.869323 | AB60: =DATA!R167 -> 6.79 | AC60: =_xlfn.IFS(IPCA!$O$9=DATA!$T$34,CALC!Z49,IPCA!$O$9=DATA!$T$33,CALC!W49/100) -> 0.038199482
U61: *business days (interpolated tenors) | Z61: *business days (interpolated tenors)

Sheet PERIODS
B1: Curve Date: | C1: =DATA!$U$6 -> 45828 | K1: Curve Date: | L1: =DATA!$U$4 -> 45268 | T1: Curve Date: | U1: =DATA!$U$5 -> 45084
B3: Months | C3: Relative | E3: Settlement | G3: End of Month | K3: Months | L3: Relative | N3: Settlement | P3: End of Month | T3: Months | U3: Relative | W3: Settlement | Y3: End of Month
B4: 1 | C4: 21 | D4: 1M | E4: =IFERROR(_xll.BCOUNTPERIODS($C$1,F4,"CDR=BZ")*1,"") -> 17 | F4: {=_xll.BQL.DATE(_xll.BADDPERIODS(DATE(YEAR($C$1),MONTH($C$1),DAY(15)),"NUMBEROFPERIODS",B4,"PER=M","CDR=BZ","BusDayAdj=-1"))} -> 2025-07-15 | G4: =IFERROR(_xll.BCOUNTPERIODS($C$1,H4,"CDR=BZ")*1,"") -> 28 | H4: {=_xll.BQL.DATE(_xll.BADDPERIODS(EOMONTH($C$1,0),"NUMBEROFPERIODS",B4,"PER=M","CDR=BZ","BusDayAdj=2"))} -> 2025-07-30 | K4: 1 | L4: 21 | M4: 1M | N4: =IFERROR(_xll.BCOUNTPERIODS($L$1,O4,"CDR=BZ")*1,"") -> 24 | O4: {=_xll.BQL.DATE(_xll.BADDPERIODS(DATE(YEAR($L$1),MONTH($L$1),DAY(15)),"NUMBEROFPERIODS",K4,"PER=M","CDR=BZ","BusDayAdj=-1"))} -> 2024-01-15 | P4: =IFERROR(_xll.BCOUNTPERIODS($L$1,Q4,"CDR=BZ")*1,"") -> 36 | Q4: {=_xll.BQL.DATE(_xll.BADDPERIODS(EOMONTH($L$1,0),"NUMBEROFPERIODS",K4,"PER=M","CDR=BZ","BusDayAdj=2"))} -> 2024-01-31 | T4: 1 | U4: 21 | V4: 1M | W4: =IFERROR(_xll.BCOUNTPERIODS($U$1,X4,"CDR=BZ")*1,"") -> 27 | X4: {=_xll.BQL.DATE(_xll.BADDPERIODS(DATE(YEAR($U$1),MONTH($U$1),DAY(15)),"NUMBEROFPERIODS",T4,"PER=M","CDR=BZ","BusDayAdj=-1"))} -> 2023-07-17 | Y4: =IFERROR(_xll.BCOUNTPERIODS($U$1,Z4,"CDR=BZ")*1,"") -> 36 | Z4: {=_xll.BQL.DATE(_xll.BADDPERIODS(EOMONTH($U$1,0),"NUMBEROFPERIODS",T4,"PER=M","CDR=BZ","BusDayAdj=2"))} -> 2023-07-28
B5: 2 | C5: 42 | D5: 2M | E5: =IFERROR(_xll.BCOUNTPERIODS($C$1,F5,"CDR=BZ")*1,"") -> 40 | F5: {=_xll.BQL.DATE(_xll.BADDPERIODS(DATE(YEAR($C$1),MONTH($C$1),DAY(15)),"NUMBEROFPERIODS",B5,"PER=M","CDR=BZ","BusDayAdj=-1"))} -> 2025-08-15 | G5: =IFERROR(_xll.BCOUNTPERIODS($C$1,H5,"CDR=BZ")*1,"") -> 50 | H5: {=_xll.BQL.DATE(_xll.BADDPERIODS(EOMONTH($C$1,0),"NUMBEROFPERIODS",B5,"PER=M","CDR=BZ","BusDayAdj=2"))} -> 2025-08-29 | K5: 2 | L5: 42 | M5: 2M | N5: =IFERROR(_xll.BCOUNTPERIODS($L$1,O5,"CDR=BZ")*1,"") -> 45 | O5: {=_xll.BQL.DATE(_xll.BADDPERIODS(DATE(YEAR($L$1),MONTH($L$1),DAY(15)),"NUMBEROFPERIODS",K5,"PER=M","CDR=BZ","BusDayAdj=-1"))} -> 2024-02-15 | P5: =IFERROR(_xll.BCOUNTPERIODS($L$1,Q5,"CDR=BZ")*1,"") -> 55 | Q5: {=_xll.BQL.DATE(_xll.BADDPERIODS(EOMONTH($L$1,0),"NUMBEROFPERIODS",K5,"PER=M","CDR=BZ","BusDayAdj=2"))} -> 2024-02-29 | T5: 2 | U5: 42 | V5: 2M | W5: =IFERROR(_xll.BCOUNTPERIODS($U$1,X5,"CDR=BZ")*1,"") -> 48 | X5: {=_xll.BQL.DATE(_xll.BADDPERIODS(DATE(YEAR($U$1),MONTH($U$1),DAY(15)),"NUMBEROFPERIODS",T5,"PER=M","CDR=BZ","BusDayAdj=-1"))} -> 2023-08-15 | Y5: =IFERROR(_xll.BCOUNTPERIODS($U$1,Z5,"CDR=BZ")*1,"") -> 59 | Z5: {=_xll.BQL.DATE(_xll.BADDPERIODS(EOMONTH($U$1,0),"NUMBEROFPERIODS",T5,"PER=M","CDR=BZ","BusDayAdj=2"))} -> 2023-08-30
B6: 3 | C6: 63 | D6: 3M | E6: =IFERROR(_xll.BCOUNTPERIODS($C$1,F6,"CDR=BZ")*1,"") -> 61 | F6: {=_xll.BQL.DATE(_xll.BADDPERIODS(DATE(YEAR($C$1),MONTH($C$1),DAY(15)),"NUMBEROFPERIODS",B6,"PER=M","CDR=BZ","BusDayAdj=-1"))} -> 2025-09-15 | G6: =IFERROR(_xll.BCOUNTPERIODS($C$1,H6,"CDR=BZ")*1,"") -> 72 | H6: {=_xll.BQL.DATE(_xll.BADDPERIODS(EOMONTH($C$1,0),"NUMBEROFPERIODS",B6,"PER=M","CDR=BZ","BusDayAdj=2"))} -> 2025-09-30 | K6: 3 | L6: 63 | M6: 3M | N6: =IFERROR(_xll.BCOUNTPERIODS($L$1,O6,"CDR=BZ")*1,"") -> 66 | O6: {=_xll.BQL.DATE(_xll.BADDPERIODS(DATE(YEAR($L$1),MONTH($L$1),DAY(15)),"NUMBEROFPERIODS",K6,"PER=M","CDR=BZ","BusDayAdj=-1"))} -> 2024-03-15 | P6: =IFERROR(_xll.BCOUNTPERIODS($L$1,Q6,"CDR=BZ")*1,"") -> 75 | Q6: {=_xll.BQL.DATE(_xll.BADDPERIODS(EOMONTH($L$1,0),"NUMBEROFPERIODS",K6,"PER=M","CDR=BZ","BusDayAdj=2"))} -> 2024-03-28 | T6: 3 | U6: 63 | V6: 3M | W6: =IFERROR(_xll.BCOUNTPERIODS($U$1,X6,"CDR=BZ")*1,"") -> 70 | X6: {=_xll.BQL.DATE(_xll.BADDPERIODS(DATE(YEAR($U$1),MONTH($U$1),DAY(15)),"NUMBEROFPERIODS",T6,"PER=M","CDR=BZ","BusDayAdj=-1"))} -> 2023-09-15 | Y6: =IFERROR(_xll.BCOUNTPERIODS($U$1,Z6,"CDR=BZ")*1,"") -> 80 | Z6: {=_xll.BQL.DATE(_xll.BADDPERIODS(EOMONTH($U$1,0),"NUMBEROFPERIODS",T6,"PER=M","CDR=BZ","BusDayAdj=2"))} -> 2023-09-29
B7: 4 | C7: 84 | D7: 4M | E7: =IFERROR(_xll.BCOUNTPERIODS($C$1,F7,"CDR=BZ")*1,"") -> 83 | F7: {=_xll.BQL.DATE(_xll.BADDPERIODS(DATE(YEAR($C$1),MONTH($C$1),DAY(15)),"NUMBEROFPERIODS",B7,"PER=M","CDR=BZ","BusDayAdj=-1"))} -> 2025-10-15 | G7: =IFERROR(_xll.BCOUNTPERIODS($C$1,H7,"CDR=BZ")*1,"") -> 94 | H7: {=_xll.BQL.DATE(_xll.BADDPERIODS(EOMONTH($C$1,0),"NUMBEROFPERIODS",B7,"PER=M","CDR=BZ","BusDayAdj=2"))} -> 2025-10-30 | K7: 4 | L7: 84 | M7: 4M | N7: =IFERROR(_xll.BCOUNTPERIODS($L$1,O7,"CDR=BZ")*1,"") -> 86 | O7: {=_xll.BQL.DATE(_xll.BADDPERIODS(DATE(YEAR($L$1),MONTH($L$1),DAY(15)),"NUMBEROFPERIODS",K7,"PER=M","CDR=BZ","BusDayAdj=-1"))} -> 2024-04-15 | P7: =IFERROR(_xll.BCOUNTPERIODS($L$1,Q7,"CDR=BZ")*1,"") -> 97 | Q7: {=_xll.BQL.DATE(_xll.BADDPERIODS(EOMONTH($L$1,0),"NUMBEROFPERIODS",K7,"PER=M","CDR=BZ","BusDayAdj=2"))} -> 2024-04-30 | T7: 4 | U7: 84 | V7: 4M | W7: =IFERROR(_xll.BCOUNTPERIODS($U$1,X7,"CDR=BZ")*1,"") -> 90 | X7: {=_xll.BQL.DATE(_xll.BADDPERIODS(DATE(YEAR($U$1),MONTH($U$1),DAY(15)),"NUMBEROFPERIODS",T7,"PER=M","CDR=BZ","BusDayAdj=-1"))} -> 2023-10-16 | Y7: =IFERROR(_xll.BCOUNTPERIODS($U$1,Z7,"CDR=BZ")*1,"") -> 100 | Z7: {=_xll.BQL.DATE(_xll.BADDPERIODS(EOMONTH($U$1,0),"NUMBEROFPERIODS",T7,"PER=M","CDR=BZ","BusDayAdj=2"))} -> 2023-10-30
B8: 5 | C8: 105 | D8: 5M | E8: =IFERROR(_xll.BCOUNTPERIODS($C$1,F8,"CDR=BZ")*1,"") -> 106 | F8: {=_xll.BQL.DATE(_xll.BADDPERIODS(DATE(YEAR($C$1),MONTH($C$1),DAY(15)),"NUMBEROFPERIODS",B8,"PER=M","CDR=BZ","BusDayAdj=-1"))} -> 2025-11-17 | G8: =IFERROR(_xll.BCOUNTPERIODS($C$1,H8,"CDR=BZ")*1,"") -> 114 | H8: {=_xll.BQL.DATE(_xll.BADDPERIODS(EOMONTH($C$1,0),"NUMBEROFPERIODS",B8,"PER=M","CDR=BZ","BusDayAdj=2"))} -> 2025-11-28 | K8: 5 | L8: 105 | M8: 5M | N8: =IFERROR(_xll.BCOUNTPERIODS($L$1,O8,"CDR=BZ")*1,"") -> 107 | O8: {=_xll.BQL.DATE(_xll.BADDPERIODS(DATE(YEAR($L$1),MONTH($L$1),DAY(15)),"NUMBEROFPERIODS",K8,"PER=M","CDR=BZ","BusDayAdj=-1"))} -> 2024-05-15 | P8: =IFERROR(_xll.BCOUNTPERIODS($L$1,Q8,"CDR=BZ")*1,"") -> 118 | Q8: {=_xll.BQL.DATE(_xll.BADDPERIODS(EOMONTH($L$1,0),"NUMBEROFPERIODS",K8,"PER=M","CDR=BZ","BusDayAdj=2"))} -> 2024-05-31 | T8: 5 | U8: 105 | V8: 5M | W8: =IFERROR(_xll.BCOUNTPERIODS($U$1,X8,"CDR=BZ")*1,"") -> 111 | X8: {=_xll.BQL.DATE(_xll.BADDPERIODS(DATE(YEAR($U$1),MONTH($U$1),DAY(15)),"NUMBEROFPERIODS",T8,"PER=M","CDR=BZ","BusDayAdj=-1"))} -> 2023-11-16 | Y8: =IFERROR(_xll.BCOUNTPERIODS($U$1,Z8,"CDR=BZ")*1,"") -> 121 | Z8: {=_xll.BQL.DATE(_xll.BADDPERIODS(EOMONTH($U$1,0),"NUMBEROFPERIODS",T8,"PER=M","CDR=BZ","BusDayAdj=2"))} -> 2023-11-30
B9: 6 | C9: 126 | D9: 6M | E9: =IFERROR(_xll.BCOUNTPERIODS($C$1,F9,"CDR=BZ")*1,"") -> 125 | F9: {=_xll.BQL.DATE(_xll.BADDPERIODS(DATE(YEAR($C$1),MONTH($C$1),DAY(15)),"NUMBEROFPERIODS",B9,"PER=M","CDR=BZ","BusDayAdj=-1"))} -> 2025-12-15 | G9: =IFERROR(_xll.BCOUNTPERIODS($C$1,H9,"CDR=BZ")*1,"") -> 135 | H9: {=_xll.BQL.DATE(_xll.BADDPERIODS(EOMONTH($C$1,0),"NUMBEROFPERIODS",B9,"PER=M","CDR=BZ","BusDayAdj=2"))} -> 2025-12-30 | K9: 6 | L9: 126 | M9: 6M | N9: =IFERROR(_xll.BCOUNTPERIODS($L$1,O9,"CDR=BZ")*1,"") -> 129 | O9: {=_xll.BQL.DATE(_xll.BADDPERIODS(DATE(YEAR($L$1),MONTH($L$1),DAY(15)),"NUMBEROFPERIODS",K9,"PER=M","CDR=BZ","BusDayAdj=-1"))} -> 2024-06-17 | P9: =IFERROR(_xll.BCOUNTPERIODS($L$1,Q9,"CDR=BZ")*1,"") -> 138 | Q9: {=_xll.BQL.DATE(_xll.BADDPERIODS(EOMONTH($L$1,0),"NUMBEROFPERIODS",K9,"PER=M","CDR=BZ","BusDayAdj=2"))} -> 2024-06-28 | T9: 6 | U9: 126 | V9: 6M | W9: =IFERROR(_xll.BCOUNTPERIODS($U$1,X9,"CDR=BZ")*1,"") -> 132 | X9: {=_xll.BQL.DATE(_xll.BADDPERIODS(DATE(YEAR($U$1),MONTH($U$1),DAY(15)),"NUMBEROFPERIODS",T9,"PER=M","CDR=BZ","BusDayAdj=-1"))} -> 2023-12-15 | Y9: =IFERROR(_xll.BCOUNTPERIODS($U$1,Z9,"CDR=BZ")*1,"") -> 141 | Z9: {=_xll.BQL.DATE(_xll.BADDPERIODS(EOMONTH($U$1,0),"NUMBEROFPERIODS",T9,"PER=M","CDR=BZ","BusDayAdj=2"))} -> 2023-12-29
B10: 7 | C10: 147 | D10: 7M | E10: =IFERROR(_xll.BCOUNTPERIODS($C$1,F10,"CDR=BZ")*1,"") -> 146 | F10: {=_xll.BQL.DATE(_xll.BADDPERIODS(DATE(YEAR($C$1),MONTH($C$1),DAY(15)),"NUMBEROFPERIODS",B10,"PER=M","CDR=BZ","BusDayAdj=-1"))} -> 2026-01-15 | G10: =IFERROR(_xll.BCOUNTPERIODS($C$1,H10,"CDR=BZ")*1,"") -> 157 | H10: {=_xll.BQL.DATE(_xll.BADDPERIODS(EOMONTH($C$1,0),"NUMBEROFPERIODS",B10,"PER=M","CDR=BZ","BusDayAdj=2"))} -> 2026-01-30 | K10: 7 | L10: 147 | M10: 7M | N10: =IFERROR(_xll.BCOUNTPERIODS($L$1,O10,"CDR=BZ")*1,"") -> 149 | O10: {=_xll.BQL.DATE(_xll.BADDPERIODS(DATE(YEAR($L$1),MONTH($L$1),DAY(15)),"NUMBEROFPERIODS",K10,"PER=M","CDR=BZ","BusDayAdj=-1"))} -> 2024-07-15 | P10: =IFERROR(_xll.BCOUNTPERIODS($L$1,Q10,"CDR=BZ")*1,"") -> 161 | Q10: {=_xll.BQL.DATE(_xll.BADDPERIODS(EOMONTH($L$1,0),"NUMBEROFPERIODS",K10,"PER=M","CDR=BZ","BusDayAdj=2"))} -> 2024-07-31 | T10: 7 | U10: 147 | V10: 7M | W10: =IFERROR(_xll.BCOUNTPERIODS($U$1,X10,"CDR=BZ")*1,"") -> 151 | X10: {=_xll.BQL.DATE(_xll.BADDPERIODS(DATE(YEAR($U$1),MONTH($U$1),DAY(15)),"NUMBEROFPERIODS",T10,"PER=M","CDR=BZ","BusDayAdj=-1"))} -> 2024-01-15 | Y10: =IFERROR(_xll.BCOUNTPERIODS($U$1,Z10,"CDR=BZ")*1,"") -> 162 | Z10: {=_xll.BQL.DATE(_xll.BADDPERIODS(EOMONTH($U$1,0),"NUMBEROFPERIODS",T10,"PER=M","CDR=BZ","BusDayAdj=2"))} -> 2024-01-30
B11: 8 | C11: 168 | D11: 8M | E11: =IFERROR(_xll.BCOUNTPERIODS($C$1,F11,"CDR=BZ")*1,"") -> 168 | F11: {=_xll.BQL.DATE(_xll.BADDPERIODS(DATE(YEAR($C$1),MONTH($C$1),DAY(15)),"NUMBEROFPERIODS",B11,"PER=M","CDR=BZ","BusDayAdj=-1"))} -> 2026-02-18 | G11: =IFERROR(_xll.BCOUNTPERIODS($C$1,H11,"CDR=BZ")*1,"") -> 175 | H11: {=_xll.BQL.DATE(_xll.BADDPERIODS(EOMONTH($C$1,0),"NUMBEROFPERIODS",B11,"PER=M","CDR=BZ","BusDayAdj=2"))} -> 2026-02-27 | K11: 8 | L11: 168 | M11: 8M | N11: =IFERROR(_xll.BCOUNTPERIODS($L$1,O11,"CDR=BZ")*1,"") -> 172 | O11: {=_xll.BQL.DATE(_xll.BADDPERIODS(DATE(YEAR($L$1),MONTH($L$1),DAY(15)),"NUMBEROFPERIODS",K11,"PER=M","CDR=BZ","BusDayAdj=-1"))} -> 2024-08-15 | P11: =IFERROR(_xll.BCOUNTPERIODS($L$1,Q11,"CDR=BZ")*1,"") -> 183 | Q11: {=_xll.BQL.DATE(_xll.BADDPERIODS(EOMONTH($L$1,0),"NUMBEROFPERIODS",K11,"PER=M","CDR=BZ","BusDayAdj=2"))} -> 2024-08-30 | T11: 8 | U11: 168 | V11: 8M | W11: =IFERROR(_xll.BCOUNTPERIODS($U$1,X11,"CDR=BZ")*1,"") -> 172 | X11: {=_xll.BQL.DATE(_xll.BADDPERIODS(DATE(YEAR($U$1),MONTH($U$1),DAY(15)),"NUMBEROFPERIODS",T11,"PER=M","CDR=BZ","BusDayAdj=-1"))} -> 2024-02-15 | Y11: =IFERROR(_xll.BCOUNTPERIODS($U$1,Z11,"CDR=BZ")*1,"") -> 182 | Z11: {=_xll.BQL.DATE(_xll.BADDPERIODS(EOMONTH($U$1,0),"NUMBEROFPERIODS",T11,"PER=M","CDR=BZ","BusDayAdj=2"))} -> 2024-02-29
B12: 9 | C12: 189 | D12: 9M | E12: =IFERROR(_xll.BCOUNTPERIODS($C$1,F12,"CDR=BZ")*1,"") -> 186 | F12: {=_xll.BQL.DATE(_xll.BADDPERIODS(DATE(YEAR($C$1),MONTH($C$1),DAY(15)),"NUMBEROFPERIODS",B12,"PER=M","CDR=BZ","BusDayAdj=-1"))} -> 2026-03-16 | G12: =IFERROR(_xll.BCOUNTPERIODS($C$1,H12,"CDR=BZ")*1,"") -> 196 | H12: {=_xll.BQL.DATE(_xll.BADDPERIODS(EOMONTH($C$1,0),"NUMBEROFPERIODS",B12,"PER=M","CDR=BZ","BusDayAdj=2"))} -> 2026-03-30 | K12: 9 | L12: 189 | M12: 9M | N12: =IFERROR(_xll.BCOUNTPERIODS($L$1,O12,"CDR=BZ")*1,"") -> 194 | O12: {=_xll.BQL.DATE(_xll.BADDPERIODS(DATE(YEAR($L$1),MONTH($L$1),DAY(15)),"NUMBEROFPERIODS",K12,"PER=M","CDR=BZ","BusDayAdj=-1"))} -> 2024-09-16 | P12: =IFERROR(_xll.BCOUNTPERIODS($L$1,Q12,"CDR=BZ")*1,"") -> 204 | Q12: {=_xll.BQL.DATE(_xll.BADDPERIODS(EOMONTH($L$1,0),"NUMBEROFPERIODS",K12,"PER=M","CDR=BZ","BusDayAdj=2"))} -> 2024-09-30 | T12: 9 | U12: 189 | V12: 9M | W12: =IFERROR(_xll.BCOUNTPERIODS($U$1,X12,"CDR=BZ")*1,"") -> 193 | X12: {=_xll.BQL.DATE(_xll.BADDPERIODS(DATE(YEAR($U$1),MONTH($U$1),DAY(15)),"NUMBEROFPERIODS",T12,"PER=M","CDR=BZ","BusDayAdj=-1"))} -> 2024-03-15 | Y12: =IFERROR(_xll.BCOUNTPERIODS($U$1,Z12,"CDR=BZ")*1,"") -> 202 | Z12: {=_xll.BQL.DATE(_xll.BADDPERIODS(EOMONTH($U$1,0),"NUMBEROFPERIODS",T12,"PER=M","CDR=BZ","BusDayAdj=2"))} -> 2024-03-28
B13: 10 | C13: 210 | D13: 10M | E13: =IFERROR(_xll.BCOUNTPERIODS($C$1,F13,"CDR=BZ")*1,"") -> 207 | F13: {=_xll.BQL.DATE(_xll.BADDPERIODS(DATE(YEAR($C$1),MONTH($C$1),DAY(15)),"NUMBEROFPERIODS",B13,"PER=M","CDR=BZ","BusDayAdj=-1"))} -> 2026-04-15 | G13: =IFERROR(_xll.BCOUNTPERIODS($C$1,H13,"CDR=BZ")*1,"") -> 217 | H13: {=_xll.BQL.DATE(_xll.BADDPERIODS(EOMONTH($C$1,0),"NUMBEROFPERIODS",B13,"PER=M","CDR=BZ","BusDayAdj=2"))} -> 2026-04-30 | K13: 10 | L13: 210 | M13: 10M | N13: =IFERROR(_xll.BCOUNTPERIODS($L$1,O13,"CDR=BZ")*1,"") -> 215 | O13: {=_xll.BQL.DATE(_xll.BADDPERIODS(DATE(YEAR($L$1),MONTH($L$1),DAY(15)),"NUMBEROFPERIODS",K13,"PER=M","CDR=BZ","BusDayAdj=-1"))} -> 2024-10-15 | P13: =IFERROR(_xll.BCOUNTPERIODS($L$1,Q13,"CDR=BZ")*1,"") -> 227 | Q13: {=_xll.BQL.DATE(_xll.BADDPERIODS(EOMONTH($L$1,0),"NUMBEROFPERIODS",K13,"PER=M","CDR=BZ","BusDayAdj=2"))} -> 2024-10-31 | T13: 10 | U13: 210 | V13: 10M | W13: =IFERROR(_xll.BCOUNTPERIODS($U$1,X13,"CDR=BZ")*1,"") -> 213 | X13: {=_xll.BQL.DATE(_xll.BADDPERIODS(DATE(YEAR($U$1),MONTH($U$1),DAY(15)),"NUMBEROFPERIODS",T13,"PER=M","CDR=BZ","BusDayAdj=-1"))} -> 2024-04-15 | Y13: =IFERROR(_xll.BCOUNTPERIODS($U$1,Z13,"CDR=BZ")*1,"") -> 224 | Z13: {=_xll.BQL.DATE(_xll.BADDPERIODS(EOMONTH($U$1,0),"NUMBEROFPERIODS",T13,"PER=M","CDR=BZ","BusDayAdj=2"))} -> 2024-04-30
B14: 11 | C14: 231 | D14: 11M | E14: =IFERROR(_xll.BCOUNTPERIODS($C$1,F14,"CDR=BZ")*1,"") -> 227 | F14: {=_xll.BQL.DATE(_xll.BADDPERIODS(DATE(YEAR($C$1),MONTH($C$1),DAY(15)),"NUMBEROFPERIODS",B14,"PER=M","CDR=BZ","BusDayAdj=-1"))} -> 2026-05-15 | G14: =IFERROR(_xll.BCOUNTPERIODS($C$1,H14,"CDR=BZ")*1,"") -> 237 | H14: {=_xll.BQL.DATE(_xll.BADDPERIODS(EOMONTH($C$1,0),"NUMBEROFPERIODS",B14,"PER=M","CDR=BZ","BusDayAdj=2"))} -> 2026-05-29 | K14: 11 | L14: 231 | M14: 11M | N14: =IFERROR(_xll.BCOUNTPERIODS($L$1,O14,"CDR=BZ")*1,"") -> 238 | O14: {=_xll.BQL.DATE(_xll.BADDPERIODS(DATE(YEAR($L$1),MONTH($L$1),DAY(15)),"NUMBEROFPERIODS",K14,"PER=M","CDR=BZ","BusDayAdj=-1"))} -> 2024-11-18 | P14: =IFERROR(_xll.BCOUNTPERIODS($L$1,Q14,"CDR=BZ")*1,"") -> 246 | Q14: {=_xll.BQL.DATE(_xll.BADDPERIODS(EOMONTH($L$1,0),"NUMBEROFPERIODS",K14,"PER=M","CDR=BZ","BusDayAdj=2"))} -> 2024-11-29 | T14: 11 | U14: 231 | V14: 11M | W14: =IFERROR(_xll.BCOUNTPERIODS($U$1,X14,"CDR=BZ")*1,"") -> 234 | X14: {=_xll.BQL.DATE(_xll.BADDPERIODS(DATE(YEAR($U$1),MONTH($U$1),DAY(15)),"NUMBEROFPERIODS",T14,"PER=M","CDR=BZ","BusDayAdj=-1"))} -> 2024-05-15 | Y14: =IFERROR(_xll.BCOUNTPERIODS($U$1,Z14,"CDR=BZ")*1,"") -> 244 | Z14: {=_xll.BQL.DATE(_xll.BADDPERIODS(EOMONTH($U$1,0),"NUMBEROFPERIODS",T14,"PER=M","CDR=BZ","BusDayAdj=2"))} -> 2024-05-29
B15: 12 | C15: 252 | D15: 1Y | E15: =IFERROR(_xll.BCOUNTPERIODS($C$1,F15,"CDR=BZ")*1,"") -> 247 | F15: {=_xll.BQL.DATE(_xll.BADDPERIODS(DATE(YEAR($C$1),MONTH($C$1),DAY(15)),"NUMBEROFPERIODS",B15,"PER=M","CDR=BZ","BusDayAdj=-1"))} -> 2026-06-15 | G15: =IFERROR(_xll.BCOUNTPERIODS($C$1,H15,"CDR=BZ")*1,"") -> 258 | H15: {=_xll.BQL.DATE(_xll.BADDPERIODS(EOMONTH($C$1,0),"NUMBEROFPERIODS",B15,"PER=M","CDR=BZ","BusDayAdj=2"))} -> 2026-06-30 | K15: 12 | L15: 252 | M15: 1Y | N15: =IFERROR(_xll.BCOUNTPERIODS($L$1,O15,"CDR=BZ")*1,"") -> 257 | O15: {=_xll.BQL.DATE(_xll.BADDPERIODS(DATE(YEAR($L$1),MONTH($L$1),DAY(15)),"NUMBEROFPERIODS",K15,"PER=M","CDR=BZ","BusDayAdj=-1"))} -> 2024-12-16 | P15: =IFERROR(_xll.BCOUNTPERIODS($L$1,Q15,"CDR=BZ")*1,"") -> 267 | Q15: {=_xll.BQL.DATE(_xll.BADDPERIODS(EOMONTH($L$1,0),"NUMBEROFPERIODS",K15,"PER=M","CDR=BZ","BusDayAdj=2"))} -> 2024-12-31 | T15: 12 | U15: 252 | V15: 1Y | W15: =IFERROR(_xll.BCOUNTPERIODS($U$1,X15,"CDR=BZ")*1,"") -> 256 | X15: {=_xll.BQL.DATE(_xll.BADDPERIODS(DATE(YEAR($U$1),MONTH($U$1),DAY(15)),"NUMBEROFPERIODS",T15,"PER=M","CDR=BZ","BusDayAdj=-1"))} -> 2024-06-17 | Y15: =IFERROR(_xll.BCOUNTPERIODS($U$1,Z15,"CDR=BZ")*1,"") -> 265 | Z15: {=_xll.BQL.DATE(_xll.BADDPERIODS(EOMONTH($U$1,0),"NUMBEROFPERIODS",T15,"PER=M","CDR=BZ","BusDayAdj=2"))} -> 2024-06-28
... B45: 60 | C45: 1260 | D45: 5Y | E45: =IFERROR(_xll.BCOUNTPERIODS($C$1,F45,"CDR=BZ")*1,"") -> 1248 | F45: {=_xll.BQL.DATE(_xll.BADDPERIODS(DATE(YEAR($C$1),MONTH($C$1),DAY(15)),"NUMBEROFPERIODS",B45,"PER=M","CDR=BZ","BusDayAdj=-1"))} -> 2030-06-17 | G45: =IFERROR(_xll.BCOUNTPERIODS($C$1,H45,"CDR=BZ")*1,"") -> 1256 | H45: {=_xll.BQL.DATE(_xll.BADDPERIODS(EOMONTH($C$1,0),"NUMBEROFPERIODS",B45,"PER=M","CDR=BZ","BusDayAdj=2"))} -> 2030-06-28 | K45: 60 | L45: 1260 | M45: 5Y | N45: =IFERROR(_xll.BCOUNTPERIODS($L$1,O45,"CDR=BZ")*1,"") -> 1258 | O45: {=_xll.BQL.DATE(_xll.BADDPERIODS(DATE(YEAR($L$1),MONTH($L$1),DAY(15)),"NUMBEROFPERIODS",K45,"PER=M","CDR=BZ","BusDayAdj=-1"))} -> 2028-12-15 | P45: =IFERROR(_xll.BCOUNTPERIODS($L$1,Q45,"CDR=BZ")*1,"") -> 1267 | Q45: {=_xll.BQL.DATE(_xll.BADDPERIODS(EOMONTH($L$1,0),"NUMBEROFPERIODS",K45,"PER=M","CDR=BZ","BusDayAdj=2"))} -> 2028-12-29 | T45: 60 | U45: 1260 | V45: 5Y | W45: =IFERROR(_xll.BCOUNTPERIODS($U$1,X45,"CDR=BZ")*1,"") -> 1260 | X45: {=_xll.BQL.DATE(_xll.BADDPERIODS(DATE(YEAR($U$1),MONTH($U$1),DAY(15)),"NUMBEROFPERIODS",T45,"PER=M","CDR=BZ","BusDayAdj=-1"))} -> 2028-06-16 | Y45: =IFERROR(_xll.BCOUNTPERIODS($U$1,Z45,"CDR=BZ")*1,"") -> 1270 | Z45: {=_xll.BQL.DATE(_xll.BADDPERIODS(EOMONTH($U$1,0),"NUMBEROFPERIODS",T45,"PER=M","CDR=BZ","BusDayAdj=2"))} -> 2028-06-30

Sheet DATA
B2: =IPCA!$G$7 -> YCSW0089 Index | K2: =IPCA!$G$9 -> WLA Index | T2: Today | U2: =TODAY() -> 45829
B3: Curve Date: | C3: =$U$6 -> 45828 | K3: Curve Date: | L3: =$U$6 -> 45828
B4: ="get(ID().tenor as #tenor, curve_rate(side=Ask).value as #yield,Ceil(id().year_fraction*252) as #Point,MATURITY().value as #Maturity) for(curveMembers(['"&B2&"'])) with(dates="&_xll.BQL.DATE(C3)&")" -> get(ID().tenor as #tenor, curve_rate(side=Ask).value as #yield,Ceil(id().year_fraction*252) as #Point,MATURITY().value as #Maturity) for(curveMembers(['YCSW0089 Index'])) with(dates=2025-06-20) | T4: DATE 1 | U4: {=_xll.BADDPERIODS(Comparison!$C$9,"CDR=B3","BusDayAdj=+1")} -> 45268
B5: ="get(ID().tenor as #tenor, curve_rate(side=Ask).value as #yield,Ceil(id().year_fraction*252) as #Point,FUT_LAST_TRADE_DT AS #maturity) for(filter(curveMembers(['"&B2&"']),grouprank(FUT_LAST_TRADE_DT,order=asc)<=60)) with(dates="&_xll.BQL.DATE(C3)&")" -> get(ID().tenor as #tenor, curve_rate(side=Ask).value as #yield,Ceil(id().year_fraction*252) as #Point,FUT_LAST_TRADE_DT AS #maturity) for(filter(curveMembers(['YCSW0089 Index']),grouprank(FUT_LAST_TRADE_DT,order=asc)<=60)) with(dates=2025-06-20) | K5: ="get(ID().tenor as #tenor, curve_rate(side=Ask).value as #yield,Ceil(id().year_fraction*252) as #Point,MATURITY().value as #Maturity) for(curveMembers(['"&K2&"'])) with(dates="&_xll.BQL.DATE(L3)&")" -> get(ID().tenor as #tenor, curve_rate(side=Ask).value as #yield,Ceil(id().year_fraction*252) as #Point,MATURITY().value as #Maturity) for(curveMembers(['WLA Index'])) with(dates=2025-06-20) | T5: DATE 2 | U5: {=_xll.BADDPERIODS(Comparison!$C$11,"CDR=B3","BusDayAdj=+1")} -> 45084
B6: {=_xll.BQL.QUERY(_xlfn.IFS(B2=$T$9,B5,B2=$T$10,B4))} -> ID | C6: #tenor.TENOR | D6: #yield | E6: #Point | F6: #maturity | G6: BD | H6: Periods | I6: Interpol | K6: {=_xll.BQL.QUERY(K5)} -> #N/A Invalid Security: Unable to evaluate universe. Either the identifier is invalid or you do not have access to the data. Check inputs and try again. | P6: BD | Q6: Periods | R6: Interpol | T6: MAIN | U6: {=_xll.BADDPERIODS($U$2,"CDR=B3","BusDayAdj=+1")} -> 45828
B7: ODN25 Comdty | C7: 1W | D7: 14.901 | E7: 5 | F7: 45838 | G7: =IFERROR(_xll.BCOUNTPERIODS($C$3,F7,"CDR=BZ")*1,"") -> 6 | H7: =_xlfn.IFS(IPCA!$O$7=DATA!$T$26,PERIODS!C4,IPCA!$O$7=DATA!$T$27,PERIODS!E4,IPCA!$O$7=DATA!$T$28,PERIODS!G4) -> 28 | I7: =IFERROR(_xll.BInterpol($G$7:$G$48, $D$7:$D$48, H7, "Cubic","Skip=True")*1,"") -> 14.905143 | P7: =IFERROR(_xll.BCOUNTPERIODS($L$3,O7,"CDR=BZ")*1,"") | Q7: =_xlfn.IFS(IPCA!$O$7=DATA!$T$26,PERIODS!C4,IPCA!$O$7=DATA!$T$27,PERIODS!E4,IPCA!$O$7=DATA!$T$28,PERIODS!G4) -> 28 | R7: =IFERROR(IF($K$2=$T$16,_xll.BInterpol(FUT!$F$7:$F$28, FUT!$E$7:$E$28, Q7, "Cubic","Skip=True"),_xll.BInterpol($P$7:$P$48, $M$7:$M$48, Q7, "Cubic","Skip=True"))*1,"") -> 12.421827
B8: ODQ25 Comdty | C8: 1M | D8: 14.906 | E8: 21 | F8: 45869 | G8: =IFERROR(_xll.BCOUNTPERIODS($C$3,F8,"CDR=BZ")*1,"") -> 29 | H8: =_xlfn.IFS(IPCA!$O$7=DATA!$T$26,PERIODS!C5,IPCA!$O$7=DATA!$T$27,PERIODS!E5,IPCA!$O$7=DATA!$T$28,PERIODS!G5) -> 50 | I8: =IFERROR(_xll.BInterpol($G$7:$G$45, $D$7:$D$45, H8, "Cubic","Skip=True")*1,"") -> 14.933 | P8: =IFERROR(_xll.BCOUNTPERIODS($L$3,O8,"CDR=BZ")*1,"") | Q8: =_xlfn.IFS(IPCA!$O$7=DATA!$T$26,PERIODS!C5,IPCA!$O$7=DATA!$T$27,PERIODS!E5,IPCA!$O$7=DATA!$T$28,PERIODS!G5) -> 50 | R8: =IFERROR(IF($K$2=$T$16,_xll.BInterpol(FUT!$F$7:$F$28, FUT!$E$7:$E$28, Q8, "Cubic","Skip=True"),_xll.BInterpol($P$7:$P$48, $M$7:$M$48, Q8, "Cubic","Skip=True"))*1,"") -> 11.758117
B9: ODU25 Comdty | C9: 2M | D9: 14.933 | E9: 42 | F9: 45898 | G9: =IFERROR(_xll.BCOUNTPERIODS($C$3,F9,"CDR=BZ")*1,"") -> 50 | H9: =_xlfn.IFS(IPCA!$O$7=DATA!$T$26,PERIODS!C6,IPCA!$O$7=DATA!$T$27,PERIODS!E6,IPCA!$O$7=DATA!$T$28,PERIODS!G6) -> 72 | I9: =IFERROR(_xll.BInterpol($G$7:$G$45, $D$7:$D$45, H9, "Cubic","Skip=True")*1,"") -> 14.947 | P9: =IFERROR(_xll.BCOUNTPERIODS($L$3,O9,"CDR=BZ")*1,"") | Q9: =_xlfn.IFS(IPCA!$O$7=DATA!$T$26,PERIODS!C6,IPCA!$O$7=DATA!$T$27,PERIODS!E6,IPCA!$O$7=DATA!$T$28,PERIODS!G6) -> 72 | R9: =IFERROR(IF($K$2=$T$16,_xll.BInterpol(FUT!$F$7:$F$28, FUT!$E$7:$E$28, Q9, "Cubic","Skip=True"),_xll.BInterpol($P$7:$P$48, $M$7:$M$48, Q9, "Cubic","Skip=True"))*1,"") -> 10.6457 | T9: YCSW0089 Index | U9: {=_xll.BQL(T9,"LONG_COMP_NAME")} -> BM&F Pre x DI Curve
B10: ODV25 Comdty | C10: 3M | D10: 14.947 | E10: 63 | F10: 45930 | G10: =IFERROR(_xll.BCOUNTPERIODS($C$3,F10,"CDR=BZ")*1,"") -> 72 | H10: =_xlfn.IFS(IPCA!$O$7=DATA!$T$26,PERIODS!C7,IPCA!$O$7=DATA!$T$27,PERIODS!E7,IPCA!$O$7=DATA!$T$28,PERIODS!G7) -> 94 | I10: =IFERROR(_xll.BInterpol($G$7:$G$45, $D$7:$D$45, H10, "Cubic","Skip=True")*1,"") -> 14.954852 | P10: =IFERROR(_xll.BCOUNTPERIODS($L$3,O10,"CDR=BZ")*1,"") | Q10: =_xlfn.IFS(IPCA!$O$7=DATA!$T$26,PERIODS!C7,IPCA!$O$7=DATA!$T$27,PERIODS!E7,IPCA!$O$7=DATA!$T$28,PERIODS!G7) -> 94 | R10: =IFERROR(IF($K$2=$T$16,_xll.BInterpol(FUT!$F$7:$F$28, FUT!$E$7:$E$28, Q10, "Cubic","Skip=True"),_xll.BInterpol($P$7:$P$48, $M$7:$M$48, Q10, "Cubic","Skip=True"))*1,"") -> 10.64822 | T10: YCGT0393 Index | U10: {=_xll.BQL(T10,"LONG_COMP_NAME")} -> BRL Brazil Sovereign Curve
B11: ODX25 Comdty | C11: 4M | D11: 14.955 | E11: 83 | F11: 45961 | G11: =IFERROR(_xll.BCOUNTPERIODS($C$3,F11,"CDR=BZ")*1,"") -> 95 | H11: =_xlfn.IFS(IPCA!$O$7=DATA!$T$26,PERIODS!C8,IPCA!$O$7=DATA!$T$27,PERIODS!E8,IPCA!$O$7=DATA!$T$28,PERIODS!G8) -> 114 | I11: =IFERROR(_xll.BInterpol($G$7:$G$45, $D$7:$D$45, H11, "Cubic","Skip=True")*1,"") -> 14.955 | P11: =IFERROR(_xll.BCOUNTPERIODS($L$3,O11,"CDR=BZ")*1,"") | Q11: =_xlfn.IFS(IPCA!$O$7=DATA!$T$26,PERIODS!C8,IPCA!$O$7=DATA!$T$27,PERIODS!E8,IPCA!$O$7=DATA!$T$28,PERIODS!G8) -> 114 | R11: =IFERROR(IF($K$2=$T$16,_xll.BInterpol(FUT!$F$7:$F$28, FUT!$E$7:$E$28, Q11, "Cubic","Skip=True"),_xll.BInterpol($P$7:$P$48, $M$7:$M$48, Q11, "Cubic","Skip=True"))*1,"") -> 10.463594
B12: ODZ25 Comdty | C12: 5M | D12: 14.955 | E12: 104 | F12: 45989 | G12: =IFERROR(_xll.BCOUNTPERIODS($C$3,F12,"CDR=BZ")*1,"") -> 114 | H12: =_xlfn.IFS(IPCA!$O$7=DATA!$T$26,PERIODS!C9,IPCA!$O$7=DATA!$T$27,PERIODS!E9,IPCA!$O$7=DATA!$T$28,PERIODS!G9) -> 135 | I12: =IFERROR(_xll.BInterpol($G$7:$G$45, $D$7:$D$45, H12, "Cubic","Skip=True")*1,"") -> 14.958 | P12: =IFERROR(_xll.BCOUNTPERIODS($L$3,O12,"CDR=BZ")*1,"") | Q12: =_xlfn.IFS(IPCA!$O$7=DATA!$T$26,PERIODS!C9,IPCA!$O$7=DATA!$T$27,PERIODS!E9,IPCA!$O$7=DATA!$T$28,PERIODS!G9) -> 135 | R12: =IFERROR(IF($K$2=$T$16,_xll.BInterpol(FUT!$F$7:$F$28, FUT!$E$7:$E$28, Q12, "Cubic","Skip=True"),_xll.BInterpol($P$7:$P$48, $M$7:$M$48, Q12, "Cubic","Skip=True"))*1,"") -> 10.369619
B13: ODF26 Comdty | C13: 6M | D13: 14.958 | E13: 125 | F13: 46021 | G13: =IFERROR(_xll.BCOUNTPERIODS($C$3,F13,"CDR=BZ")*1,"") -> 135 | H13: =_xlfn.IFS(IPCA!$O$7=DATA!$T$26,PERIODS!C10,IPCA!$O$7=DATA!$T$27,PERIODS!E10,IPCA!$O$7=DATA!$T$28,PERIODS!G10) -> 157 | I13: =IFERROR(_xll.BInterpol($G$7:$G$45, $D$7:$D$45, H13, "Cubic","Skip=True")*1,"") -> 14.96 | P13: =IFERROR(_xll.BCOUNTPERIODS($L$3,O13,"CDR=BZ")*1,"") | Q13: =_xlfn.IFS(IPCA!$O$7=DATA!$T$26,PERIODS!C10,IPCA!$O$7=DATA!$T$27,PERIODS!E10,IPCA!$O$7=DATA!$T$28,PERIODS!G10) -> 157 | R13: =IFERROR(IF($K$2=$T$16,_xll.BInterpol(FUT!$F$7:$F$28, FUT!$E$7:$E$28, Q13, "Cubic","Skip=True"),_xll.BInterpol($P$7:$P$48, $M$7:$M$48, Q13, "Cubic","Skip=True"))*1,"") -> 10.22527
B14: ODG26 Comdty | C14: 7M | D14: 14.96 | E14: 145 | F14: 46052 | G14: =IFERROR(_xll.BCOUNTPERIODS($C$3,F14,"CDR=BZ")*1,"") -> 157 | H14: =_xlfn.IFS(IPCA!$O$7=DATA!$T$26,PERIODS!C11,IPCA!$O$7=DATA!$T$27,PERIODS!E11,IPCA!$O$7=DATA!$T$28,PERIODS!G11) -> 175 | I14: =IFERROR(_xll.BInterpol($G$7:$G$45, $D$7:$D$45, H14, "Cubic","Skip=True")*1,"") -> 14.955 | P14: =IFERROR(_xll.BCOUNTPERIODS($L$3,O14,"CDR=BZ")*1,"") | Q14: =_xlfn.IFS(IPCA!$O$7=DATA!$T$26,PERIODS!C11,IPCA!$O$7=DATA!$T$27,PERIODS!E11,IPCA!$O$7=DATA!$T$28,PERIODS!G11) -> 175 | R14: =IFERROR(IF($K$2=$T$16,_xll.BInterpol(FUT!$F$7:$F$28, FUT!$E$7:$E$28, Q14, "Cubic","Skip=True"),_xll.BInterpol($P$7:$P$48, $M$7:$M$48, Q14, "Cubic","Skip=True"))*1,"") -> 10.137143
B15: ODH26 Comdty | C15: 8M | D15: 14.955 | E15: 166 | F15: 46080 | G15: =IFERROR(_xll.BCOUNTPERIODS($C$3,F15,"CDR=BZ")*1,"") -> 175 | H15: =_xlfn.IFS(IPCA!$O$7=DATA!$T$26,PERIODS!C12,IPCA!$O$7=DATA!$T$27,PERIODS!E12,IPCA!$O$7=DATA!$T$28,PERIODS!G12) -> 196 | I15: =IFERROR(_xll.BInterpol($G$7:$G$45, $D$7:$D$45, H15, "Cubic","Skip=True")*1,"") -> 14.926749 | P15: =IFERROR(_xll.BCOUNTPERIODS($L$3,O15,"CDR=BZ")*1,"") | Q15: =_xlfn.IFS(IPCA!$O$7=DATA!$T$26,PERIODS!C12,IPCA!$O$7=DATA!$T$27,PERIODS!E12,IPCA!$O$7=DATA!$T$28,PERIODS!G12) -> 196 | R15: =IFERROR(IF($K$2=$T$16,_xll.BInterpol(FUT!$F$7:$F$28, FUT!$E$7:$E$28, Q15, "Cubic","Skip=True"),_xll.BInterpol($P$7:$P$48, $M$7:$M$48, Q15, "Cubic","Skip=True"))*1,"") -> 10.063334
B16: ODJ26 Comdty | C16: 9M | D16: 14.925 | E16: 187 | F16: 46112 | G16: =IFERROR(_xll.BCOUNTPERIODS($C$3,F16,"CDR=BZ")*1,"") -> 197 | H16: =_xlfn.IFS(IPCA!$O$7=DATA!$T$26,PERIODS!C13,IPCA!$O$7=DATA!$T$27,PERIODS!E13,IPCA!$O$7=DATA!$T$28,PERIODS!G13) -> 217 | I16: =IFERROR(_xll.BInterpol($G$7:$G$45, $D$7:$D$45, H16, "Cubic","Skip=True")*1,"") -> 14.885 | P16: =IFERROR(_xll.BCOUNTPERIODS($L$3,O16,"CDR=BZ")*1,"") | Q16: =_xlfn.IFS(IPCA!$O$7=DATA!$T$26,PERIODS!C13,IPCA!$O$7=DATA!$T$27,PERIODS!E13,IPCA!$O$7=DATA!$T$28,PERIODS!G13) -> 217 | R16: =IFERROR(IF($K$2=$T$16,_xll.BInterpol(FUT!$F$7:$F$28, FUT!$E$7:$E$28, Q16, "Cubic","Skip=True"),_xll.BInterpol($P$7:$P$48, $M$7:$M$48, Q16, "Cubic","Skip=True"))*1,"") -> 10.011454 | T16: WLA Index | U16: {=_xll.BQL( T16, "ID_BB_GLOBAL_COMPANY_NAME()")} -> ID x IPCA Spread Futures
B17: ODK26 Comdty | C17: 10M | D17: 14.885 | E17: 208 | F17: 46142 | G17: =IFERROR(_xll.BCOUNTPERIODS($C$3,F17,"CDR=BZ")*1,"") -> 217 | H17: =_xlfn.IFS(IPCA!$O$7=DATA!$T$26,PERIODS!C14,IPCA!$O$7=DATA!$T$27,PERIODS!E14,IPCA!$O$7=DATA!$T$28,PERIODS!G14) -> 237 | I17: =IFERROR(_xll.BInterpol($G$7:$G$45, $D$7:$D$45, H17, "Cubic","Skip=True")*1,"") -> 14.833 | P17: =IFERROR(_xll.BCOUNTPERIODS($L$3,O17,"CDR=BZ")*1,"") | Q17: =_xlfn.IFS(IPCA!$O$7=DATA!$T$26,PERIODS!C14,IPCA!$O$7=DATA!$T$27,PERIODS!E14,IPCA!$O$7=DATA!$T$28,PERIODS!G14) -> 237 | R17: =IFERROR(IF($K$2=$T$16,_xll.BInterpol(FUT!$F$7:$F$28, FUT!$E$7:$E$28, Q17, "Cubic","Skip=True"),_xll.BInterpol($P$7:$P$48, $M$7:$M$48, Q17, "Cubic","Skip=True"))*1,"") -> 9.973491 | T17: YCGT0372 Index | U17: {=_xll.BQL(T17,"LONG_COMP_NAME")} -> BRL Brazil Govt IPCA-Link Curve
B18: ODM26 Comdty | C18: 11M | D18: 14.833 | E18: 228 | F18: 46171 | G18: =IFERROR(_xll.BCOUNTPERIODS($C$3,F18,"CDR=BZ")*1,"") -> 237 | H18: =_xlfn.IFS(IPCA!$O$7=DATA!$T$26,PERIODS!C15,IPCA!$O$7=DATA!$T$27,PERIODS!E15,IPCA!$O$7=DATA!$T$28,PERIODS!G15) -> 258 | I18: =IFERROR(_xll.BInterpol($G$7:$G$45, $D$7:$D$45, H18, "Cubic","Skip=True")*1,"") -> 14.773 | P18: =IFERROR(_xll.BCOUNTPERIODS($L$3,O18,"CDR=BZ")*1,"") | Q18: =_xlfn.IFS(IPCA!$O$7=DATA!$T$26,PERIODS!C15,IPCA!$O$7=DATA!$T$27,PERIODS!E15,IPCA!$O$7=DATA!$T$28,PERIODS!G15) -> 258 | R18: =IFERROR(IF($K$2=$T$16,_xll.BInterpol(FUT!$F$7:$F$28, FUT!$E$7:$E$28, Q18, "Cubic","Skip=True"),_xll.BInterpol($P$7:$P$48, $M$7:$M$48, Q18, "Cubic","Skip=True"))*1,"") -> 9.9362588 | T18: BVIS1138 Index | U18: {=_xll.BQL(T18,"LONG_COMP_NAME")} -> BRL Brazil Govt Inflation Linked BVAL Curve
B19: ODN26 Comdty | C19: 1Y | D19: 14.773 | E19: 252 | F19: 46203 | G19: =IFERROR(_xll.BCOUNTPERIODS($C$3,F19,"CDR=BZ")*1,"") -> 258 | H19: =_xlfn.IFS(IPCA!$O$7=DATA!$T$26,PERIODS!C16,IPCA!$O$7=DATA!$T$27,PERIODS!E16,IPCA!$O$7=DATA!$T$28,PERIODS!G16) -> 280 | I19: =IFERROR(_xll.BInterpol($G$7:$G$45, $D$7:$D$45, H19, "Cubic","Skip=True")*1,"") -> 14.701109 | P19: =IFERROR(_xll.BCOUNTPERIODS($L$3,O19,"CDR=BZ")*1,"") | Q19: =_xlfn.IFS(IPCA!$O$7=DATA!$T$26,PERIODS!C16,IPCA!$O$7=DATA!$T$27,PERIODS!E16,IPCA!$O$7=DATA!$T$28,PERIODS!G16) -> 280 | R19: =IFERROR(IF($K$2=$T$16,_xll.BInterpol(FUT!$F$7:$F$28, FUT!$E$7:$E$28, Q19, "Cubic","Skip=True"),_xll.BInterpol($P$7:$P$48, $M$7:$M$48, Q19, "Cubic","Skip=True"))*1,"") -> 9.8896604
B20: ODV26 Comdty | C20: 15M | D20: 14.535 | E20: 311 | F20: 46295 | G20: =IFERROR(_xll.BCOUNTPERIODS($C$3,F20,"CDR=BZ")*1,"") -> 323 | H20: =_xlfn.IFS(IPCA!$O$7=DATA!$T$26,PERIODS!C17,IPCA!$O$7=DATA!$T$27,PERIODS!E17,IPCA!$O$7=DATA!$T$28,PERIODS!G17) -> 301 | I20: =IFERROR(_xll.BInterpol($G$7:$G$45, $D$7:$D$45, H20, "Cubic","Skip=True")*1,"") -> 14.623692 | P20: =IFERROR(_xll.BCOUNTPERIODS($L$3,O20,"CDR=BZ")*1,"") | Q20: =_xlfn.IFS(IPCA!$O$7=DATA!$T$26,PERIODS!C17,IPCA!$O$7=DATA!$T$27,PERIODS!E17,IPCA!$O$7=DATA!$T$28,PERIODS!G17) -> 301 | R20: =IFERROR(IF($K$2=$T$16,_xll.BInterpol(FUT!$F$7:$F$28, FUT!$E$7:$E$28, Q20, "Cubic","Skip=True"),_xll.BInterpol($P$7:$P$48, $M$7:$M$48, Q20, "Cubic","Skip=True"))*1,"") -> 9.8279867
B21: ODF27 Comdty | C21: 18M | D21: 14.281 | E21: 373 | F21: 46386 | G21: =IFERROR(_xll.BCOUNTPERIODS($C$3,F21,"CDR=BZ")*1,"") -> 384 | H21: =_xlfn.IFS(IPCA!$O$7=DATA!$T$26,PERIODS!C18,IPCA!$O$7=DATA!$T$27,PERIODS!E18,IPCA!$O$7=DATA!$T$28,PERIODS!G18) -> 323 | I21: =IFERROR(_xll.BInterpol($G$7:$G$45, $D$7:$D$45, H21, "Cubic","Skip=True")*1,"") -> 14.535 | P21: =IFERROR(_xll.BCOUNTPERIODS($L$3,O21,"CDR=BZ")*1,"") | Q21: =_xlfn.IFS(IPCA!$O$7=DATA!$T$26,PERIODS!C18,IPCA!$O$7=DATA!$T$27,PERIODS!E18,IPCA!$O$7=DATA!$T$28,PERIODS!G18) -> 323 | R21: =IFERROR(IF($K$2=$T$16,_xll.BInterpol(FUT!$F$7:$F$28, FUT!$E$7:$E$28, Q21, "Cubic","Skip=True"),_xll.BInterpol($P$7:$P$48, $M$7:$M$48, Q21, "Cubic","Skip=True"))*1,"") -> 9.7410489
B22: ODJ27 Comdty | C22: 21M | D22: 14.079 | E22: 435 | F22: 46477 | G22: =IFERROR(_xll.BCOUNTPERIODS($C$3,F22,"CDR=BZ")*1,"") -> 445 | H22: =_xlfn.IFS(IPCA!$O$7=DATA!$T$26,PERIODS!C19,IPCA!$O$7=DATA!$T$27,PERIODS!E19,IPCA!$O$7=DATA!$T$28,PERIODS!G19) -> 344 | I22: =IFERROR(_xll.BInterpol($G$7:$G$45, $D$7:$D$45, H22, "Cubic","Skip=True")*1,"") -> 14.445382 | P22: =IFERROR(_xll.BCOUNTPERIODS($L$3,O22,"CDR=BZ")*1,"") | Q22: =_xlfn.IFS(IPCA!$O$7=DATA!$T$26,PERIODS!C19,IPCA!$O$7=DATA!$T$27,PERIODS!E19,IPCA!$O$7=DATA!$T$28,PERIODS!G19) -> 344 | R22: =IFERROR(IF($K$2=$T$16,_xll.BInterpol(FUT!$F$7:$F$28, FUT!$E$7:$E$28, Q22, "Cubic","Skip=True"),_xll.BInterpol($P$7:$P$48, $M$7:$M$48, Q22, "Cubic","Skip=True"))*1,"") -> 9.6389539
B23: ODN27 Comdty | C23: 2Y | D23: 13.872 | E23: 504 | F23: 46568 | G23: =IFERROR(_xll.BCOUNTPERIODS($C$3,F23,"CDR=BZ")*1,"") -> 508 | H23: =_xlfn.IFS(IPCA!$O$7=DATA!$T$26,PERIODS!C20,IPCA!$O$7=DATA!$T$27,PERIODS!E20,IPCA!$O$7=DATA!$T$28,PERIODS!G20) -> 363 | I23: =IFERROR(_xll.BInterpol($G$7:$G$45, $D$7:$D$45, H23, "Cubic","Skip=True")*1,"") -> 14.364536 | P23: =IFERROR(_xll.BCOUNTPERIODS($L$3,O23,"CDR=BZ")*1,"") | Q23: =_xlfn.IFS(IPCA!$O$7=DATA!$T$26,PERIODS!C20,IPCA!$O$7=DATA!$T$27,PERIODS!E20,IPCA!$O$7=DATA!$T$28,PERIODS!G20) -> 363 | R23: =IFERROR(IF($K$2=$T$16,_xll.BInterpol(FUT!$F$7:$F$28, FUT!$E$7:$E$28, Q23, "Cubic","Skip=True"),_xll.BInterpol($P$7:$P$48, $M$7:$M$48, Q23, "Cubic","Skip=True"))*1,"") -> 9.5325337
B24: ODV27 Comdty | C24: 27M | D24: 13.708 | E24: 560 | F24: 46660 | G24: =IFERROR(_xll.BCOUNTPERIODS($C$3,F24,"CDR=BZ")*1,"") -> 573 | H24: =_xlfn.IFS(IPCA!$O$7=DATA!$T$26,PERIODS!C21,IPCA!$O$7=DATA!$T$27,PERIODS!E21,IPCA!$O$7=DATA!$T$28,PERIODS!G21) -> 384 | I24: =IFERROR(_xll.BInterpol($G$7:$G$45, $D$7:$D$45, H24, "Cubic","Skip=True")*1,"") -> 14.281 | P24: =IFERROR(_xll.BCOUNTPERIODS($L$3,O24,"CDR=BZ")*1,"") | Q24: =_xlfn.IFS(IPCA!$O$7=DATA!$T$26,PERIODS!C21,IPCA!$O$7=DATA!$T$27,PERIODS!E21,IPCA!$O$7=DATA!$T$28,PERIODS!G21) -> 384 | R24: =IFERROR(IF($K$2=$T$16,_xll.BInterpol(FUT!$F$7:$F$28, FUT!$E$7:$E$28, Q24, "Cubic","Skip=True"),_xll.BInterpol($P$7:$P$48, $M$7:$M$48, Q24, "Cubic","Skip=True"))*1,"") -> 9.4015961
B25: ODF28 Comdty | C25: 30M | D25: 13.558 | E25: 622 | F25: 46751 | G25: =IFERROR(_xll.BCOUNTPERIODS($C$3,F25,"CDR=BZ")*1,"") -> 635 | H25: =_xlfn.IFS(IPCA!$O$7=DATA!$T$26,PERIODS!C22,IPCA!$O$7=DATA!$T$27,PERIODS!E22,IPCA!$O$7=DATA!$T$28,PERIODS!G22) -> 405 | I25: =IFERROR(_xll.BInterpol($G$7:$G$45, $D$7:$D$45, H25, "Cubic","Skip=True")*1,"") -> 14.207421 | P25: =IFERROR(_xll.BCOUNTPERIODS($L$3,O25,"CDR=BZ")*1,"") | Q25: =_xlfn.IFS(IPCA!$O$7=DATA!$T$26,PERIODS!C22,IPCA!$O$7=DATA!$T$27,PERIODS!E22,IPCA!$O$7=DATA!$T$28,PERIODS!G22) -> 405 | R25: =IFERROR(IF($K$2=$T$16,_xll.BInterpol(FUT!$F$7:$F$28, FUT!$E$7:$E$28, Q25, "Cubic","Skip=True"),_xll.BInterpol($P$7:$P$48, $M$7:$M$48, Q25, "Cubic","Skip=True"))*1,"") -> 9.259115
B26: ODJ28 Comdty | C26: 33M | D26: 13.466 | E26: 684 | F26: 46843 | G26: =IFERROR(_xll.BCOUNTPERIODS($C$3,F26,"CDR=BZ")*1,"") -> 699 | H26: =_xlfn.IFS(IPCA!$O$7=DATA!$T$26,PERIODS!C23,IPCA!$O$7=DATA!$T$27,PERIODS!E23,IPCA!$O$7=DATA!$T$28,PERIODS!G23) -> 423 | I26: =IFERROR(_xll.BInterpol($G$7:$G$45, $D$7:$D$45, H26, "Cubic","Skip=True")*1,"") -> 14.149373 | P26: =IFERROR(_xll.BCOUNTPERIODS($L$3,O26,"CDR=BZ")*1,"") | Q26: =_xlfn.IFS(IPCA!$O$7=DATA!$T$26,PERIODS!C23,IPCA!$O$7=DATA!$T$27,PERIODS!E23,IPCA!$O$7=DATA!$T$28,PERIODS!G23) -> 423 | R26: =IFERROR(IF($K$2=$T$16,_xll.BInterpol(FUT!$F$7:$F$28, FUT!$E$7:$E$28, Q26, "Cubic","Skip=True"),_xll.BInterpol($P$7:$P$48, $M$7:$M$48, Q26, "Cubic","Skip=True"))*1,"") -> 9.1314192 | T26: Relative
B27: ODN28 Comdty | C27: 3Y | D27: 13.428 | E27: 756 | F27: 46934 | G27: =IFERROR(_xll.BCOUNTPERIODS($C$3,F27,"CDR=BZ")*1,"") -> 760 | H27: =_xlfn.IFS(IPCA!$O$7=DATA!$T$26,PERIODS!C24,IPCA!$O$7=DATA!$T$27,PERIODS!E24,IPCA!$O$7=DATA!$T$28,PERIODS!G24) -> 444 | I27: =IFERROR(_xll.BInterpol($G$7:$G$45, $D$7:$D$45, H27, "Cubic","Skip=True")*1,"") -> 14.082272 | P27: =IFERROR(_xll.BCOUNTPERIODS($L$3,O27,"CDR=BZ")*1,"") | Q27: =_xlfn.IFS(IPCA!$O$7=DATA!$T$26,PERIODS!C24,IPCA!$O$7=DATA!$T$27,PERIODS!E24,IPCA!$O$7=DATA!$T$28,PERIODS!G24) -> 444 | R27: =IFERROR(IF($K$2=$T$16,_xll.BInterpol(FUT!$F$7:$F$28, FUT!$E$7:$E$28, Q27, "Cubic","Skip=True"),_xll.BInterpol($P$7:$P$48, $M$7:$M$48, Q27, "Cubic","Skip=True"))*1,"") -> 8.9822195 | T27: Settlement
B28: ODV28 Comdty | C28: 39M | D28: 13.425 | E28: 808 | F28: 47025 | G28: =IFERROR(_xll.BCOUNTPERIODS($C$3,F28,"CDR=BZ")*1,"") -> 824 | H28: =_xlfn.IFS(IPCA!$O$7=DATA!$T$26,PERIODS!C25,IPCA!$O$7=DATA!$T$27,PERIODS!E25,IPCA!$O$7=DATA!$T$28,PERIODS!G25) -> 466 | I28: =IFERROR(_xll.BInterpol($G$7:$G$45, $D$7:$D$45, H28, "Cubic","Skip=True")*1,"") -> 14.008389 | P28: =IFERROR(_xll.BCOUNTPERIODS($L$3,O28,"CDR=BZ")*1,"") | Q28: =_xlfn.IFS(IPCA!$O$7=DATA!$T$26,PERIODS!C25,IPCA!$O$7=DATA!$T$27,PERIODS!E25,IPCA!$O$7=DATA!$T$28,PERIODS!G25) -> 466 | R28: =IFERROR(IF($K$2=$T$16,_xll.BInterpol(FUT!$F$7:$F$28, FUT!$E$7:$E$28, Q28, "Cubic","Skip=True"),_xll.BInterpol($P$7:$P$48, $M$7:$M$48, Q28, "Cubic","Skip=True"))*1,"") -> 8.8331308 | T28: End of Month
B29: ODF29 Comdty | C29: 42M | D29: 13.41 | E29: 870 | F29: 47115 | G29: =IFERROR(_xll.BCOUNTPERIODS($C$3,F29,"CDR=BZ")*1,"") -> 883 | H29: =_xlfn.IFS(IPCA!$O$7=DATA!$T$26,PERIODS!C26,IPCA!$O$7=DATA!$T$27,PERIODS!E26,IPCA!$O$7=DATA!$T$28,PERIODS!G26) -> 485 | I29: =IFERROR(_xll.BInterpol($G$7:$G$45, $D$7:$D$45, H29, "Cubic","Skip=True")*1,"") -> 13.944271 | P29: =IFERROR(_xll.BCOUNTPERIODS($L$3,O29,"CDR=BZ")*1,"") | Q29: =_xlfn.IFS(IPCA!$O$7=DATA!$T$26,PERIODS!C26,IPCA!$O$7=DATA!$T$27,PERIODS!E26,IPCA!$O$7=DATA!$T$28,PERIODS!G26) -> 485 | R29: =IFERROR(IF($K$2=$T$16,_xll.BInterpol(FUT!$F$7:$F$28, FUT!$E$7:$E$28, Q29, "Cubic","Skip=True"),_xll.BInterpol($P$7:$P$48, $M$7:$M$48, Q29, "Cubic","Skip=True"))*1,"") -> 8.7164542
B30: ODJ29 Comdty | C30: 45M | D30: 13.409 | E30: 933 | F30: 47206 | G30: =IFERROR(_xll.BCOUNTPERIODS($C$3,F30,"CDR=BZ")*1,"") -> 945 | H30: =_xlfn.IFS(IPCA!$O$7=DATA!$T$26,PERIODS!C27,IPCA!$O$7=DATA!$T$27,PERIODS!E27,IPCA!$O$7=DATA!$T$28,PERIODS!G27) -> 508 | I30: =IFERROR(_xll.BInterpol($G$7:$G$45, $D$7:$D$45, H30, "Cubic","Skip=True")*1,"") -> 13.872 | P30: =IFERROR(_xll.BCOUNTPERIODS($L$3,O30,"CDR=BZ")*1,"") | Q30: =_xlfn.IFS(IPCA!$O$7=DATA!$T$26,PERIODS!C27,IPCA!$O$7=DATA!$T$27,PERIODS!E27,IPCA!$O$7=DATA!$T$28,PERIODS!G27) -> 508 | R30: =IFERROR(IF($K$2=$T$16,_xll.BInterpol(FUT!$F$7:$F$28, FUT!$E$7:$E$28, Q30, "Cubic","Skip=True"),_xll.BInterpol($P$7:$P$48, $M$7:$M$48, Q30, "Cubic","Skip=True"))*1,"") -> 8.5934877
B31: ODN29 Comdty | C31: 4Y | D31: 13.433 | E31: 1008 | F31: 47298 | G31: =IFERROR(_xll.BCOUNTPERIODS($C$3,F31,"CDR=BZ")*1,"") -> 1008 | H31: =_xlfn.IFS(IPCA!$O$7=DATA!$T$26,PERIODS!C28,IPCA!$O$7=DATA!$T$27,PERIODS!E28,IPCA!$O$7=DATA!$T$28,PERIODS!G28) -> 530 | I31: =IFERROR(_xll.BInterpol($G$7:$G$45, $D$7:$D$45, H31, "Cubic","Skip=True")*1,"") -> 13.812354 | P31: =IFERROR(_xll.BCOUNTPERIODS($L$3,O31,"CDR=BZ")*1,"") | Q31: =_xlfn.IFS(IPCA!$O$7=DATA!$T$26,PERIODS!C28,IPCA!$O$7=DATA!$T$27,PERIODS!E28,IPCA!$O$7=DATA!$T$28,PERIODS!G28) -> 530 | R31: =IFERROR(IF($K$2=$T$16,_xll.BInterpol(FUT!$F$7:$F$28, FUT!$E$7:$E$28, Q31, "Cubic","Skip=True"),_xll.BInterpol($P$7:$P$48, $M$7:$M$48, Q31, "Cubic","Skip=True"))*1,"") -> 8.4931214
B32: ODV29 Comdty | C32: 51M | D32: 13.44 | E32: 1057 | F32: 47389 | G32: =IFERROR(_xll.BCOUNTPERIODS($C$3,F32,"CDR=BZ")*1,"") -> 1072 | H32: =_xlfn.IFS(IPCA!$O$7=DATA!$T$26,PERIODS!C29,IPCA!$O$7=DATA!$T$27,PERIODS!E29,IPCA!$O$7=DATA!$T$28,PERIODS!G29) -> 551 | I32: =IFERROR(_xll.BInterpol($G$7:$G$45, $D$7:$D$45, H32, "Cubic","Skip=True")*1,"") -> 13.761009 | P32: =IFERROR(_xll.BCOUNTPERIODS($L$3,O32,"CDR=BZ")*1,"") | Q32: =_xlfn.IFS(IPCA!$O$7=DATA!$T$26,PERIODS!C29,IPCA!$O$7=DATA!$T$27,PERIODS!E29,IPCA!$O$7=DATA!$T$28,PERIODS!G29) -> 551 | R32: =IFERROR(IF($K$2=$T$16,_xll.BInterpol(FUT!$F$7:$F$28, FUT!$E$7:$E$28, Q32, "Cubic","Skip=True"),_xll.BInterpol($P$7:$P$48, $M$7:$M$48, Q32, "Cubic","Skip=True"))*1,"") -> 8.4114867
B33: ODF30 Comdty | C33: 54M | D33: 13.459 | E33: 1119 | F33: 47480 | G33: =IFERROR(_xll.BCOUNTPERIODS($C$3,F33,"CDR=BZ")*1,"") -> 1132 | H33: =_xlfn.IFS(IPCA!$O$7=DATA!$T$26,PERIODS!C30,IPCA!$O$7=DATA!$T$27,PERIODS!E30,IPCA!$O$7=DATA!$T$28,PERIODS!G30) -> 573 | I33: =IFERROR(_xll.BInterpol($G$7:$G$45, $D$7:$D$45, H33, "Cubic","Skip=True")*1,"") -> 13.708 | P33: =IFERROR(_xll.BCOUNTPERIODS($L$3,O33,"CDR=BZ")*1,"") | Q33: =_xlfn.IFS(IPCA!$O$7=DATA!$T$26,PERIODS!C30,IPCA!$O$7=DATA!$T$27,PERIODS!E30,IPCA!$O$7=DATA!$T$28,PERIODS!G30) -> 573 | R33: =IFERROR(IF($K$2=$T$16,_xll.BInterpol(FUT!$F$7:$F$28, FUT!$E$7:$E$28, Q33, "Cubic","Skip=True"),_xll.BInterpol($P$7:$P$48, $M$7:$M$48, Q33, "Cubic","Skip=True"))*1,"") -> 8.3391908 | T33: Annualized
B34: ODJ30 Comdty | C34: 57M | D34: 13.474 | E34: 1181 | F34: 47571 | G34: =IFERROR(_xll.BCOUNTPERIODS($C$3,F34,"CDR=BZ")*1,"") -> 1194 | H34: =_xlfn.IFS(IPCA!$O$7=DATA!$T$26,PERIODS!C31,IPCA!$O$7=DATA!$T$27,PERIODS!E31,IPCA!$O$7=DATA!$T$28,PERIODS!G31) -> 593 | I34: =IFERROR(_xll.BInterpol($G$7:$G$45, $D$7:$D$45, H34, "Cubic","Skip=True")*1,"") -> 13.657486 | P34: =IFERROR(_xll.BCOUNTPERIODS($L$3,O34,"CDR=BZ")*1,"") | Q34: =_xlfn.IFS(IPCA!$O$7=DATA!$T$26,PERIODS!C31,IPCA!$O$7=DATA!$T$27,PERIODS!E31,IPCA!$O$7=DATA!$T$28,PERIODS!G31) -> 593 | R34: =IFERROR(IF($K$2=$T$16,_xll.BInterpol(FUT!$F$7:$F$28, FUT!$E$7:$E$28, Q34, "Cubic","Skip=True"),_xll.BInterpol($P$7:$P$48, $M$7:$M$48, Q34, "Cubic","Skip=True"))*1,"") -> 8.2838191 | T34: Cumulative
B35: ODN30 Comdty | C35: 5Y | D35: 13.495 | E35: 1260 | F35: 47662 | G35: =IFERROR(_xll.BCOUNTPERIODS($C$3,F35,"CDR=BZ")*1,"") -> 1256 | H35: =_xlfn.IFS(IPCA!$O$7=DATA!$T$26,PERIODS!C32,IPCA!$O$7=DATA!$T$27,PERIODS!E32,IPCA!$O$7=DATA!$T$28,PERIODS!G32) -> 613 | I35: =IFERROR(_xll.BInterpol($G$7:$G$45, $D$7:$D$45, H35, "Cubic","Skip=True")*1,"") -> 13.60748 | P35: =IFERROR(_xll.BCOUNTPERIODS($L$3,O35,"CDR=BZ")*1,"") | Q35: =_xlfn.IFS(IPCA!$O$7=DATA!$T$26,PERIODS!C32,IPCA!$O$7=DATA!$T$27,PERIODS!E32,IPCA!$O$7=DATA!$T$28,PERIODS!G32) -> 613 | R35: =IFERROR(IF($K$2=$T$16,_xll.BInterpol(FUT!$F$7:$F$28, FUT!$E$7:$E$28, Q35, "Cubic","Skip=True"),_xll.BInterpol($P$7:$P$48, $M$7:$M$48, Q35, "Cubic","Skip=True"))*1,"") -> 8.2370012
