Workbook

Sheet hp
A1: Start date | B1: 42057
A2: End date | B2: =TODAY() -> 45849
C4: =_xll.BSRCH("fi:supra_national_brl","dir=h","cols=79;rows=1") -> id | D4: ZM903300 Corp | E4: ZM819269 Corp | F4: BJ485726 Corp | G4: YN482880 Corp | H4: BT802365 Corp | I4: BM044614 Corp | J4: BT735061 Corp | K4: BW499053 Corp | L4: BN496886 Corp | M4: BO165590 Corp | N4: YU913074 Corp | O4: YU416694 Corp | P4: BU614742 Corp | Q4: ZL353780 Corp | R4: BT642376 Corp | S4: YN748671 Corp | T4: YS542553 Corp | U4: YS509089 Corp | V4: ZL479769 Corp | W4: YR474692 Corp | X4: AX813975 Corp | Y4: AN703481 Corp | Z4: YU254355 Corp | AA4: ZH961035 Corp | AB4: BT396062 Corp | AC4: BN411719 Corp | AD4: BR588576 Corp | AE4: ZR500008 Corp | AF4: BN718496 Corp | AG4: BW577080 Corp | AH4: BO169050 Corp | AI4: YW833064 Corp | AJ4: BK458282 Corp | AK4: BQ799145 Corp | AL4: YN649376 Corp | AM4: YX291422 Corp | AN4: BN756935 Corp | AO4: BR425633 Corp | AP4: YR732902 Corp | AQ4: ZM294074 Corp | AR4: ZM636659 Corp | AS4: AP550972 Corp | AT4: BQ799727 Corp | AU4: AZ257187 Corp | AV4: BT481997 Corp | AW4: ZQ802560 Corp | AX4: AN629808 Corp | AY4: YQ448515 Corp | AZ4: ZS021650 Corp | BA4: AP971344 Corp | BB4: ZL354478 Corp | BC4: ZL641942 Corp | BD4: YX800450 Corp | BE4: BT482185 Corp | BF4: ZH598780 Corp | BG4: BW982245 Corp | BH4: BV443414 Corp | BI4: BV963634 Corp | BJ4: BQ725281 Corp | BK4: BS187660 Corp | BL4: BQ376842 Corp | BM4: ZJ582077 Corp | BN4: ZO295365 Corp | BO4: BQ706131 Corp | BP4: PP590IOV M-Mkt | BQ4: BQ721820 Corp | BR4: BQ721824 Corp | BS4: BQ721132 Corp | BT4: BQ722937 Corp | BU4: BP909148 Corp | BV4: BP780031 Corp | BW4: BN542084 Corp | BX4: BU793824 Corp | BY4: BW057488 Corp | BZ4: BO510428 Corp | CA4: BQ747472 Corp | CB4: AT637750 Corp | CC4: BP322887 Corp
C5: {=_xll.BDH(D$4 & " Corp","px_last","02/22/2015","","per=m","days=all","fill=0")} -> 42062 | D5: 0 | E5: {=_xll.BDH(E$4 & " Corp","px_last","02/22/2015","","per=m","days=all","fill=0","dts=h")} -> 0 | F5: {=_xll.BDH(F$4 & " Corp","px_last","02/22/2015","","per=m","days=all","fill=0","dts=h")} -> 0 | G5: {=_xll.BDH(G$4 & " Corp","px_last","02/22/2015","","per=m","days=all","fill=0","dts=h")} -> 0 | H5: {=_xll.BDH(H$4 & " Corp","px_last","02/22/2015","","per=m","days=all","fill=0","dts=h")} -> 0 | I5: {=_xll.BDH(I$4 & " Corp","px_last","02/22/2015","","per=m","days=all","fill=0","dts=h")} -> 0 | J5: {=_xll.BDH(J$4 & " Corp","px_last","02/22/2015","","per=m","days=all","fill=0","dts=h")} -> 0 | K5: {=_xll.BDH(K$4 & " Corp","px_last","02/22/2015","","per=m","days=all","fill=0","dts=h")} -> 0 | L5: {=_xll.BDH(L$4 & " Corp","px_last","02/22/2015","","per=m","days=all","fill=0","dts=h")} -> 0 | ... CC5: {=_xll.BDH(CC$4 & " Corp","px_last","02/22/2015","","per=m","days=all","fill=0","dts=h")} -> 0
C6: 42094 | D6: 0 | E6: 0 | F6: 0 | G6: 0 | H6: 0 | I6: 0 | J6: 0 | K6: 0 | L6: 0 | M6: 0 | N6: 0 | O6: 0 | P6: 0 | Q6: 0 | R6: 0 | S6: 0 | T6: 0 | U6: 0 | V6: 0 | W6: 0 | X6: 0 | Y6: 0 | Z6: 0 | AA6: 0 | AB6: 0 | AC6: 0 | AD6: 0 | AE6: 0 | AF6: 0 | AG6: 0 | AH6: 0 | AI6: 0 | AJ6: 0 | AK6: 0 | AL6: 0 | AM6: 0 | AN6: 0 | AO6: 0 | AP6: 0 | AQ6: 0 | AR6: 0 | AS6: 0 | AT6: 0 | AU6: 0 | AV6: 0 | AW6: 0 | AX6: 0 | AY6: 0 | AZ6: 0 | BA6: 0 | BB6: 0 | BC6: 0 | BD6: 0 | BE6: 0 | BF6: 0 | BG6: 0 | BH6: 0 | BI6: 0 | BJ6: 0 | BK6: 0 | BL6: 0 | BM6: 0 | BN6: 0 | BO6: 0 | BP6: 0 | BQ6: 0 | BR6: 0 | BS6: 0 | BT6: 0 | BU6: 0 | BV6: 0 | BW6: 0 | BX6: 0 | BY6: 0 | BZ6: 0 | CA6: 0 | CB6: 0 | CC6: 0
C7: 42124 | D7: 0 | E7: 0 | F7: 0 | G7: 0 | H7: 0 | I7: 0 | J7: 0 | K7: 0 | L7: 0 | M7: 0 | N7: 0 | O7: 0 | P7: 0 | Q7: 0 | R7: 0 | S7: 0 | T7: 0 | U7: 0 | V7: 0 | W7: 0 | X7: 0 | Y7: 0 | Z7: 0 | AA7: 0 | AB7: 0 | AC7: 0 | AD7: 0 | AE7: 0 | AF7: 0 | AG7: 0 | AH7: 0 | AI7: 0 | AJ7: 0 | AK7: 0 | AL7: 0 | AM7: 0 | AN7: 0 | AO7: 0 | AP7: 0 | AQ7: 0 | AR7: 0 | AS7: 0 | AT7: 0 | AU7: 0 | AV7: 0 | AW7: 0 | AX7: 0 | AY7: 0 | AZ7: 0 | BA7: 0 | BB7: 0 | BC7: 0 | BD7: 0 | BE7: 0 | BF7: 0 | BG7: 0 | BH7: 0 | BI7: 0 | BJ7: 0 | BK7: 0 | BL7: 0 | BM7: 0 | BN7: 0 | BO7: 0 | BP7: 0 | BQ7: 0 | BR7: 0 | BS7: 0 | BT7: 0 | BU7: 0 | BV7: 0 | BW7: 0 | BX7: 0 | BY7: 0 | BZ7: 0 | CA7: 0 | CB7: 0 | CC7: 0
C8: 42153 | D8: 0 | E8: 0 | F8: 0 | G8: 0 | H8: 0 | I8: 0 | J8: 0 | K8: 0 | L8: 0 | M8: 0 | N8: 0 | O8: 0 | P8: 0 | Q8: 0 | R8: 0 | S8: 0 | T8: 0 | U8: 0 | V8: 0 | W8: 0 | X8: 0 | Y8: 0 | Z8: 0 | AA8: 0 | AB8: 0 | AC8: 0 | AD8: 0 | AE8: 0 | AF8: 0 | AG8: 0 | AH8: 0 | AI8: 0 | AJ8: 0 | AK8: 0 | AL8: 0 | AM8: 0 | AN8: 0 | AO8: 0 | AP8: 0 | AQ8: 0 | AR8: 0 | AS8: 0 | AT8: 0 | AU8: 0 | AV8: 0 | AW8: 0 | AX8: 0 | AY8: 0 | AZ8: 0 | BA8: 0 | BB8: 0 | BC8: 0 | BD8: 0 | BE8: 0 | BF8: 0 | BG8: 0 | BH8: 0 | BI8: 0 | BJ8: 0 | BK8: 0 | BL8: 0 | BM8: 0 | BN8: 0 | BO8: 0 | BP8: 0 | BQ8: 0 | BR8: 0 | BS8: 0 | BT8: 0 | BU8: 0 | BV8: 0 | BW8: 0 | BX8: 0 | BY8: 0 | BZ8: 0 | CA8: 0 | CB8: 0 | CC8: 0
C9: 42185 | D9: 0 | E9: 0 | F9: 0 | G9: 0 | H9: 0 | I9: 0 | J9: 0 | K9: 0 | L9: 0 | M9: 0 | N9: 0 | O9: 0 | P9: 0 | Q9: 0 | R9: 0 | S9: 0 | T9: 0 | U9: 0 | V9: 0 | W9: 0 | X9: 0 | Y9: 0 | Z9: 0 | AA9: 0 | AB9: 0 | AC9: 0 | AD9: 0 | AE9: 0 | AF9: 0 | AG9: 0 | AH9: 0 | AI9: 0 | AJ9: 0 | AK9: 0 | AL9: 0 | AM9: 0 | AN9: 0 | AO9: 0 | AP9: 0 | AQ9: 0 | AR9: 0 | AS9: 0 | AT9: 0 | AU9: 0 | AV9: 0 | AW9: 0 | AX9: 0 | AY9: 0 | AZ9: 0 | BA9: 0 | BB9: 0 | BC9: 0 | BD9: 0 | BE9: 0 | BF9: 0 | BG9: 0 | BH9: 0 | BI9: 0 | BJ9: 0 | BK9: 0 | BL9: 0 | BM9: 0 | BN9: 0 | BO9: 0 | BP9: 0 | BQ9: 0 | BR9: 0 | BS9: 0 | BT9: 0 | BU9: 0 | BV9: 0 | BW9: 0 | BX9: 0 | BY9: 0 | BZ9: 0 | CA9: 0 | CB9: 0 | CC9: 0
C10: 42216 | D10: 0 | E10: 0 | F10: 0 | G10: 0 | H10: 0 | I10: 0 | J10: 0 | K10: 0 | L10: 0 | M10: 0 | N10: 0 | O10: 0 | P10: 0 | Q10: 0 | R10: 0 | S10: 0 | T10: 0 | U10: 0 | V10: 0 | W10: 0 | X10: 0 | Y10: 0 | Z10: 0 | AA10: 0 | AB10: 0 | AC10: 0 | AD10: 0 | AE10: 0 | AF10: 0 | AG10: 0 | AH10: 0 | AI10: 0 | AJ10: 0 | AK10: 0 | AL10: 0 | AM10: 0 | AN10: 0 | AO10: 0 | AP10: 0 | AQ10: 0 | AR10: 0 | AS10: 0 | AT10: 0 | AU10: 0 | AV10: 0 | AW10: 0 | AX10: 0 | AY10: 0 | AZ10: 0 | BA10: 0 | BB10: 0 | BC10: 0 | BD10: 0 | BE10: 0 | BF10: 0 | BG10: 0 | BH10: 0 | BI10: 0 | BJ10: 0 | BK10: 0 | BL10: 0 | BM10: 0 | BN10: 0 | BO10: 0 | BP10: 0 | BQ10: 0 | BR10: 0 | BS10: 0 | BT10: 0 | BU10: 0 | BV10: 0 | BW10: 0 | BX10: 0 | BY10: 0 | BZ10: 0 | CA10: 0 | CB10: 0 | CC10: 0
C11: 42247 | D11: 0 | E11: 0 | F11: 0 | G11: 0 | H11: 0 | I11: 0 | J11: 0 | K11: 0 | L11: 0 | M11: 0 | N11: 0 | O11: 0 | P11: 0 | Q11: 0 | R11: 0 | S11: 0 | T11: 0 | U11: 0 | V11: 0 | W11: 0 | X11: 0 | Y11: 0 | Z11: 0 | AA11: 0 | AB11: 0 | AC11: 0 | AD11: 0 | AE11: 0 | AF11: 0 | AG11: 0 | AH11: 0 | AI11: 0 | AJ11: 0 | AK11: 0 | AL11: 0 | AM11: 0 | AN11: 0 | AO11: 0 | AP11: 0 | AQ11: 0 | AR11: 0 | AS11: 0 | AT11: 0 | AU11: 0 | AV11: 0 | AW11: 0 | AX11: 0 | AY11: 0 | AZ11: 0 | BA11: 0 | BB11: 0 | BC11: 0 | BD11: 0 | BE11: 0 | BF11: 0 | BG11: 0 | BH11: 0 | BI11: 0 | BJ11: 0 | BK11: 0 | BL11: 0 | BM11: 0 | BN11: 0 | BO11: 0 | BP11: 0 | BQ11: 0 | BR11: 0 | BS11: 0 | BT11: 0 | BU11: 0 | BV11: 0 | BW11: 0 | BX11: 0 | BY11: 0 | BZ11: 0 | CA11: 0 | CB11: 0 | CC11: 0
C12: 42277 | D12: 0 | E12: 0 | F12: 0 | G12: 0 | H12: 0 | I12: 0 | J12: 0 | K12: 0 | L12: 0 | M12: 0 | N12: 0 | O12: 0 | P12: 0 | Q12: 0 | R12: 0 | S12: 0 | T12: 0 | U12: 0 | V12: 0 | W12: 0 | X12: 0 | Y12: 0 | Z12: 0 | AA12: 0 | AB12: 0 | AC12: 0 | AD12: 0 | AE12: 0 | AF12: 0 | AG12: 0 | AH12: 0 | AI12: 0 | AJ12: 0 | AK12: 0 | AL12: 0 | AM12: 0 | AN12: 0 | AO12: 0 | AP12: 0 | AQ12: 0 | AR12: 0 | AS12: 0 | AT12: 0 | AU12: 0 | AV12: 0 | AW12: 0 | AX12: 0 | AY12: 0 | AZ12: 0 | BA12: 0 | BB12: 0 | BC12: 0 | BD12: 0 | BE12: 0 | BF12: 0 | BG12: 0 | BH12: 0 | BI12: 0 | BJ12: 0 | BK12: 0 | BL12: 0 | BM12: 0 | BN12: 0 | BO12: 0 | BP12: 0 | BQ12: 0 | BR12: 0 | BS12: 0 | BT12: 0 | BU12: 0 | BV12: 0 | BW12: 0 | BX12: 0 | BY12: 0 | BZ12: 0 | CA12: 0 | CB12: 0 | CC12: 0
C13: 42307 | D13: 0 | E13: 0 | F13: 0 | G13: 0 | H13: 0 | I13: 0 | J13: 0 | K13: 0 | L13: 0 | M13: 0 | N13: 0 | O13: 0 | P13: 0 | Q13: 0 | R13: 0 | S13: 0 | T13: 0 | U13: 0 | V13: 0 | W13: 0 | X13: 0 | Y13: 0 | Z13: 0 | AA13: 0 | AB13: 0 | AC13: 0 | AD13: 0 | AE13: 0 | AF13: 0 | AG13: 0 | AH13: 0 | AI13: 0 | AJ13: 0 | AK13: 0 | AL13: 0 | AM13: 0 | AN13: 0 | AO13: 0 | AP13: 0 | AQ13: 0 | AR13: 0 | AS13: 0 | AT13: 0 | AU13: 0 | AV13: 0 | AW13: 0 | AX13: 0 | AY13: 0 | AZ13: 0 | BA13: 0 | BB13: 0 | BC13: 0 | BD13: 0 | BE13: 0 | BF13: 0 | BG13: 0 | BH13: 0 | BI13: 0 | BJ13: 0 | BK13: 0 | BL13: 0 | BM13: 0 | BN13: 0 | BO13: 0 | BP13: 0 | BQ13: 0 | BR13: 0 | BS13: 0 | BT13: 0 | BU13: 0 | BV13: 0 | BW13: 0 | BX13: 0 | BY13: 0 | BZ13: 0 | CA13: 0 | CB13: 0 | CC13: 0
C14: 42338 | D14: 0 | E14: 0 | F14: 0 | G14: 0 | H14: 0 | I14: 0 | J14: 0 | K14: 0 | L14: 0 | M14: 0 | N14: 0 | O14: 0 | P14: 0 | Q14: 0 | R14: 0 | S14: 0 | T14: 0 | U14: 0 | V14: 0 | W14: 0 | X14: 0 | Y14: 0 | Z14: 0 | AA14: 0 | AB14: 0 | AC14: 0 | AD14: 0 | AE14: 0 | AF14: 0 | AG14: 0 | AH14: 0 | AI14: 0 | AJ14: 0 | AK14: 0 | AL14: 0 | AM14: 0 | AN14: 0 | AO14: 0 | AP14: 0 | AQ14: 0 | AR14: 0 | AS14: 0 | AT14: 0 | AU14: 0 | AV14: 0 | AW14: 0 | AX14: 0 | AY14: 0 | AZ14: 0 | BA14: 0 | BB14: 0 | BC14: 0 | BD14: 0 | BE14: 0 | BF14: 0 | BG14: 0 | BH14: 0 | BI14: 0 | BJ14: 0 | BK14: 0 | BL14: 0 | BM14: 0 | BN14: 0 | BO14: 0 | BP14: 0 | BQ14: 0 | BR14: 0 | BS14: 0 | BT14: 0 | BU14: 0 | BV14: 0 | BW14: 0 | BX14: 0 | BY14: 0 | BZ14: 0 | CA14: 0 | CB14: 0 | CC14: 0
C15: 42369 | D15: 0 | E15: 0 | F15: 0 | G15: 0 | H15: 0 | I15: 0 | J15: 0 | K15: 0 | L15: 0 | M15: 0 | N15: 0 | O15: 0 | P15: 0 | Q15: 0 | R15: 0 | S15: 0 | T15: 0 | U15: 0 | V15: 0 | W15: 0 | X15: 0 | Y15: 0 | Z15: 0 | AA15: 0 | AB15: 0 | AC15: 0 | AD15: 0 | AE15: 0 | AF15: 0 | AG15: 0 | AH15: 0 | AI15: 0 | AJ15: 0 | AK15: 0 | AL15: 0 | AM15: 0 | AN15: 0 | AO15: 0 | AP15: 0 | AQ15: 0 | AR15: 0 | AS15: 0 | AT15: 0 | AU15: 0 | AV15: 0 | AW15: 0 | AX15: 0 | AY15: 0 | AZ15: 0 | BA15: 0 | BB15: 0 | BC15: 0 | BD15: 0 | BE15: 0 | BF15: 0 | BG15: 0 | BH15: 0 | BI15: 0 | BJ15: 0 | BK15: 0 | BL15: 0 | BM15: 0 | BN15: 0 | BO15: 0 | BP15: 0 | BQ15: 0 | BR15: 0 | BS15: 0 | BT15: 0 | BU15: 0 | BV15: 0 | BW15: 0 | BX15: 0 | BY15: 0 | BZ15: 0 | CA15: 0 | CB15: 0 | CC15: 0
C16: 42398 | D16: 0 | E16: 0 | F16: 0 | G16: 0 | H16: 0 | I16: 0 | J16: 0 | K16: 0 | L16: 0 | M16: 0 | N16: 0 | O16: 0 | P16: 0 | Q16: 0 | R16: 0 | S16: 0 | T16: 0 | U16: 0 | V16: 0 | W16: 0 | X16: 0 | Y16: 0 | Z16: 0 | AA16: 0 | AB16: 0 | AC16: 0 | AD16: 0 | AE16: 0 | AF16: 0 | AG16: 0 | AH16: 0 | AI16: 0 | AJ16: 0 | AK16: 0 | AL16: 0 | AM16: 0 | AN16: 0 | AO16: 0 | AP16: 0 | AQ16: 0 | AR16: 0 | AS16: 0 | AT16: 0 | AU16: 0 | AV16: 0 | AW16: 0 | AX16: 0 | AY16: 0 | AZ16: 0 | BA16: 0 | BB16: 0 | BC16: 0 | BD16: 0 | BE16: 0 | BF16: 0 | BG16: 0 | BH16: 0 | BI16: 0 | BJ16: 0 | BK16: 0 | BL16: 0 | BM16: 0 | BN16: 0 | BO16: 0 | BP16: 0 | BQ16: 0 | BR16: 0 | BS16: 0 | BT16: 0 | BU16: 0 | BV16: 0 | BW16: 0 | BX16: 0 | BY16: 0 | BZ16: 0 | CA16: 0 | CB16: 0 | CC16: 0
C17: 42429 | D17: 0 | E17: 0 | F17: 0 | G17: 0 | H17: 0 | I17: 0 | J17: 0 | K17: 0 | L17: 0 | M17: 0 | N17: 0 | O17: 0 | P17: 0 | Q17: 0 | R17: 0 | S17: 0 | T17: 0 | U17: 0 | V17: 0 | W17: 0 | X17: 0 | Y17: 0 | Z17: 0 | AA17: 0 | AB17: 0 | AC17: 0 | AD17: 0 | AE17: 0 | AF17: 0 | AG17: 0 | AH17: 0 | AI17: 0 | AJ17: 0 | AK17: 0 | AL17: 0 | AM17: 0 | AN17: 0 | AO17: 0 | AP17: 0 | AQ17: 0 | AR17: 0 | AS17: 0 | AT17: 0 | AU17: 0 | AV17: 0 | AW17: 0 | AX17: 0 | AY17: 0 | AZ17: 0 | BA17: 0 | BB17: 0 | BC17: 0 | BD17: 0 | BE17: 0 | BF17: 0 | BG17: 0 | BH17: 0 | BI17: 0 | BJ17: 0 | BK17: 0 | BL17: 0 | BM17: 0 | BN17: 0 | BO17: 0 | BP17: 0 | BQ17: 0 | BR17: 0 | BS17: 0 | BT17: 0 | BU17: 0 | BV17: 0 | BW17: 0 | BX17: 0 | BY17: 0 | BZ17: 0 | CA17: 0 | CB17: 0 | CC17: 0
... C129: 45838 | D129: 96.938 | E129: 26.541 | F129: 58.285 | G129: 95.183 | H129: 93.504 | I129: 97.213 | J129: 48.278 | K129: 71.561 | L129: 95.468 | M129: 18.348 | N129: 95.185 | O129: 93.37 | P129: 16.785 | Q129: 0 | R129: 95.337 | S129: 97.255 | T129: 102.168 | U129: 98.325 | V129: 24.574 | W129: 34.74 | X129: 95.183 | Y129: 79.931 | Z129: 95.94 | AA129: 24.782 | AB129: 95.475 | AC129: 86.735 | AD129: 94.309 | AE129: 87.269 | AF129: 87.348 | AG129: 27.238 | AH129: 79.009 | AI129: 87.057 | AJ129: 99.647 | AK129: 82.805 | AL129: 94.037 | AM129: 36.254 | AN129: 95.541 | AO129: 88.178 | AP129: 101.801 | AQ129: 98.515 | AR129: 95.751 | AS129: 55.514 | AT129: 81.987 | AU129: 87.337 | AV129: 97.566 | AW129: 74.157 | AX129: 55.783 | AY129: 37.808 | AZ129: 75.841 | BA129: 75.834 | BB129: 73.52 | BC129: 97.601 | BD129: 98.102 | BE129: 66.435 | BF129: 82.271 | BG129: 97.056 | BH129: 0 | BI129: 94.678 | BJ129: 0 | BK129: 98.074 | BL129: 82.369 | BM129: 88.343 | BN129: 97.138 | BO129: 0 | BP129: 0 | BQ129: 0 | BR129: 0 | BS129: 0 | BT129: 0 | BU129: 0 | BV129: 0 | BW129: 0 | BX129: 0 | BY129: 0 | BZ129: 90.367 | CA129: 69.086 | CB129: 0 | CC129: 81.163

Sheet ya
A1: Start date | B1: 42057
A2: End date | B2: =TODAY() -> 45849
C4: =_xll.BSRCH("fi:supra_national_brl","dir=h","cols=79;rows=1") -> id | D4: ZM903300 Corp | E4: ZM819269 Corp | F4: BJ485726 Corp | G4: YN482880 Corp | H4: BT802365 Corp | I4: BM044614 Corp | J4: BT735061 Corp | K4: BW499053 Corp | L4: BN496886 Corp | M4: BO165590 Corp | N4: YU913074 Corp | O4: YU416694 Corp | P4: BU614742 Corp | Q4: ZL353780 Corp | R4: BT642376 Corp | S4: YS542553 Corp | T4: YN748671 Corp | U4: YS509089 Corp | V4: ZL479769 Corp | W4: YR474692 Corp | X4: AX813975 Corp | Y4: AN703481 Corp | Z4: YU254355 Corp | AA4: ZH961035 Corp | AB4: BT396062 Corp | AC4: BN411719 Corp | AD4: BR588576 Corp | AE4: ZR500008 Corp | AF4: BN718496 Corp | AG4: BW577080 Corp | AH4: BO169050 Corp | AI4: YW833064 Corp | AJ4: BK458282 Corp | AK4: YN649376 Corp | AL4: BQ799145 Corp | AM4: YX291422 Corp | AN4: BN756935 Corp | AO4: BR425633 Corp | AP4: YR732902 Corp | AQ4: ZM294074 Corp | AR4: ZM636659 Corp | AS4: AP550972 Corp | AT4: BQ799727 Corp | AU4: AZ257187 Corp | AV4: BT481997 Corp | AW4: ZQ802560 Corp | AX4: AN629808 Corp | AY4: ZS021650 Corp | AZ4: YQ448515 Corp | BA4: AP971344 Corp | BB4: ZL354478 Corp | BC4: YX800450 Corp | BD4: ZL641942 Corp | BE4: BT482185 Corp | BF4: ZH598780 Corp | BG4: BW982245 Corp | BH4: BV443414 Corp | BI4: BV963634 Corp | BJ4: BQ725281 Corp | BK4: ZO295365 Corp | BL4: BQ376842 Corp | BM4: BS187660 Corp | BN4: ZJ582077 Corp | BO4: PP590IOV M-Mkt | BP4: BQ721132 Corp | BQ4: BQ721820 Corp | BR4: BQ721824 Corp | BS4: BQ722937 Corp | BT4: BP909148 Corp | BU4: BN542084 Corp | BV4: BP780031 Corp | BW4: BU793824 Corp | BX4: BW057488 Corp | BY4: BQ706131 Corp | BZ4: BP322887 Corp | CA4: AT637750 Corp | CB4: BO510428 Corp | CC4: BQ747472 Corp
C5: {=_xll.BDH(D$4 & " Corp","px_last","02/22/2015","","per=m","days=all","fill=0","dts=o")} -> 42062 | D5: {=IF(hp!D5=0,0,_xll.BDP(D$4,"YAS_BOND_YLD", "YAS_BOND_PX",hp!D5, "SETTLE_DT", TEXT(ya!$C5,"YYYYMMDD")))} -> 0 | E5: {=IF(hp!E5=0,0,_xll.BDP(E$4,"YAS_BOND_YLD", "YAS_BOND_PX",hp!E5, "SETTLE_DT", TEXT(ya!$C5,"YYYYMMDD")))} -> 0 | F5: {=IF(hp!F5=0,0,_xll.BDP(F$4,"YAS_BOND_YLD", "YAS_BOND_PX",hp!F5, "SETTLE_DT", TEXT(ya!$C5,"YYYYMMDD")))} -> 0 | G5: {=IF(hp!G5=0,0,_xll.BDP(G$4,"YAS_BOND_YLD", "YAS_BOND_PX",hp!G5, "SETTLE_DT", TEXT(ya!$C5,"YYYYMMDD")))} -> 0 | H5: {=IF(hp!H5=0,0,_xll.BDP(H$4,"YAS_BOND_YLD", "YAS_BOND_PX",hp!H5, "SETTLE_DT", TEXT(ya!$C5,"YYYYMMDD")))} -> 0 | I5: {=IF(hp!I5=0,0,_xll.BDP(I$4,"YAS_BOND_YLD", "YAS_BOND_PX",hp!I5, "SETTLE_DT", TEXT(ya!$C5,"YYYYMMDD")))} -> 0 | J5: {=IF(hp!J5=0,0,_xll.BDP(J$4,"YAS_BOND_YLD", "YAS_BOND_PX",hp!J5, "SETTLE_DT", TEXT(ya!$C5,"YYYYMMDD")))} -> 0 | K5: {=IF(hp!K5=0,0,_xll.BDP(K$4,"YAS_BOND_YLD", "YAS_BOND_PX",hp!K5, "SETTLE_DT", TEXT(ya!$C5,"YYYYMMDD")))} -> 0 | ... CC5: {=IF(hp!CC5=0,0,_xll.BDP(CC$4,"YAS_BOND_YLD", "YAS_BOND_PX",hp!CC5, "SETTLE_DT", TEXT(ya!$C5,"YYYYMMDD")))} -> 0
C6: 42094 | D6: {=IF(hp!D6=0,0,_xll.BDP(D$4,"YAS_BOND_YLD", "YAS_BOND_PX",hp!D6, "SETTLE_DT", TEXT(ya!$C6,"YYYYMMDD")))} -> 0 | E6: {=IF(hp!E6=0,0,_xll.BDP(E$4,"YAS_BOND_YLD", "YAS_BOND_PX",hp!E6, "SETTLE_DT", TEXT(ya!$C6,"YYYYMMDD")))} -> 0 | F6: {=IF(hp!F6=0,0,_xll.BDP(F$4,"YAS_BOND_YLD", "YAS_BOND_PX",hp!F6, "SETTLE_DT", TEXT(ya!$C6,"YYYYMMDD")))} -> 0 | G6: {=IF(hp!G6=0,0,_xll.BDP(G$4,"YAS_BOND_YLD", "YAS_BOND_PX",hp!G6, "SETTLE_DT", TEXT(ya!$C6,"YYYYMMDD")))} -> 0 | H6: {=IF(hp!H6=0,0,_xll.BDP(H$4,"YAS_BOND_YLD", "YAS_BOND_PX",hp!H6, "SETTLE_DT", TEXT(ya!$C6,"YYYYMMDD")))} -> 0 | I6: {=IF(hp!I6=0,0,_xll.BDP(I$4,"YAS_BOND_YLD", "YAS_BOND_PX",hp!I6, "SETTLE_DT", TEXT(ya!$C6,"YYYYMMDD")))} -> 0 | J6: {=IF(hp!J6=0,0,_xll.BDP(J$4,"YAS_BOND_YLD", "YAS_BOND_PX",hp!J6, "SETTLE_DT", TEXT(ya!$C6,"YYYYMMDD")))} -> 0 | K6: {=IF(hp!K6=0,0,_xll.BDP(K$4,"YAS_BOND_YLD", "YAS_BOND_PX",hp!K6, "SETTLE_DT", TEXT(ya!$C6,"YYYYMMDD")))} -> 0 | ... CC6: {=IF(hp!CC6=0,0,_xll.BDP(CC$4,"YAS_BOND_YLD", "YAS_BOND_PX",hp!CC6, "SETTLE_DT", TEXT(ya!$C6,"YYYYMMDD")))} -> 0
C7: 42124 | D7: {=IF(hp!D7=0,0,_xll.BDP(D$4,"YAS_BOND_YLD", "YAS_BOND_PX",hp!D7, "SETTLE_DT", TEXT(ya!$C7,"YYYYMMDD")))} -> 0 | E7: {=IF(hp!E7=0,0,_xll.BDP(E$4,"YAS_BOND_YLD", "YAS_BOND_PX",hp!E7, "SETTLE_DT", TEXT(ya!$C7,"YYYYMMDD")))} -> 0 | F7: {=IF(hp!F7=0,0,_xll.BDP(F$4,"YAS_BOND_YLD", "YAS_BOND_PX",hp!F7, "SETTLE_DT", TEXT(ya!$C7,"YYYYMMDD")))} -> 0 | G7: {=IF(hp!G7=0,0,_xll.BDP(G$4,"YAS_BOND_YLD", "YAS_BOND_PX",hp!G7, "SETTLE_DT", TEXT(ya!$C7,"YYYYMMDD")))} -> 0 | H7: {=IF(hp!H7=0,0,_xll.BDP(H$4,"YAS_BOND_YLD", "YAS_BOND_PX",hp!H7, "SETTLE_DT", TEXT(ya!$C7,"YYYYMMDD")))} -> 0 | I7: {=IF(hp!I7=0,0,_xll.BDP(I$4,"YAS_BOND_YLD", "YAS_BOND_PX",hp!I7, "SETTLE_DT", TEXT(ya!$C7,"YYYYMMDD")))} -> 0 | J7: {=IF(hp!J7=0,0,_xll.BDP(J$4,"YAS_BOND_YLD", "YAS_BOND_PX",hp!J7, "SETTLE_DT", TEXT(ya!$C7,"YYYYMMDD")))} -> 0 | K7: {=IF(hp!K7=0,0,_xll.BDP(K$4,"YAS_BOND_YLD", "YAS_BOND_PX",hp!K7, "SETTLE_DT", TEXT(ya!$C7,"YYYYMMDD")))} -> 0 | ... CC7: {=IF(hp!CC7=0,0,_xll.BDP(CC$4,"YAS_BOND_YLD", "YAS_BOND_PX",hp!CC7, "SETTLE_DT", TEXT(ya!$C7,"YYYYMMDD")))} -> 0
C8: 42153 | D8: {=IF(hp!D8=0,0,_xll.BDP(D$4,"YAS_BOND_YLD", "YAS_BOND_PX",hp!D8, "SETTLE_DT", TEXT(ya!$C8,"YYYYMMDD")))} -> 0 | E8: {=IF(hp!E8=0,0,_xll.BDP(E$4,"YAS_BOND_YLD", "YAS_BOND_PX",hp!E8, "SETTLE_DT", TEXT(ya!$C8,"YYYYMMDD")))} -> 0 | F8: {=IF(hp!F8=0,0,_xll.BDP(F$4,"YAS_BOND_YLD", "YAS_BOND_PX",hp!F8, "SETTLE_DT", TEXT(ya!$C8,"YYYYMMDD")))} -> 0 | G8: {=IF(hp!G8=0,0,_xll.BDP(G$4,"YAS_BOND_YLD", "YAS_BOND_PX",hp!G8, "SETTLE_DT", TEXT(ya!$C8,"YYYYMMDD")))} -> 0 | H8: {=IF(hp!H8=0,0,_xll.BDP(H$4,"YAS_BOND_YLD", "YAS_BOND_PX",hp!H8, "SETTLE_DT", TEXT(ya!$C8,"YYYYMMDD")))} -> 0 | I8: {=IF(hp!I8=0,0,_xll.BDP(I$4,"YAS_BOND_YLD", "YAS_BOND_PX",hp!I8, "SETTLE_DT", TEXT(ya!$C8,"YYYYMMDD")))} -> 0 | J8: {=IF(hp!J8=0,0,_xll.BDP(J$4,"YAS_BOND_YLD", "YAS_BOND_PX",hp!J8, "SETTLE_DT", TEXT(ya!$C8,"YYYYMMDD")))} -> 0 | K8: {=IF(hp!K8=0,0,_xll.BDP(K$4,"YAS_BOND_YLD", "YAS_BOND_PX",hp!K8, "SETTLE_DT", TEXT(ya!$C8,"YYYYMMDD")))} -> 0 | ... CC8: {=IF(hp!CC8=0,0,_xll.BDP(CC$4,"YAS_BOND_YLD", "YAS_BOND_PX",hp!CC8, "SETTLE_DT", TEXT(ya!$C8,"YYYYMMDD")))} -> 0
C9: 42185 | D9: {=IF(hp!D9=0,0,_xll.BDP(D$4,"YAS_BOND_YLD", "YAS_BOND_PX",hp!D9, "SETTLE_DT", TEXT(ya!$C9,"YYYYMMDD")))} -> 0 | E9: {=IF(hp!E9=0,0,_xll.BDP(E$4,"YAS_BOND_YLD", "YAS_BOND_PX",hp!E9, "SETTLE_DT", TEXT(ya!$C9,"YYYYMMDD")))} -> 0 | F9: {=IF(hp!F9=0,0,_xll.BDP(F$4,"YAS_BOND_YLD", "YAS_BOND_PX",hp!F9, "SETTLE_DT", TEXT(ya!$C9,"YYYYMMDD")))} -> 0 | G9: {=IF(hp!G9=0,0,_xll.BDP(G$4,"YAS_BOND_YLD", "YAS_BOND_PX",hp!G9, "SETTLE_DT", TEXT(ya!$C9,"YYYYMMDD")))} -> 0 | H9: {=IF(hp!H9=0,0,_xll.BDP(H$4,"YAS_BOND_YLD", "YAS_BOND_PX",hp!H9, "SETTLE_DT", TEXT(ya!$C9,"YYYYMMDD")))} -> 0 | I9: {=IF(hp!I9=0,0,_xll.BDP(I$4,"YAS_BOND_YLD", "YAS_BOND_PX",hp!I9, "SETTLE_DT", TEXT(ya!$C9,"YYYYMMDD")))} -> 0 | J9: {=IF(hp!J9=0,0,_xll.BDP(J$4,"YAS_BOND_YLD", "YAS_BOND_PX",hp!J9, "SETTLE_DT", TEXT(ya!$C9,"YYYYMMDD")))} -> 0 | K9: {=IF(hp!K9=0,0,_xll.BDP(K$4,"YAS_BOND_YLD", "YAS_BOND_PX",hp!K9, "SETTLE_DT", TEXT(ya!$C9,"YYYYMMDD")))} -> 0 | ... CC9: {=IF(hp!CC9=0,0,_xll.BDP(CC$4,"YAS_BOND_YLD", "YAS_BOND_PX",hp!CC9, "SETTLE_DT", TEXT(ya!$C9,"YYYYMMDD")))} -> 0
C10: 42216 | D10: {=IF(hp!D10=0,0,_xll.BDP(D$4,"YAS_BOND_YLD", "YAS_BOND_PX",hp!D10, "SETTLE_DT", TEXT(ya!$C10,"YYYYMMDD")))} -> 0 | E10: {=IF(hp!E10=0,0,_xll.BDP(E$4,"YAS_BOND_YLD", "YAS_BOND_PX",hp!E10, "SETTLE_DT", TEXT(ya!$C10,"YYYYMMDD")))} -> 0 | F10: {=IF(hp!F10=0,0,_xll.BDP(F$4,"YAS_BOND_YLD", "YAS_BOND_PX",hp!F10, "SETTLE_DT", TEXT(ya!$C10,"YYYYMMDD")))} -> 0 | G10: {=IF(hp!G10=0,0,_xll.BDP(G$4,"YAS_BOND_YLD", "YAS_BOND_PX",hp!G10, "SETTLE_DT", TEXT(ya!$C10,"YYYYMMDD")))} -> 0 | H10: {=IF(hp!H10=0,0,_xll.BDP(H$4,"YAS_BOND_YLD", "YAS_BOND_PX",hp!H10, "SETTLE_DT", TEXT(ya!$C10,"YYYYMMDD")))} -> 0 | I10: {=IF(hp!I10=0,0,_xll.BDP(I$4,"YAS_BOND_YLD", "YAS_BOND_PX",hp!I10, "SETTLE_DT", TEXT(ya!$C10,"YYYYMMDD")))} -> 0 | J10: {=IF(hp!J10=0,0,_xll.BDP(J$4,"YAS_BOND_YLD", "YAS_BOND_PX",hp!J10, "SETTLE_DT", TEXT(ya!$C10,"YYYYMMDD")))} -> 0 | K10: {=IF(hp!K10=0,0,_xll.BDP(K$4,"YAS_BOND_YLD", "YAS_BOND_PX",hp!K10, "SETTLE_DT", TEXT(ya!$C10,"YYYYMMDD")))} -> 0 | ... CC10: {=IF(hp!CC10=0,0,_xll.BDP(CC$4,"YAS_BOND_YLD", "YAS_BOND_PX",hp!CC10, "SETTLE_DT", TEXT(ya!$C10,"YYYYMMDD")))} -> 0
C11: 42247 | D11: {=IF(hp!D11=0,0,_xll.BDP(D$4,"YAS_BOND_YLD", "YAS_BOND_PX",hp!D11, "SETTLE_DT", TEXT(ya!$C11,"YYYYMMDD")))} -> 0 | E11: {=IF(hp!E11=0,0,_xll.BDP(E$4,"YAS_BOND_YLD", "YAS_BOND_PX",hp!E11, "SETTLE_DT", TEXT(ya!$C11,"YYYYMMDD")))} -> 0 | F11: {=IF(hp!F11=0,0,_xll.BDP(F$4,"YAS_BOND_YLD", "YAS_BOND_PX",hp!F11, "SETTLE_DT", TEXT(ya!$C11,"YYYYMMDD")))} -> 0 | G11: {=IF(hp!G11=0,0,_xll.BDP(G$4,"YAS_BOND_YLD", "YAS_BOND_PX",hp!G11, "SETTLE_DT", TEXT(ya!$C11,"YYYYMMDD")))} -> 0 | H11: {=IF(hp!H11=0,0,_xll.BDP(H$4,"YAS_BOND_YLD", "YAS_BOND_PX",hp!H11, "SETTLE_DT", TEXT(ya!$C11,"YYYYMMDD")))} -> 0 | I11: {=IF(hp!I11=0,0,_xll.BDP(I$4,"YAS_BOND_YLD", "YAS_BOND_PX",hp!I11, "SETTLE_DT", TEXT(ya!$C11,"YYYYMMDD")))} -> 0 | J11: {=IF(hp!J11=0,0,_xll.BDP(J$4,"YAS_BOND_YLD", "YAS_BOND_PX",hp!J11, "SETTLE_DT", TEXT(ya!$C11,"YYYYMMDD")))} -> 0 | K11: {=IF(hp!K11=0,0,_xll.BDP(K$4,"YAS_BOND_YLD", "YAS_BOND_PX",hp!K11, "SETTLE_DT", TEXT(ya!$C11,"YYYYMMDD")))} -> 0 | ... CC11: {=IF(hp!CC11=0,0,_xll.BDP(CC$4,"YAS_BOND_YLD", "YAS_BOND_PX",hp!CC11, "SETTLE_DT", TEXT(ya!$C11,"YYYYMMDD")))} -> 0
C12: 42277 | D12: {=IF(hp!D12=0,0,_xll.BDP(D$4,"YAS_BOND_YLD", "YAS_BOND_PX",hp!D12, "SETTLE_DT", TEXT(ya!$C12,"YYYYMMDD")))} -> 0 | E12: {=IF(hp!E12=0,0,_xll.BDP(E$4,"YAS_BOND_YLD", "YAS_BOND_PX",hp!E12, "SETTLE_DT", TEXT(ya!$C12,"YYYYMMDD")))} -> 0 | F12: {=IF(hp!F12=0,0,_xll.BDP(F$4,"YAS_BOND_YLD", "YAS_BOND_PX",hp!F12, "SETTLE_DT", TEXT(ya!$C12,"YYYYMMDD")))} -> 0 | G12: {=IF(hp!G12=0,0,_xll.BDP(G$4,"YAS_BOND_YLD", "YAS_BOND_PX",hp!G12, "SETTLE_DT", TEXT(ya!$C12,"YYYYMMDD")))} -> 0 | H12: {=IF(hp!H12=0,0,_xll.BDP(H$4,"YAS_BOND_YLD", "YAS_BOND_PX",hp!H12, "SETTLE_DT", TEXT(ya!$C12,"YYYYMMDD")))} -> 0 | I12: {=IF(hp!I12=0,0,_xll.BDP(I$4,"YAS_BOND_YLD", "YAS_BOND_PX",hp!I12, "SETTLE_DT", TEXT(ya!$C12,"YYYYMMDD")))} -> 0 | J12: {=IF(hp!J12=0,0,_xll.BDP(J$4,"YAS_BOND_YLD", "YAS_BOND_PX",hp!J12, "SETTLE_DT", TEXT(ya!$C12,"YYYYMMDD")))} -> 0 | K12: {=IF(hp!K12=0,0,_xll.BDP(K$4,"YAS_BOND_YLD", "YAS_BOND_PX",hp!K12, "SETTLE_DT", TEXT(ya!$C12,"YYYYMMDD")))} -> 0 | ... CC12: {=IF(hp!CC12=0,0,_xll.BDP(CC$4,"YAS_BOND_YLD", "YAS_BOND_PX",hp!CC12, "SETTLE_DT", TEXT(ya!$C12,"YYYYMMDD")))} -> 0
C13: 42307 | D13: {=IF(hp!D13=0,0,_xll.BDP(D$4,"YAS_BOND_YLD", "YAS_BOND_PX",hp!D13, "SETTLE_DT", TEXT(ya!$C13,"YYYYMMDD")))} -> 0 | E13: {=IF(hp!E13=0,0,_xll.BDP(E$4,"YAS_BOND_YLD", "YAS_BOND_PX",hp!E13, "SETTLE_DT", TEXT(ya!$C13,"YYYYMMDD")))} -> 0 | F13: {=IF(hp!F13=0,0,_xll.BDP(F$4,"YAS_BOND_YLD", "YAS_BOND_PX",hp!F13, "SETTLE_DT", TEXT(ya!$C13,"YYYYMMDD")))} -> 0 | G13: {=IF(hp!G13=0,0,_xll.BDP(G$4,"YAS_BOND_YLD", "YAS_BOND_PX",hp!G13, "SETTLE_DT", TEXT(ya!$C13,"YYYYMMDD")))} -> 0 | H13: {=IF(hp!H13=0,0,_xll.BDP(H$4,"YAS_BOND_YLD", "YAS_BOND_PX",hp!H13, "SETTLE_DT", TEXT(ya!$C13,"YYYYMMDD")))} -> 0 | I13: {=IF(hp!I13=0,0,_xll.BDP(I$4,"YAS_BOND_YLD", "YAS_BOND_PX",hp!I13, "SETTLE_DT", TEXT(ya!$C13,"YYYYMMDD")))} -> 0 | J13: {=IF(hp!J13=0,0,_xll.BDP(J$4,"YAS_BOND_YLD", "YAS_BOND_PX",hp!J13, "SETTLE_DT", TEXT(ya!$C13,"YYYYMMDD")))} -> 0 | K13: {=IF(hp!K13=0,0,_xll.BDP(K$4,"YAS_BOND_YLD", "YAS_BOND_PX",hp!K13, "SETTLE_DT", TEXT(ya!$C13,"YYYYMMDD")))} -> 0 | ... CC13: {=IF(hp!CC13=0,0,_xll.BDP(CC$4,"YAS_BOND_YLD", "YAS_BOND_PX",hp!CC13, "SETTLE_DT", TEXT(ya!$C13,"YYYYMMDD")))} -> 0
C14: 42338 | D14: {=IF(hp!D14=0,0,_xll.BDP(D$4,"YAS_BOND_YLD", "YAS_BOND_PX",hp!D14, "SETTLE_DT", TEXT(ya!$C14,"YYYYMMDD")))} -> 0 | E14: {=IF(hp!E14=0,0,_xll.BDP(E$4,"YAS_BOND_YLD", "YAS_BOND_PX",hp!E14, "SETTLE_DT", TEXT(ya!$C14,"YYYYMMDD")))} -> 0 | F14: {=IF(hp!F14=0,0,_xll.BDP(F$4,"YAS_BOND_YLD", "YAS_BOND_PX",hp!F14, "SETTLE_DT", TEXT(ya!$C14,"YYYYMMDD")))} -> 0 | G14: {=IF(hp!G14=0,0,_xll.BDP(G$4,"YAS_BOND_YLD", "YAS_BOND_PX",hp!G14, "SETTLE_DT", TEXT(ya!$C14,"YYYYMMDD")))} -> 0 | H14: {=IF(hp!H14=0,0,_xll.BDP(H$4,"YAS_BOND_YLD", "YAS_BOND_PX",hp!H14, "SETTLE_DT", TEXT(ya!$C14,"YYYYMMDD")))} -> 0 | I14: {=IF(hp!I14=0,0,_xll.BDP(I$4,"YAS_BOND_YLD", "YAS_BOND_PX",hp!I14, "SETTLE_DT", TEXT(ya!$C14,"YYYYMMDD")))} -> 0 | J14: {=IF(hp!J14=0,0,_xll.BDP(J$4,"YAS_BOND_YLD", "YAS_BOND_PX",hp!J14, "SETTLE_DT", TEXT(ya!$C14,"YYYYMMDD")))} -> 0 | K14: {=IF(hp!K14=0,0,_xll.BDP(K$4,"YAS_BOND_YLD", "YAS_BOND_PX",hp!K14, "SETTLE_DT", TEXT(ya!$C14,"YYYYMMDD")))} -> 0 | ... CC14: {=IF(hp!CC14=0,0,_xll.BDP(CC$4,"YAS_BOND_YLD", "YAS_BOND_PX",hp!CC14, "SETTLE_DT", TEXT(ya!$C14,"YYYYMMDD")))} -> 0
C15: 42369 | D15: {=IF(hp!D15=0,0,_xll.BDP(D$4,"YAS_BOND_YLD", "YAS_BOND_PX",hp!D15, "SETTLE_DT", TEXT(ya!$C15,"YYYYMMDD")))} -> 0 | E15: {=IF(hp!E15=0,0,_xll.BDP(E$4,"YAS_BOND_YLD", "YAS_BOND_PX",hp!E15, "SETTLE_DT", TEXT(ya!$C15,"YYYYMMDD")))} -> 0 | F15: {=IF(hp!F15=0,0,_xll.BDP(F$4,"YAS_BOND_YLD", "YAS_BOND_PX",hp!F15, "SETTLE_DT", TEXT(ya!$C15,"YYYYMMDD")))} -> 0 | G15: {=IF(hp!G15=0,0,_xll.BDP(G$4,"YAS_BOND_YLD", "YAS_BOND_PX",hp!G15, "SETTLE_DT", TEXT(ya!$C15,"YYYYMMDD")))} -> 0 | H15: {=IF(hp!H15=0,0,_xll.BDP(H$4,"YAS_BOND_YLD", "YAS_BOND_PX",hp!H15, "SETTLE_DT", TEXT(ya!$C15,"YYYYMMDD")))} -> 0 | I15: {=IF(hp!I15=0,0,_xll.BDP(I$4,"YAS_BOND_YLD", "YAS_BOND_PX",hp!I15, "SETTLE_DT", TEXT(ya!$C15,"YYYYMMDD")))} -> 0 | J15: {=IF(hp!J15=0,0,_xll.BDP(J$4,"YAS_BOND_YLD", "YAS_BOND_PX",hp!J15, "SETTLE_DT", TEXT(ya!$C15,"YYYYMMDD")))} -> 0 | K15: {=IF(hp!K15=0,0,_xll.BDP(K$4,"YAS_BOND_YLD", "YAS_BOND_PX",hp!K15, "SETTLE_DT", TEXT(ya!$C15,"YYYYMMDD")))} -> 0 | ... CC15: {=IF(hp!CC15=0,0,_xll.BDP(CC$4,"YAS_BOND_YLD", "YAS_BOND_PX",hp!CC15, "SETTLE_DT", TEXT(ya!$C15,"YYYYMMDD")))} -> 0
C16: 42398 | D16: {=IF(hp!D16=0,0,_xll.BDP(D$4,"YAS_BOND_YLD", "YAS_BOND_PX",hp!D16, "SETTLE_DT", TEXT(ya!$C16,"YYYYMMDD")))} -> 0 | E16: {=IF(hp!E16=0,0,_xll.BDP(E$4,"YAS_BOND_YLD", "YAS_BOND_PX",hp!E16, "SETTLE_DT", TEXT(ya!$C16,"YYYYMMDD")))} -> 0 | F16: {=IF(hp!F16=0,0,_xll.BDP(F$4,"YAS_BOND_YLD", "YAS_BOND_PX",hp!F16, "SETTLE_DT", TEXT(ya!$C16,"YYYYMMDD")))} -> 0 | G16: {=IF(hp!G16=0,0,_xll.BDP(G$4,"YAS_BOND_YLD", "YAS_BOND_PX",hp!G16, "SETTLE_DT", TEXT(ya!$C16,"YYYYMMDD")))} -> 0 | H16: {=IF(hp!H16=0,0,_xll.BDP(H$4,"YAS_BOND_YLD", "YAS_BOND_PX",hp!H16, "SETTLE_DT", TEXT(ya!$C16,"YYYYMMDD")))} -> 0 | I16: {=IF(hp!I16=0,0,_xll.BDP(I$4,"YAS_BOND_YLD", "YAS_BOND_PX",hp!I16, "SETTLE_DT", TEXT(ya!$C16,"YYYYMMDD")))} -> 0 | J16: {=IF(hp!J16=0,0,_xll.BDP(J$4,"YAS_BOND_YLD", "YAS_BOND_PX",hp!J16, "SETTLE_DT", TEXT(ya!$C16,"YYYYMMDD")))} -> 0 | K16: {=IF(hp!K16=0,0,_xll.BDP(K$4,"YAS_BOND_YLD", "YAS_BOND_PX",hp!K16, "SETTLE_DT", TEXT(ya!$C16,"YYYYMMDD")))} -> 0 | ... CC16: {=IF(hp!CC16=0,0,_xll.BDP(CC$4,"YAS_BOND_YLD", "YAS_BOND_PX",hp!CC16, "SETTLE_DT", TEXT(ya!$C16,"YYYYMMDD")))} -> 0
C17: 42429 | D17: {=IF(hp!D17=0,0,_xll.BDP(D$4,"YAS_BOND_YLD", "YAS_BOND_PX",hp!D17, "SETTLE_DT", TEXT(ya!$C17,"YYYYMMDD")))} -> 0 | E17: {=IF(hp!E17=0,0,_xll.BDP(E$4,"YAS_BOND_YLD", "YAS_BOND_PX",hp!E17, "SETTLE_DT", TEXT(ya!$C17,"YYYYMMDD")))} -> 0 | F17: {=IF(hp!F17=0,0,_xll.BDP(F$4,"YAS_BOND_YLD", "YAS_BOND_PX",hp!F17, "SETTLE_DT", TEXT(ya!$C17,"YYYYMMDD")))} -> 0 | G17: {=IF(hp!G17=0,0,_xll.BDP(G$4,"YAS_BOND_YLD", "YAS_BOND_PX",hp!G17, "SETTLE_DT", TEXT(ya!$C17,"YYYYMMDD")))} -> 0 | H17: {=IF(hp!H17=0,0,_xll.BDP(H$4,"YAS_BOND_YLD", "YAS_BOND_PX",hp!H17, "SETTLE_DT", TEXT(ya!$C17,"YYYYMMDD")))} -> 0 | I17: {=IF(hp!I17=0,0,_xll.BDP(I$4,"YAS_BOND_YLD", "YAS_BOND_PX",hp!I17, "SETTLE_DT", TEXT(ya!$C17,"YYYYMMDD")))} -> 0 | J17: {=IF(hp!J17=0,0,_xll.BDP(J$4,"YAS_BOND_YLD", "YAS_BOND_PX",hp!J17, "SETTLE_DT", TEXT(ya!$C17,"YYYYMMDD")))} -> 0 | K17: {=IF(hp!K17=0,0,_xll.BDP(K$4,"YAS_BOND_YLD", "YAS_BOND_PX",hp!K17, "SETTLE_DT", TEXT(ya!$C17,"YYYYMMDD")))} -> 0 | ... CC17: {=IF(hp!CC17=0,0,_xll.BDP(CC$4,"YAS_BOND_YLD", "YAS_BOND_PX",hp!CC17, "SETTLE_DT", TEXT(ya!$C17,"YYYYMMDD")))} -> 0
... C129: 45838 | D129: {=IF(hp!D129=0,0,_xll.BDP(D$4,"YAS_BOND_YLD", "YAS_BOND_PX",hp!D129, "SETTLE_DT", TEXT(ya!$C129,"YYYYMMDD")))} -> 12.111618 | E129: {=IF(hp!E129=0,0,_xll.BDP(E$4,"YAS_BOND_YLD", "YAS_BOND_PX",hp!E129, "SETTLE_DT", TEXT(ya!$C129,"YYYYMMDD")))} -> 11.096583 | F129: {=IF(hp!F129=0,0,_xll.BDP(F$4,"YAS_BOND_YLD", "YAS_BOND_PX",hp!F129, "SETTLE_DT", TEXT(ya!$C129,"YYYYMMDD")))} -> 11.677643 | G129: {=IF(hp!G129=0,0,_xll.BDP(G$4,"YAS_BOND_YLD", "YAS_BOND_PX",hp!G129, "SETTLE_DT", TEXT(ya!$C129,"YYYYMMDD")))} -> 11.828794 | H129: {=IF(hp!H129=0,0,_xll.BDP(H$4,"YAS_BOND_YLD", "YAS_BOND_PX",hp!H129, "SETTLE_DT", TEXT(ya!$C129,"YYYYMMDD")))} -> 11.76471 | I129: {=IF(hp!I129=0,0,_xll.BDP(I$4,"YAS_BOND_YLD", "YAS_BOND_PX",hp!I129, "SETTLE_DT", TEXT(ya!$C129,"YYYYMMDD")))} -> 13.106169 | J129: {=IF(hp!J129=0,0,_xll.BDP(J$4,"YAS_BOND_YLD", "YAS_BOND_PX",hp!J129, "SETTLE_DT", TEXT(ya!$C129,"YYYYMMDD")))} -> 11.675162 | K129: {=IF(hp!K129=0,0,_xll.BDP(K$4,"YAS_BOND_YLD", "YAS_BOND_PX",hp!K129, "SETTLE_DT", TEXT(ya!$C129,"YYYYMMDD")))} -> 12.293014 | ... CC129: {=IF(hp!CC129=0,0,_xll.BDP(CC$4,"YAS_BOND_YLD", "YAS_BOND_PX",hp!CC129, "SETTLE_DT", TEXT(ya!$C129,"YYYYMMDD")))} -> 6.819094

Sheet hp_values_only
B1: ZM903300 Corp | C1: ZM819269 Corp | D1: BJ485726 Corp | E1: YN482880 Corp | F1: BT802365 Corp | G1: BM044614 Corp | H1: BT735061 Corp | I1: BW499053 Corp | J1: BN496886 Corp | K1: BO165590 Corp | L1: YU913074 Corp | M1: YU416694 Corp | N1: BU614742 Corp | O1: ZL353780 Corp | P1: BT642376 Corp | Q1: YN748671 Corp | R1: YS542553 Corp | S1: YS509089 Corp | T1: ZL479769 Corp | U1: YR474692 Corp | V1: AX813975 Corp | W1: AN703481 Corp | X1: YU254355 Corp | Y1: ZH961035 Corp | Z1: BT396062 Corp | AA1: BN411719 Corp | AB1: BR588576 Corp | AC1: ZR500008 Corp | AD1: BN718496 Corp | AE1: BW577080 Corp | AF1: BO169050 Corp | AG1: YW833064 Corp | AH1: BK458282 Corp | AI1: BQ799145 Corp | AJ1: YN649376 Corp | AK1: YX291422 Corp | AL1: BN756935 Corp | AM1: BR425633 Corp | AN1: YR732902 Corp | AO1: ZM294074 Corp | AP1: ZM636659 Corp | AQ1: AP550972 Corp | AR1: BQ799727 Corp | AS1: AZ257187 Corp | AT1: BT481997 Corp | AU1: ZQ802560 Corp | AV1: AN629808 Corp | AW1: YQ448515 Corp | AX1: ZS021650 Corp | AY1: AP971344 Corp | AZ1: ZL354478 Corp | BA1: ZL641942 Corp | BB1: YX800450 Corp | BC1: BT482185 Corp | BD1: ZH598780 Corp | BE1: BW982245 Corp | BF1: BV443414 Corp | BG1: BV963634 Corp | BH1: BQ725281 Corp | BI1: BS187660 Corp | BJ1: BQ376842 Corp | BK1: ZJ582077 Corp | BL1: ZO295365 Corp | BM1: BQ706131 Corp | BN1: PP590IOV M-Mkt | BO1: BQ721820 Corp | BP1: BQ721824 Corp | BQ1: BQ721132 Corp | BR1: BQ722937 Corp | BS1: BP909148 Corp | BT1: BP780031 Corp | BU1: BN542084 Corp | BV1: BU793824 Corp | BW1: BW057488 Corp | BX1: BO510428 Corp | BY1: BQ747472 Corp | BZ1: AT637750 Corp | CA1: BP322887 Corp
A2: 42062 | B2: 0 | C2: 0 | D2: 0 | E2: 0 | F2: 0 | G2: 0 | H2: 0 | I2: 0 | J2: 0 | K2: 0 | L2: 0 | M2: 0 | N2: 0 | O2: 0 | P2: 0 | Q2: 0 | R2: 0 | S2: 0 | T2: 0 | U2: 0 | V2: 0 | W2: 0 | X2: 0 | Y2: 0 | Z2: 0 | AA2: 0 | AB2: 0 | AC2: 0 | AD2: 0 | AE2: 0 | AF2: 0 | AG2: 0 | AH2: 0 | AI2: 0 | AJ2: 0 | AK2: 0 | AL2: 0 | AM2: 0 | AN2: 0 | AO2: 0 | AP2: 0 | AQ2: 0 | AR2: 0 | AS2: 0 | AT2: 0 | AU2: 0 | AV2: 0 | AW2: 0 | AX2: 0 | AY2: 0 | AZ2: 0 | BA2: 0 | BB2: 0 | BC2: 0 | BD2: 0 | BE2: 0 | BF2: 0 | BG2: 0 | BH2: 0 | BI2: 0 | BJ2: 0 | BK2: 0 | BL2: 0 | BM2: 0 | BN2: 0 | BO2: 0 | BP2: 0 | BQ2: 0 | BR2: 0 | BS2: 0 | BT2: 0 | BU2: 0 | BV2: 0 | BW2: 0 | BX2: 0 | BY2: 0 | BZ2: 0 | CA2: 0
A3: 42094 | B3: 0 | C3: 0 | D3: 0 | E3: 0 | F3: 0 | G3: 0 | H3: 0 | I3: 0 | J3: 0 | K3: 0 | L3: 0 | M3: 0 | N3: 0 | O3: 0 | P3: 0 | Q3: 0 | R3: 0 | S3: 0 | T3: 0 | U3: 0 | V3: 0 | W3: 0 | X3: 0 | Y3: 0 | Z3: 0 | AA3: 0 | AB3: 0 | AC3: 0 | AD3: 0 | AE3: 0 | AF3: 0 | AG3: 0 | AH3: 0 | AI3: 0 | AJ3: 0 | AK3: 0 | AL3: 0 | AM3: 0 | AN3: 0 | AO3: 0 | AP3: 0 | AQ3: 0 | AR3: 0 | AS3: 0 | AT3: 0 | AU3: 0 | AV3: 0 | AW3: 0 | AX3: 0 | AY3: 0 | AZ3: 0 | BA3: 0 | BB3: 0 | BC3: 0 | BD3: 0 | BE3: 0 | BF3: 0 | BG3: 0 | BH3: 0 | BI3: 0 | BJ3: 0 | BK3: 0 | BL3: 0 | BM3: 0 | BN3: 0 | BO3: 0 | BP3: 0 | BQ3: 0 | BR3: 0 | BS3: 0 | BT3: 0 | BU3: 0 | BV3: 0 | BW3: 0 | BX3: 0 | BY3: 0 | BZ3: 0 | CA3: 0
A4: 42124 | B4: 0 | C4: 0 | D4: 0 | E4: 0 | F4: 0 | G4: 0 | H4: 0 | I4: 0 | J4: 0 | K4: 0 | L4: 0 | M4: 0 | N4: 0 | O4: 0 | P4: 0 | Q4: 0 | R4: 0 | S4: 0 | T4: 0 | U4: 0 | V4: 0 | W4: 0 | X4: 0 | Y4: 0 | Z4: 0 | AA4: 0 | AB4: 0 | AC4: 0 | AD4: 0 | AE4: 0 | AF4: 0 | AG4: 0 | AH4: 0 | AI4: 0 | AJ4: 0 | AK4: 0 | AL4: 0 | AM4: 0 | AN4: 0 | AO4: 0 | AP4: 0 | AQ4: 0 | AR4: 0 | AS4: 0 | AT4: 0 | AU4: 0 | AV4: 0 | AW4: 0 | AX4: 0 | AY4: 0 | AZ4: 0 | BA4: 0 | BB4: 0 | BC4: 0 | BD4: 0 | BE4: 0 | BF4: 0 | BG4: 0 | BH4: 0 | BI4: 0 | BJ4: 0 | BK4: 0 | BL4: 0 | BM4: 0 | BN4: 0 | BO4: 0 | BP4: 0 | BQ4: 0 | BR4: 0 | BS4: 0 | BT4: 0 | BU4: 0 | BV4: 0 | BW4: 0 | BX4: 0 | BY4: 0 | BZ4: 0 | CA4: 0
A5: 42153 | B5: 0 | C5: 0 | D5: 0 | E5: 0 | F5: 0 | G5: 0 | H5: 0 | I5: 0 | J5: 0 | K5: 0 | L5: 0 | M5: 0 | N5: 0 | O5: 0 | P5: 0 | Q5: 0 | R5: 0 | S5: 0 | T5: 0 | U5: 0 | V5: 0 | W5: 0 | X5: 0 | Y5: 0 | Z5: 0 | AA5: 0 | AB5: 0 | AC5: 0 | AD5: 0 | AE5: 0 | AF5: 0 | AG5: 0 | AH5: 0 | AI5: 0 | AJ5: 0 | AK5: 0 | AL5: 0 | AM5: 0 | AN5: 0 | AO5: 0 | AP5: 0 | AQ5: 0 | AR5: 0 | AS5: 0 | AT5: 0 | AU5: 0 | AV5: 0 | AW5: 0 | AX5: 0 | AY5: 0 | AZ5: 0 | BA5: 0 | BB5: 0 | BC5: 0 | BD5: 0 | BE5: 0 | BF5: 0 | BG5: 0 | BH5: 0 | BI5: 0 | BJ5: 0 | BK5: 0 | BL5: 0 | BM5: 0 | BN5: 0 | BO5: 0 | BP5: 0 | BQ5: 0 | BR5: 0 | BS5: 0 | BT5: 0 | BU5: 0 | BV5: 0 | BW5: 0 | BX5: 0 | BY5: 0 | BZ5: 0 | CA5: 0
A6: 42185 | B6: 0 | C6: 0 | D6: 0 | E6: 0 | F6: 0 | G6: 0 | H6: 0 | I6: 0 | J6: 0 | K6: 0 | L6: 0 | M6: 0 | N6: 0 | O6: 0 | P6: 0 | Q6: 0 | R6: 0 | S6: 0 | T6: 0 | U6: 0 | V6: 0 | W6: 0 | X6: 0 | Y6: 0 | Z6: 0 | AA6: 0 | AB6: 0 | AC6: 0 | AD6: 0 | AE6: 0 | AF6: 0 | AG6: 0 | AH6: 0 | AI6: 0 | AJ6: 0 | AK6: 0 | AL6: 0 | AM6: 0 | AN6: 0 | AO6: 0 | AP6: 0 | AQ6: 0 | AR6: 0 | AS6: 0 | AT6: 0 | AU6: 0 | AV6: 0 | AW6: 0 | AX6: 0 | AY6: 0 | AZ6: 0 | BA6: 0 | BB6: 0 | BC6: 0 | BD6: 0 | BE6: 0 | BF6: 0 | BG6: 0 | BH6: 0 | BI6: 0 | BJ6: 0 | BK6: 0 | BL6: 0 | BM6: 0 | BN6: 0 | BO6: 0 | BP6: 0 | BQ6: 0 | BR6: 0 | BS6: 0 | BT6: 0 | BU6: 0 | BV6: 0 | BW6: 0 | BX6: 0 | BY6: 0 | BZ6: 0 | CA6: 0
A7: 42216 | B7: 0 | C7: 0 | D7: 0 | E7: 0 | F7: 0 | G7: 0 | H7: 0 | I7: 0 | J7: 0 | K7: 0 | L7: 0 | M7: 0 | N7: 0 | O7: 0 | P7: 0 | Q7: 0 | R7: 0 | S7: 0 | T7: 0 | U7: 0 | V7: 0 | W7: 0 | X7: 0 | Y7: 0 | Z7: 0 | AA7: 0 | AB7: 0 | AC7: 0 | AD7: 0 | AE7: 0 | AF7: 0 | AG7: 0 | AH7: 0 | AI7: 0 | AJ7: 0 | AK7: 0 | AL7: 0 | AM7: 0 | AN7: 0 | AO7: 0 | AP7: 0 | AQ7: 0 | AR7: 0 | AS7: 0 | AT7: 0 | AU7: 0 | AV7: 0 | AW7: 0 | AX7: 0 | AY7: 0 | AZ7: 0 | BA7: 0 | BB7: 0 | BC7: 0 | BD7: 0 | BE7: 0 | BF7: 0 | BG7: 0 | BH7: 0 | BI7: 0 | BJ7: 0 | BK7: 0 | BL7: 0 | BM7: 0 | BN7: 0 | BO7: 0 | BP7: 0 | BQ7: 0 | BR7: 0 | BS7: 0 | BT7: 0 | BU7: 0 | BV7: 0 | BW7: 0 | BX7: 0 | BY7: 0 | BZ7: 0 | CA7: 0
A8: 42247 | B8: 0 | C8: 0 | D8: 0 | E8: 0 | F8: 0 | G8: 0 | H8: 0 | I8: 0 | J8: 0 | K8: 0 | L8: 0 | M8: 0 | N8: 0 | O8: 0 | P8: 0 | Q8: 0 | R8: 0 | S8: 0 | T8: 0 | U8: 0 | V8: 0 | W8: 0 | X8: 0 | Y8: 0 | Z8: 0 | AA8: 0 | AB8: 0 | AC8: 0 | AD8: 0 | AE8: 0 | AF8: 0 | AG8: 0 | AH8: 0 | AI8: 0 | AJ8: 0 | AK8: 0 | AL8: 0 | AM8: 0 | AN8: 0 | AO8: 0 | AP8: 0 | AQ8: 0 | AR8: 0 | AS8: 0 | AT8: 0 | AU8: 0 | AV8: 0 | AW8: 0 | AX8: 0 | AY8: 0 | AZ8: 0 | BA8: 0 | BB8: 0 | BC8: 0 | BD8: 0 | BE8: 0 | BF8: 0 | BG8: 0 | BH8: 0 | BI8: 0 | BJ8: 0 | BK8: 0 | BL8: 0 | BM8: 0 | BN8: 0 | BO8: 0 | BP8: 0 | BQ8: 0 | BR8: 0 | BS8: 0 | BT8: 0 | BU8: 0 | BV8: 0 | BW8: 0 | BX8: 0 | BY8: 0 | BZ8: 0 | CA8: 0
A9: 42277 | B9: 0 | C9: 0 | D9: 0 | E9: 0 | F9: 0 | G9: 0 | H9: 0 | I9: 0 | J9: 0 | K9: 0 | L9: 0 | M9: 0 | N9: 0 | O9: 0 | P9: 0 | Q9: 0 | R9: 0 | S9: 0 | T9: 0 | U9: 0 | V9: 0 | W9: 0 | X9: 0 | Y9: 0 | Z9: 0 | AA9: 0 | AB9: 0 | AC9: 0 | AD9: 0 | AE9: 0 | AF9: 0 | AG9: 0 | AH9: 0 | AI9: 0 | AJ9: 0 | AK9: 0 | AL9: 0 | AM9: 0 | AN9: 0 | AO9: 0 | AP9: 0 | AQ9: 0 | AR9: 0 | AS9: 0 | AT9: 0 | AU9: 0 | AV9: 0 | AW9: 0 | AX9: 0 | AY9: 0 | AZ9: 0 | BA9: 0 | BB9: 0 | BC9: 0 | BD9: 0 | BE9: 0 | BF9: 0 | BG9: 0 | BH9: 0 | BI9: 0 | BJ9: 0 | BK9: 0 | BL9: 0 | BM9: 0 | BN9: 0 | BO9: 0 | BP9: 0 | BQ9: 0 | BR9: 0 | BS9: 0 | BT9: 0 | BU9: 0 | BV9: 0 | BW9: 0 | BX9: 0 | BY9: 0 | BZ9: 0 | CA9: 0
A10: 42307 | B10: 0 | C10: 0 | D10: 0 | E10: 0 | F10: 0 | G10: 0 | H10: 0 | I10: 0 | J10: 0 | K10: 0 | L10: 0 | M10: 0 | N10: 0 | O10: 0 | P10: 0 | Q10: 0 | R10: 0 | S10: 0 | T10: 0 | U10: 0 | V10: 0 | W10: 0 | X10: 0 | Y10: 0 | Z10: 0 | AA10: 0 | AB10: 0 | AC10: 0 | AD10: 0 | AE10: 0 | AF10: 0 | AG10: 0 | AH10: 0 | AI10: 0 | AJ10: 0 | AK10: 0 | AL10: 0 | AM10: 0 | AN10: 0 | AO10: 0 | AP10: 0 | AQ10: 0 | AR10: 0 | AS10: 0 | AT10: 0 | AU10: 0 | AV10: 0 | AW10: 0 | AX10: 0 | AY10: 0 | AZ10: 0 | BA10: 0 | BB10: 0 | BC10: 0 | BD10: 0 | BE10: 0 | BF10: 0 | BG10: 0 | BH10: 0 | BI10: 0 | BJ10: 0 | BK10: 0 | BL10: 0 | BM10: 0 | BN10: 0 | BO10: 0 | BP10: 0 | BQ10: 0 | BR10: 0 | BS10: 0 | BT10: 0 | BU10: 0 | BV10: 0 | BW10: 0 | BX10: 0 | BY10: 0 | BZ10: 0 | CA10: 0
A11: 42338 | B11: 0 | C11: 0 | D11: 0 | E11: 0 | F11: 0 | G11: 0 | H11: 0 | I11: 0 | J11: 0 | K11: 0 | L11: 0 | M11: 0 | N11: 0 | O11: 0 | P11: 0 | Q11: 0 | R11: 0 | S11: 0 | T11: 0 | U11: 0 | V11: 0 | W11: 0 | X11: 0 | Y11: 0 | Z11: 0 | AA11: 0 | AB11: 0 | AC11: 0 | AD11: 0 | AE11: 0 | AF11: 0 | AG11: 0 | AH11: 0 | AI11: 0 | AJ11: 0 | AK11: 0 | AL11: 0 | AM11: 0 | AN11: 0 | AO11: 0 | AP11: 0 | AQ11: 0 | AR11: 0 | AS11: 0 | AT11: 0 | AU11: 0 | AV11: 0 | AW11: 0 | AX11: 0 | AY11: 0 | AZ11: 0 | BA11: 0 | BB11: 0 | BC11: 0 | BD11: 0 | BE11: 0 | BF11: 0 | BG11: 0 | BH11: 0 | BI11: 0 | BJ11: 0 | BK11: 0 | BL11: 0 | BM11: 0 | BN11: 0 | BO11: 0 | BP11: 0 | BQ11: 0 | BR11: 0 | BS11: 0 | BT11: 0 | BU11: 0 | BV11: 0 | BW11: 0 | BX11: 0 | BY11: 0 | BZ11: 0 | CA11: 0
A12: 42369 | B12: 0 | C12: 0 | D12: 0 | E12: 0 | F12: 0 | G12: 0 | H12: 0 | I12: 0 | J12: 0 | K12: 0 | L12: 0 | M12: 0 | N12: 0 | O12: 0 | P12: 0 | Q12: 0 | R12: 0 | S12: 0 | T12: 0 | U12: 0 | V12: 0 | W12: 0 | X12: 0 | Y12: 0 | Z12: 0 | AA12: 0 | AB12: 0 | AC12: 0 | AD12: 0 | AE12: 0 | AF12: 0 | AG12: 0 | AH12: 0 | AI12: 0 | AJ12: 0 | AK12: 0 | AL12: 0 | AM12: 0 | AN12: 0 | AO12: 0 | AP12: 0 | AQ12: 0 | AR12: 0 | AS12: 0 | AT12: 0 | AU12: 0 | AV12: 0 | AW12: 0 | AX12: 0 | AY12: 0 | AZ12: 0 | BA12: 0 | BB12: 0 | BC12: 0 | BD12: 0 | BE12: 0 | BF12: 0 | BG12: 0 | BH12: 0 | BI12: 0 | BJ12: 0 | BK12: 0 | BL12: 0 | BM12: 0 | BN12: 0 | BO12: 0 | BP12: 0 | BQ12: 0 | BR12: 0 | BS12: 0 | BT12: 0 | BU12: 0 | BV12: 0 | BW12: 0 | BX12: 0 | BY12: 0 | BZ12: 0 | CA12: 0
A13: 42398 | B13: 0 | C13: 0 | D13: 0 | E13: 0 | F13: 0 | G13: 0 | H13: 0 | I13: 0 | J13: 0 | K13: 0 | L13: 0 | M13: 0 | N13: 0 | O13: 0 | P13: 0 | Q13: 0 | R13: 0 | S13: 0 | T13: 0 | U13: 0 | V13: 0 | W13: 0 | X13: 0 | Y13: 0 | Z13: 0 | AA13: 0 | AB13: 0 | AC13: 0 | AD13: 0 | AE13: 0 | AF13: 0 | AG13: 0 | AH13: 0 | AI13: 0 | AJ13: 0 | AK13: 0 | AL13: 0 | AM13: 0 | AN13: 0 | AO13: 0 | AP13: 0 | AQ13: 0 | AR13: 0 | AS13: 0 | AT13: 0 | AU13: 0 | AV13: 0 | AW13: 0 | AX13: 0 | AY13: 0 | AZ13: 0 | BA13: 0 | BB13: 0 | BC13: 0 | BD13: 0 | BE13: 0 | BF13: 0 | BG13: 0 | BH13: 0 | BI13: 0 | BJ13: 0 | BK13: 0 | BL13: 0 | BM13: 0 | BN13: 0 | BO13: 0 | BP13: 0 | BQ13: 0 | BR13: 0 | BS13: 0 | BT13: 0 | BU13: 0 | BV13: 0 | BW13: 0 | BX13: 0 | BY13: 0 | BZ13: 0 | CA13: 0
... A126: 45838 | B126: 96.938 | C126: 26.541 | D126: 58.285 | E126: 95.183 | F126: 93.504 | G126: 97.213 | H126: 48.278 | I126: 71.561 | J126: 95.468 | K126: 18.348 | L126: 95.185 | M126: 93.37 | N126: 16.785 | O126: 0 | P126: 95.337 | Q126: 97.255 | R126: 102.168 | S126: 98.325 | T126: 24.574 | U126: 34.74 | V126: 95.183 | W126: 79.931 | X126: 95.94 | Y126: 24.782 | Z126: 95.475 | AA126: 86.735 | AB126: 94.309 | AC126: 87.269 | AD126: 87.348 | AE126: 27.238 | AF126: 79.009 | AG126: 87.057 | AH126: 99.647 | AI126: 82.805 | AJ126: 94.037 | AK126: 36.254 | AL126: 95.541 | AM126: 88.178 | AN126: 101.801 | AO126: 98.515 | AP126: 95.751 | AQ126: 55.514 | AR126: 81.987 | AS126: 87.337 | AT126: 97.566 | AU126: 74.157 | AV126: 55.783 | AW126: 37.808 | AX126: 75.841 | AY126: 75.834 | AZ126: 73.52 | BA126: 97.601 | BB126: 98.102 | BC126: 66.435 | BD126: 82.271 | BE126: 97.056 | BF126: 0 | BG126: 94.678 | BH126: 0 | BI126: 98.074 | BJ126: 82.369 | BK126: 88.343 | BL126: 97.138 | BM126: 0 | BN126: 0 | BO126: 0 | BP126: 0 | BQ126: 0 | BR126: 0 | BS126: 0 | BT126: 0 | BU126: 0 | BV126: 0 | BW126: 0 | BX126: 90.367 | BY126: 69.086 | BZ126: 0 | CA126: 81.163

Sheet ya_values_only
A1: id | B1: ZM903300 Corp | C1: ZM819269 Corp | D1: BJ485726 Corp | E1: YN482880 Corp | F1: BT802365 Corp | G1: BM044614 Corp | H1: BT735061 Corp | I1: BW499053 Corp | J1: BN496886 Corp | K1: BO165590 Corp | L1: YU913074 Corp | M1: YU416694 Corp | N1: BU614742 Corp | O1: ZL353780 Corp | P1: BT642376 Corp | Q1: YS542553 Corp | R1: YN748671 Corp | S1: YS509089 Corp | T1: ZL479769 Corp | U1: YR474692 Corp | V1: AX813975 Corp | W1: AN703481 Corp | X1: YU254355 Corp | Y1: ZH961035 Corp | Z1: BT396062 Corp | AA1: BN411719 Corp | AB1: BR588576 Corp | AC1: ZR500008 Corp | AD1: BN718496 Corp | AE1: BW577080 Corp | AF1: BO169050 Corp | AG1: YW833064 Corp | AH1: BK458282 Corp | AI1: YN649376 Corp | AJ1: BQ799145 Corp | AK1: YX291422 Corp | AL1: BN756935 Corp | AM1: BR425633 Corp | AN1: YR732902 Corp | AO1: ZM294074 Corp | AP1: ZM636659 Corp | AQ1: AP550972 Corp | AR1: BQ799727 Corp | AS1: AZ257187 Corp | AT1: BT481997 Corp | AU1: ZQ802560 Corp | AV1: AN629808 Corp | AW1: ZS021650 Corp | AX1: YQ448515 Corp | AY1: AP971344 Corp | AZ1: ZL354478 Corp | BA1: YX800450 Corp | BB1: ZL641942 Corp | BC1: BT482185 Corp | BD1: ZH598780 Corp | BE1: BW982245 Corp | BF1: BV443414 Corp | BG1: BV963634 Corp | BH1: BQ725281 Corp | BI1: ZO295365 Corp | BJ1: BQ376842 Corp | BK1: BS187660 Corp | BL1: ZJ582077 Corp | BM1: PP590IOV M-Mkt | BN1: BQ721132 Corp | BO1: BQ721820 Corp | BP1: BQ721824 Corp | BQ1: BQ722937 Corp | BR1: BP909148 Corp | BS1: BN542084 Corp | BT1: BP780031 Corp | BU1: BU793824 Corp | BV1: BW057488 Corp | BW1: BQ706131 Corp | BX1: BP322887 Corp | BY1: AT637750 Corp | BZ1: BO510428 Corp | CA1: BQ747472 Corp
A2: 42062 | B2: 0 | C2: 0 | D2: 0 | E2: 0 | F2: 0 | G2: 0 | H2: 0 | I2: 0 | J2: 0 | K2: 0 | L2: 0 | M2: 0 | N2: 0 | O2: 0 | P2: 0 | Q2: 0 | R2: 0 | S2: 0 | T2: 0 | U2: 0 | V2: 0 | W2: 0 | X2: 0 | Y2: 0 | Z2: 0 | AA2: 0 | AB2: 0 | AC2: 0 | AD2: 0 | AE2: 0 | AF2: 0 | AG2: 0 | AH2: 0 | AI2: 0 | AJ2: 0 | AK2: 0 | AL2: 0 | AM2: 0 | AN2: 0 | AO2: 0 | AP2: 0 | AQ2: 0 | AR2: 0 | AS2: 0 | AT2: 0 | AU2: 0 | AV2: 0 | AW2: 0 | AX2: 0 | AY2: 0 | AZ2: 0 | BA2: 0 | BB2: 0 | BC2: 0 | BD2: 0 | BE2: 0 | BF2: 0 | BG2: 0 | BH2: 0 | BI2: 0 | BJ2: 0 | BK2: 0 | BL2: 0 | BM2: 0 | BN2: 0 | BO2: 0 | BP2: 0 | BQ2: 0 | BR2: 0 | BS2: 0 | BT2: 0 | BU2: 0 | BV2: 0 | BW2: 0 | BX2: 0 | BY2: 0 | BZ2: 0 | CA2: 0
A3: 42094 | B3: 0 | C3: 0 | D3: 0 | E3: 0 | F3: 0 | G3: 0 | H3: 0 | I3: 0 | J3: 0 | K3: 0 | L3: 0 | M3: 0 | N3: 0 | O3: 0 | P3: 0 | Q3: 0 | R3: 0 | S3: 0 | T3: 0 | U3: 0 | V3: 0 | W3: 0 | X3: 0 | Y3: 0 | Z3: 0 | AA3: 0 | AB3: 0 | AC3: 0 | AD3: 0 | AE3: 0 | AF3: 0 | AG3: 0 | AH3: 0 | AI3: 0 | AJ3: 0 | AK3: 0 | AL3: 0 | AM3: 0 | AN3: 0 | AO3: 0 | AP3: 0 | AQ3: 0 | AR3: 0 | AS3: 0 | AT3: 0 | AU3: 0 | AV3: 0 | AW3: 0 | AX3: 0 | AY3: 0 | AZ3: 0 | BA3: 0 | BB3: 0 | BC3: 0 | BD3: 0 | BE3: 0 | BF3: 0 | BG3: 0 | BH3: 0 | BI3: 0 | BJ3: 0 | BK3: 0 | BL3: 0 | BM3: 0 | BN3: 0 | BO3: 0 | BP3: 0 | BQ3: 0 | BR3: 0 | BS3: 0 | BT3: 0 | BU3: 0 | BV3: 0 | BW3: 0 | BX3: 0 | BY3: 0 | BZ3: 0 | CA3: 0
A4: 42124 | B4: 0 | C4: 0 | D4: 0 | E4: 0 | F4: 0 | G4: 0 | H4: 0 | I4: 0 | J4: 0 | K4: 0 | L4: 0 | M4: 0 | N4: 0 | O4: 0 | P4: 0 | Q4: 0 | R4: 0 | S4: 0 | T4: 0 | U4: 0 | V4: 0 | W4: 0 | X4: 0 | Y4: 0 | Z4: 0 | AA4: 0 | AB4: 0 | AC4: 0 | AD4: 0 | AE4: 0 | AF4: 0 | AG4: 0 | AH4: 0 | AI4: 0 | AJ4: 0 | AK4: 0 | AL4: 0 | AM4: 0 | AN4: 0 | AO4: 0 | AP4: 0 | AQ4: 0 | AR4: 0 | AS4: 0 | AT4: 0 | AU4: 0 | AV4: 0 | AW4: 0 | AX4: 0 | AY4: 0 | AZ4: 0 | BA4: 0 | BB4: 0 | BC4: 0 | BD4: 0 | BE4: 0 | BF4: 0 | BG4: 0 | BH4: 0 | BI4: 0 | BJ4: 0 | BK4: 0 | BL4: 0 | BM4: 0 | BN4: 0 | BO4: 0 | BP4: 0 | BQ4: 0 | BR4: 0 | BS4: 0 | BT4: 0 | BU4: 0 | BV4: 0 | BW4: 0 | BX4: 0 | BY4: 0 | BZ4: 0 | CA4: 0
A5: 42153 | B5: 0 | C5: 0 | D5: 0 | E5: 0 | F5: 0 | G5: 0 | H5: 0 | I5: 0 | J5: 0 | K5: 0 | L5: 0 | M5: 0 | N5: 0 | O5: 0 | P5: 0 | Q5: 0 | R5: 0 | S5: 0 | T5: 0 | U5: 0 | V5: 0 | W5: 0 | X5: 0 | Y5: 0 | Z5: 0 | AA5: 0 | AB5: 0 | AC5: 0 | AD5: 0 | AE5: 0 | AF5: 0 | AG5: 0 | AH5: 0 | AI5: 0 | AJ5: 0 | AK5: 0 | AL5: 0 | AM5: 0 | AN5: 0 | AO5: 0 | AP5: 0 | AQ5: 0 | AR5: 0 | AS5: 0 | AT5: 0 | AU5: 0 | AV5: 0 | AW5: 0 | AX5: 0 | AY5: 0 | AZ5: 0 | BA5: 0 | BB5: 0 | BC5: 0 | BD5: 0 | BE5: 0 | BF5: 0 | BG5: 0 | BH5: 0 | BI5: 0 | BJ5: 0 | BK5: 0 | BL5: 0 | BM5: 0 | BN5: 0 | BO5: 0 | BP5: 0 | BQ5: 0 | BR5: 0 | BS5: 0 | BT5: 0 | BU5: 0 | BV5: 0 | BW5: 0 | BX5: 0 | BY5: 0 | BZ5: 0 | CA5: 0
A6: 42185 | B6: 0 | C6: 0 | D6: 0 | E6: 0 | F6: 0 | G6: 0 | H6: 0 | I6: 0 | J6: 0 | K6: 0 | L6: 0 | M6: 0 | N6: 0 | O6: 0 | P6: 0 | Q6: 0 | R6: 0 | S6: 0 | T6: 0 | U6: 0 | V6: 0 | W6: 0 | X6: 0 | Y6: 0 | Z6: 0 | AA6: 0 | AB6: 0 | AC6: 0 | AD6: 0 | AE6: 0 | AF6: 0 | AG6: 0 | AH6: 0 | AI6: 0 | AJ6: 0 | AK6: 0 | AL6: 0 | AM6: 0 | AN6: 0 | AO6: 0 | AP6: 0 | AQ6: 0 | AR6: 0 | AS6: 0 | AT6: 0 | AU6: 0 | AV6: 0 | AW6: 0 | AX6: 0 | AY6: 0 | AZ6: 0 | BA6: 0 | BB6: 0 | BC6: 0 | BD6: 0 | BE6: 0 | BF6: 0 | BG6: 0 | BH6: 0 | BI6: 0 | BJ6: 0 | BK6: 0 | BL6: 0 | BM6: 0 | BN6: 0 | BO6: 0 | BP6: 0 | BQ6: 0 | BR6: 0 | BS6: 0 | BT6: 0 | BU6: 0 | BV6: 0 | BW6: 0 | BX6: 0 | BY6: 0 | BZ6: 0 | CA6: 0
A7: 42216 | B7: 0 | C7: 0 | D7: 0 | E7: 0 | F7: 0 | G7: 0 | H7: 0 | I7: 0 | J7: 0 | K7: 0 | L7: 0 | M7: 0 | N7: 0 | O7: 0 | P7: 0 | Q7: 0 | R7: 0 | S7: 0 | T7: 0 | U7: 0 | V7: 0 | W7: 0 | X7: 0 | Y7: 0 | Z7: 0 | AA7: 0 | AB7: 0 | AC7: 0 | AD7: 0 | AE7: 0 | AF7: 0 | AG7: 0 | AH7: 0 | AI7: 0 | AJ7: 0 | AK7: 0 | AL7: 0 | AM7: 0 | AN7: 0 | AO7: 0 | AP7: 0 | AQ7: 0 | AR7: 0 | AS7: 0 | AT7: 0 | AU7: 0 | AV7: 0 | AW7: 0 | AX7: 0 | AY7: 0 | AZ7: 0 | BA7: 0 | BB7: 0 | BC7: 0 | BD7: 0 | BE7: 0 | BF7: 0 | BG7: 0 | BH7: 0 | BI7: 0 | BJ7: 0 | BK7: 0 | BL7: 0 | BM7: 0 | BN7: 0 | BO7: 0 | BP7: 0 | BQ7: 0 | BR7: 0 | BS7: 0 | BT7: 0 | BU7: 0 | BV7: 0 | BW7: 0 | BX7: 0 | BY7: 0 | BZ7: 0 | CA7: 0
A8: 42247 | B8: 0 | C8: 0 | D8: 0 | E8: 0 | F8: 0 | G8: 0 | H8: 0 | I8: 0 | J8: 0 | K8: 0 | L8: 0 | M8: 0 | N8: 0 | O8: 0 | P8: 0 | Q8: 0 | R8: 0 | S8: 0 | T8: 0 | U8: 0 | V8: 0 | W8: 0 | X8: 0 | Y8: 0 | Z8: 0 | AA8: 0 | AB8: 0 | AC8: 0 | AD8: 0 | AE8: 0 | AF8: 0 | AG8: 0 | AH8: 0 | AI8: 0 | AJ8: 0 | AK8: 0 | AL8: 0 | AM8: 0 | AN8: 0 | AO8: 0 | AP8: 0 | AQ8: 0 | AR8: 0 | AS8: 0 | AT8: 0 | AU8: 0 | AV8: 0 | AW8: 0 | AX8: 0 | AY8: 0 | AZ8: 0 | BA8: 0 | BB8: 0 | BC8: 0 | BD8: 0 | BE8: 0 | BF8: 0 | BG8: 0 | BH8: 0 | BI8: 0 | BJ8: 0 | BK8: 0 | BL8: 0 | BM8: 0 | BN8: 0 | BO8: 0 | BP8: 0 | BQ8: 0 | BR8: 0 | BS8: 0 | BT8: 0 | BU8: 0 | BV8: 0 | BW8: 0 | BX8: 0 | BY8: 0 | BZ8: 0 | CA8: 0
A9: 42277 | B9: 0 | C9: 0 | D9: 0 | E9: 0 | F9: 0 | G9: 0 | H9: 0 | I9: 0 | J9: 0 | K9: 0 | L9: 0 | M9: 0 | N9: 0 | O9: 0 | P9: 0 | Q9: 0 | R9: 0 | S9: 0 | T9: 0 | U9: 0 | V9: 0 | W9: 0 | X9: 0 | Y9: 0 | Z9: 0 | AA9: 0 | AB9: 0 | AC9: 0 | AD9: 0 | AE9: 0 | AF9: 0 | AG9: 0 | AH9: 0 | AI9: 0 | AJ9: 0 | AK9: 0 | AL9: 0 | AM9: 0 | AN9: 0 | AO9: 0 | AP9: 0 | AQ9: 0 | AR9: 0 | AS9: 0 | AT9: 0 | AU9: 0 | AV9: 0 | AW9: 0 | AX9: 0 | AY9: 0 | AZ9: 0 | BA9: 0 | BB9: 0 | BC9: 0 | BD9: 0 | BE9: 0 | BF9: 0 | BG9: 0 | BH9: 0 | BI9: 0 | BJ9: 0 | BK9: 0 | BL9: 0 | BM9: 0 | BN9: 0 | BO9: 0 | BP9: 0 | BQ9: 0 | BR9: 0 | BS9: 0 | BT9: 0 | BU9: 0 | BV9: 0 | BW9: 0 | BX9: 0 | BY9: 0 | BZ9: 0 | CA9: 0
A10: 42307 | B10: 0 | C10: 0 | D10: 0 | E10: 0 | F10: 0 | G10: 0 | H10: 0 | I10: 0 | J10: 0 | K10: 0 | L10: 0 | M10: 0 | N10: 0 | O10: 0 | P10: 0 | Q10: 0 | R10: 0 | S10: 0 | T10: 0 | U10: 0 | V10: 0 | W10: 0 | X10: 0 | Y10: 0 | Z10: 0 | AA10: 0 | AB10: 0 | AC10: 0 | AD10: 0 | AE10: 0 | AF10: 0 | AG10: 0 | AH10: 0 | AI10: 0 | AJ10: 0 | AK10: 0 | AL10: 0 | AM10: 0 | AN10: 0 | AO10: 0 | AP10: 0 | AQ10: 0 | AR10: 0 | AS10: 0 | AT10: 0 | AU10: 0 | AV10: 0 | AW10: 0 | AX10: 0 | AY10: 0 | AZ10: 0 | BA10: 0 | BB10: 0 | BC10: 0 | BD10: 0 | BE10: 0 | BF10: 0 | BG10: 0 | BH10: 0 | BI10: 0 | BJ10: 0 | BK10: 0 | BL10: 0 | BM10: 0 | BN10: 0 | BO10: 0 | BP10: 0 | BQ10: 0 | BR10: 0 | BS10: 0 | BT10: 0 | BU10: 0 | BV10: 0 | BW10: 0 | BX10: 0 | BY10: 0 | BZ10: 0 | CA10: 0
A11: 42338 | B11: 0 | C11: 0 | D11: 0 | E11: 0 | F11: 0 | G11: 0 | H11: 0 | I11: 0 | J11: 0 | K11: 0 | L11: 0 | M11: 0 | N11: 0 | O11: 0 | P11: 0 | Q11: 0 | R11: 0 | S11: 0 | T11: 0 | U11: 0 | V11: 0 | W11: 0 | X11: 0 | Y11: 0 | Z11: 0 | AA11: 0 | AB11: 0 | AC11: 0 | AD11: 0 | AE11: 0 | AF11: 0 | AG11: 0 | AH11: 0 | AI11: 0 | AJ11: 0 | AK11: 0 | AL11: 0 | AM11: 0 | AN11: 0 | AO11: 0 | AP11: 0 | AQ11: 0 | AR11: 0 | AS11: 0 | AT11: 0 | AU11: 0 | AV11: 0 | AW11: 0 | AX11: 0 | AY11: 0 | AZ11: 0 | BA11: 0 | BB11: 0 | BC11: 0 | BD11: 0 | BE11: 0 | BF11: 0 | BG11: 0 | BH11: 0 | BI11: 0 | BJ11: 0 | BK11: 0 | BL11: 0 | BM11: 0 | BN11: 0 | BO11: 0 | BP11: 0 | BQ11: 0 | BR11: 0 | BS11: 0 | BT11: 0 | BU11: 0 | BV11: 0 | BW11: 0 | BX11: 0 | BY11: 0 | BZ11: 0 | CA11: 0
A12: 42369 | B12: 0 | C12: 0 | D12: 0 | E12: 0 | F12: 0 | G12: 0 | H12: 0 | I12: 0 | J12: 0 | K12: 0 | L12: 0 | M12: 0 | N12: 0 | O12: 0 | P12: 0 | Q12: 0 | R12: 0 | S12: 0 | T12: 0 | U12: 0 | V12: 0 | W12: 0 | X12: 0 | Y12: 0 | Z12: 0 | AA12: 0 | AB12: 0 | AC12: 0 | AD12: 0 | AE12: 0 | AF12: 0 | AG12: 0 | AH12: 0 | AI12: 0 | AJ12: 0 | AK12: 0 | AL12: 0 | AM12: 0 | AN12: 0 | AO12: 0 | AP12: 0 | AQ12: 0 | AR12: 0 | AS12: 0 | AT12: 0 | AU12: 0 | AV12: 0 | AW12: 0 | AX12: 0 | AY12: 0 | AZ12: 0 | BA12: 0 | BB12: 0 | BC12: 0 | BD12: 0 | BE12: 0 | BF12: 0 | BG12: 0 | BH12: 0 | BI12: 0 | BJ12: 0 | BK12: 0 | BL12: 0 | BM12: 0 | BN12: 0 | BO12: 0 | BP12: 0 | BQ12: 0 | BR12: 0 | BS12: 0 | BT12: 0 | BU12: 0 | BV12: 0 | BW12: 0 | BX12: 0 | BY12: 0 | BZ12: 0 | CA12: 0
A13: 42398 | B13: 0 | C13: 0 | D13: 0 | E13: 0 | F13: 0 | G13: 0 | H13: 0 | I13: 0 | J13: 0 | K13: 0 | L13: 0 | M13: 0 | N13: 0 | O13: 0 | P13: 0 | Q13: 0 | R13: 0 | S13: 0 | T13: 0 | U13: 0 | V13: 0 | W13: 0 | X13: 0 | Y13: 0 | Z13: 0 | AA13: 0 | AB13: 0 | AC13: 0 | AD13: 0 | AE13: 0 | AF13: 0 | AG13: 0 | AH13: 0 | AI13: 0 | AJ13: 0 | AK13: 0 | AL13: 0 | AM13: 0 | AN13: 0 | AO13: 0 | AP13: 0 | AQ13: 0 | AR13: 0 | AS13: 0 | AT13: 0 | AU13: 0 | AV13: 0 | AW13: 0 | AX13: 0 | AY13: 0 | AZ13: 0 | BA13: 0 | BB13: 0 | BC13: 0 | BD13: 0 | BE13: 0 | BF13: 0 | BG13: 0 | BH13: 0 | BI13: 0 | BJ13: 0 | BK13: 0 | BL13: 0 | BM13: 0 | BN13: 0 | BO13: 0 | BP13: 0 | BQ13: 0 | BR13: 0 | BS13: 0 | BT13: 0 | BU13: 0 | BV13: 0 | BW13: 0 | BX13: 0 | BY13: 0 | BZ13: 0 | CA13: 0
... A68: 44074 | B68: 0 | C68: 0 | D68: 0 | E68: 0 | F68: 0 | G68: 0 | H68: 0 | I68: 0 | J68: 0 | K68: 0 | L68: 0 | M68: 0 | N68: 0 | O68: 0 | P68: 0 | Q68: 0 | R68: 0 | S68: 0 | T68: 0 | U68: 0 | V68: 0 | W68: 6.065074 | X68: 0 | Y68: 0 | Z68: 0 | AA68: 0 | AB68: 0 | AC68: 0 | AD68: 0 | AE68: 0 | AF68: 0 | AG68: 0 | AH68: 0 | AI68: 0 | AJ68: 0 | AK68: 0 | AL68: 0 | AM68: 0 | AN68: 0 | AO68: 0 | AP68: 0 | AQ68: 0 | AR68: 0 | AS68: 0 | AT68: 0 | AU68: 6.252603 | AV68: 0 | AW68: 0 | AX68: -16.595791 | AY68: 0 | AZ68: 0 | BA68: 0 | BB68: 0 | BC68: 0 | BD68: 0 | BE68: 0 | BF68: 0 | BG68: 0 | BH68: 0 | BI68: 0 | BJ68: 0 | BK68: 0 | BL68: 0 | BM68: 0 | BN68: 0 | BO68: 0 | BP68: 0 | BQ68: 0 | BR68: 0 | BS68: 0 | BT68: 0 | BU68: 0 | BV68: 0 | BW68: 0 | BX68: 0 | BY68: 0 | BZ68: 0 | CA68: 0
A69: 44104 | B69: 0 | C69: 0 | D69: 0 | E69: 0 | F69: 0 | G69: 0 | H69: 0 | I69: 0 | J69: 0 | K69: 0 | L69: 0 | M69: 0 | N69: 0 | O69: 0 | P69: 0 | Q69: 0 | R69: 0 | S69: 0 | T69: 0 | U69: 0 | V69: 0 | W69: 6.860782 | X69: 0 | Y69: 0 | Z69: 0 | AA69: 0 | AB69: 0 | AC69: 0 | AD69: 0 | AE69: 0 | AF69: 0 | AG69: 0 | AH69: 0 | AI69: 0 | AJ69: 0 | AK69: 0 | AL69: 0 | AM69: 0 | AN69: 0 | AO69: 0 | AP69: 0 | AQ69: 0 | AR69: 0 | AS69: 0 | AT69: 0 | AU69: 7.092044 | AV69: 0 | AW69: 0 | AX69: -14.362157 | AY69: 0 | AZ69: 0 | BA69: 0 | BB69: 0 | BC69: 0 | BD69: 0 | BE69: 0 | BF69: 0 | BG69: 0 | BH69: #N/A N/A | BI69: 0 | BJ69: 0 | BK69: 0 | BL69: 21.102908 | BM69: 0 | BN69: 0 | BO69: 0 | BP69: 0 | BQ69: 0 | BR69: 0 | BS69: 0 | BT69: 0 | BU69: 0 | BV69: 0 | BW69: 0 | BX69: 0 | BY69: 0 | BZ69: 0 | CA69: 0
A70: 44134 | B70: 0 | C70: 0 | D70: 0 | E70: 0 | F70: 0 | G70: 0 | H70: 0 | I70: 0 | J70: 0 | K70: 0 | L70: 0 | M70: 0 | N70: 0 | O70: 0 | P70: 0 | Q70: 0 | R70: 0 | S70: 0 | T70: 0 | U70: 0 | V70: 0 | W70: 6.951555 | X70: 0 | Y70: 0 | Z70: 0 | AA70: 0 | AB70: 0 | AC70: 0 | AD70: 0 | AE70: 0 | AF70: 0 | AG70: 0 | AH70: 0 | AI70: 0 | AJ70: 0 | AK70: 0 | AL70: 0 | AM70: 0 | AN70: 0 | AO70: 0 | AP70: 0 | AQ70: 0 | AR70: 0 | AS70: 0 | AT70: 0 | AU70: 7.756326 | AV70: 0 | AW70: 0 | AX70: -13.840871 | AY70: 0 | AZ70: 0 | BA70: 0 | BB70: 0 | BC70: 0 | BD70: 0 | BE70: 0 | BF70: 0 | BG70: 0 | BH70: 0 | BI70: 0 | BJ70: 0 | BK70: 0 | BL70: 21.994836 | BM70: 0 | BN70: 0 | BO70: 0 | BP70: 0 | BQ70: 0 | BR70: 0 | BS70: 0 | BT70: 0 | BU70: 0 | BV70: 0 | BW70: 0 | BX70: 0 | BY70: 0 | BZ70: 0 | CA70: 0
A71: 44165 | B71: 0 | C71: 0 | D71: 0 | E71: 0 | F71: 0 | G71: 6.250564 | H71: 0 | I71: 0 | J71: 0 | K71: 0 | L71: 0 | M71: 0 | N71: 0 | O71: 0 | P71: 0 | Q71: 0 | R71: 0 | S71: 0 | T71: 0 | U71: 0 | V71: 0 | W71: 6.857788 | X71: 0 | Y71: 0 | Z71: 0 | AA71: 0 | AB71: 0 | AC71: 0 | AD71: 0 | AE71: 0 | AF71: 0 | AG71: 0 | AH71: 0 | AI71: 0 | AJ71: 0 | AK71: 0 | AL71: 0 | AM71: 0 | AN71: 0 | AO71: 0 | AP71: 0 | AQ71: 0 | AR71: 0 | AS71: 0 | AT71: 0 | AU71: 7.918207 | AV71: 0 | AW71: 0 | AX71: -14.130987 | AY71: 0 | AZ71: 0 | BA71: 0 | BB71: 0 | BC71: 0 | BD71: 0 | BE71: 0 | BF71: 0 | BG71: 0 | BH71: 0 | BI71: 0 | BJ71: 0 | BK71: 0 | BL71: 22.00101 | BM71: 0 | BN71: 0 | BO71: 0 | BP71: 0 | BQ71: #N/A N/A | BR71: #N/A N/A | BS71: 0 | BT71: 0 | BU71: 0 | BV71: 0 | BW71: 0 | BX71: 0 | BY71: 0 | BZ71: 0 | CA71: 0
A72: 44196 | B72: 0 | C72: 0 | D72: 7.016139 | E72: 0 | F72: 0 | G72: 5.175638 | H72: 0 | I72: 0 | J72: 0 | K72: 0 | L72: 0 | M72: 0 | N72: 0 | O72: 0 | P72: 0 | Q72: 0 | R72: 0 | S72: 0 | T72: 0 | U72: 0 | V72: 0 | W72: 6.368043 | X72: 0 | Y72: 0 | Z72: 0 | AA72: 0 | AB72: 0 | AC72: 0 | AD72: 0 | AE72: 0 | AF72: 0 | AG72: 0 | AH72: 5.175062 | AI72: 0 | AJ72: 0 | AK72: 0 | AL72: 0 | AM72: 0 | AN72: 0 | AO72: 0 | AP72: 0 | AQ72: 0 | AR72: 0 | AS72: 0 | AT72: 0 | AU72: 6.740005 | AV72: 0 | AW72: 0 | AX72: -16.724738 | AY72: 0 | AZ72: 0 | BA72: 0 | BB72: 0 | BC72: 0 | BD72: 0 | BE72: 0 | BF72: 0 | BG72: 0 | BH72: 0 | BI72: 0 | BJ72: 0 | BK72: 0 | BL72: 19.634097 | BM72: 0 | BN72: 0 | BO72: 0 | BP72: 0 | BQ72: 0 | BR72: 0 | BS72: 0 | BT72: 0 | BU72: 0 | BV72: 0 | BW72: 0 | BX72: 0 | BY72: 0 | BZ72: 0 | CA72: 0
A73: 44225 | B73: 0 | C73: 0 | D73: 7.425704 | E73: 0 | F73: 0 | G73: 5.770641 | H73: 0 | I73: 0 | J73: 0 | K73: 0 | L73: 0 | M73: 0 | N73: 0 | O73: 0 | P73: 0 | Q73: 0 | R73: 0 | S73: 0 | T73: 0 | U73: 0 | V73: 5.946649 | W73: 6.867319 | X73: 0 | Y73: 0 | Z73: 0 | AA73: 6.411065 | AB73: 0 | AC73: 0 | AD73: 0 | AE73: 0 | AF73: 0 | AG73: 0 | AH73: 5.693853 | AI73: 0 | AJ73: 0 | AK73: 0 | AL73: 0 | AM73: 0 | AN73: 0 | AO73: 0 | AP73: 0 | AQ73: 0 | AR73: 0 | AS73: 0 | AT73: 0 | AU73: 7.216331 | AV73: 0 | AW73: 0 | AX73: -15.19154 | AY73: 0 | AZ73: 0 | BA73: 0 | BB73: 0 | BC73: 0 | BD73: 0 | BE73: 0 | BF73: 0 | BG73: 0 | BH73: 0 | BI73: 0 | BJ73: 0 | BK73: 0 | BL73: 20.262031 | BM73: 0 | BN73: 0 | BO73: 0 | BP73: 0 | BQ73: 0 | BR73: 0 | BS73: 0 | BT73: 0 | BU73: 0 | BV73: 0 | BW73: 0 | BX73: 0 | BY73: 0 | BZ73: 0 | CA73: 0
A74: 44253 | B74: 0 | C74: 0 | D74: 7.946573 | E74: 0 | F74: 0 | G74: 6.519414 | H74: 0 | I74: 0 | J74: 6.169827 | K74: 0 | L74: 0 | M74: 0 | N74: 0 | O74: 0 | P74: 0 | Q74: 0 | R74: 0 | S74: 0 | T74: 0 | U74: 0 | V74: 6.619731 | W74: 7.196328 | X74: 0 | Y74: 0 | Z74: 0 | AA74: 7.095415 | AB74: 0 | AC74: 0 | AD74: 0 | AE74: 0 | AF74: 0 | AG74: 0 | AH74: 6.193725 | AI74: 0 | AJ74: 0 | AK74: 0 | AL74: 6.562001 | AM74: 0 | AN74: 0 | AO74: 0 | AP74: 0 | AQ74: 0 | AR74: 0 | AS74: 0 | AT74: 0 | AU74: 8.211284 | AV74: 0 | AW74: 0 | AX74: -13.309175 | AY74: 0 | AZ74: 0 | BA74: 0 | BB74: 0 | BC74: 0 | BD74: 0 | BE74: 0 | BF74: 0 | BG74: 0 | BH74: 0 | BI74: 0 | BJ74: 0 | BK74: 0 | BL74: 22.092535 | BM74: 0 | BN74: 0 | BO74: 0 | BP74: 0 | BQ74: 0 | BR74: 0 | BS74: 0 | BT74: 0 | BU74: 0 | BV74: 0 | BW74: 0 | BX74: 0 | BY74: 0 | BZ74: 0 | CA74: 0
A75: 44286 | B75: 0 | C75: 0 | D75: 8.612107 | E75: 0 | F75: 0 | G75: 7.424388 | H75: 0 | I75: 0 | J75: 7.381324 | K75: 8.240552 | L75: 0 | M75: 0 | N75: 0 | O75: 0 | P75: 0 | Q75: 0 | R75: 0 | S75: 0 | T75: 0 | U75: 0 | V75: 7.753749 | W75: 8.093361 | X75: 0 | Y75: 0 | Z75: 0 | AA75: 7.932113 | AB75: 0 | AC75: 0 | AD75: 0 | AE75: 0 | AF75: 0 | AG75: 0 | AH75: 7.359721 | AI75: 0 | AJ75: 0 | AK75: 0 | AL75: 7.492602 | AM75: 0 | AN75: 0 | AO75: 0 | AP75: 0 | AQ75: 0 | AR75: 0 | AS75: 0 | AT75: 0 | AU75: 9.091419 | AV75: 0 | AW75: 0 | AX75: -11.018105 | AY75: 0 | AZ75: 0 | BA75: 0 | BB75: 0 | BC75: 0 | BD75: 0 | BE75: 0 | BF75: 0 | BG75: 0 | BH75: 0 | BI75: 0 | BJ75: 0 | BK75: 0 | BL75: 22.905216 | BM75: 0 | BN75: 0 | BO75: #N/A N/A | BP75: #N/A N/A | BQ75: 0 | BR75: 0 | BS75: 0 | BT75: 0 | BU75: 0 | BV75: 0 | BW75: 0 | BX75: 17.88301 | BY75: 0 | BZ75: 0 | CA75: 0
A76: 44316 | B76: 0 | C76: 0 | D76: 8.301665 | E76: 0 | F76: 0 | G76: 6.971856 | H76: 0 | I76: 0 | J76: 6.900718 | K76: 0 | L76: 0 | M76: 0 | N76: 0 | O76: 0 | P76: 0 | Q76: 0 | R76: 0 | S76: 0 | T76: 0 | U76: 0 | V76: 7.459396 | W76: 8.114371 | X76: 0 | Y76: 0 | Z76: 0 | AA76: 7.783048 | AB76: 0 | AC76: 0 | AD76: 0 | AE76: 0 | AF76: 0 | AG76: 0 | AH76: 6.875638 | AI76: 0 | AJ76: 0 | AK76: 0 | AL76: 7.088637 | AM76: 0 | AN76: 0 | AO76: 0 | AP76: 0 | AQ76: 0 | AR76: 0 | AS76: 0 | AT76: 0 | AU76: 8.993775 | AV76: 0 | AW76: 0 | AX76: -12.693663 | AY76: 0 | AZ76: 0 | BA76: 0 | BB76: 0 | BC76: 0 | BD76: 0 | BE76: 0 | BF76: 0 | BG76: 0 | BH76: 0 | BI76: 0 | BJ76: 0 | BK76: 0 | BL76: 21.845182 | BM76: 0 | BN76: 0 | BO76: 0 | BP76: 0 | BQ76: 0 | BR76: 0 | BS76: 0 | BT76: 0 | BU76: 0 | BV76: 0 | BW76: 0 | BX76: 16.854075 | BY76: 0 | BZ76: 0 | CA76: -0.58644
A77: 44347 | B77: 0 | C77: 0 | D77: 8.050559 | E77: 0 | F77: 0 | G77: 6.972774 | H77: 0 | I77: 0 | J77: 6.930818 | K77: 0 | L77: 0 | M77: 0 | N77: 0 | O77: 0 | P77: 0 | Q77: 0 | R77: 0 | S77: 0 | T77: 0 | U77: 0 | V77: 7.668259 | W77: 7.628552 | X77: 0 | Y77: 0 | Z77: 0 | AA77: 7.583789 | AB77: 0 | AC77: 0 | AD77: 7.52348 | AE77: 0 | AF77: 0 | AG77: 0 | AH77: 6.9506 | AI77: 0 | AJ77: 0 | AK77: 0 | AL77: 7.006507 | AM77: 0 | AN77: 0 | AO77: 0 | AP77: 0 | AQ77: 0 | AR77: 0 | AS77: 0 | AT77: 0 | AU77: 8.806118 | AV77: 0 | AW77: 0 | AX77: -13.430531 | AY77: 0 | AZ77: 0 | BA77: 0 | BB77: 0 | BC77: 0 | BD77: 0 | BE77: 0 | BF77: 0 | BG77: 0 | BH77: 0 | BI77: 0 | BJ77: 0 | BK77: 0 | BL77: 21.432669 | BM77: 0 | BN77: 0 | BO77: 0 | BP77: 0 | BQ77: 0 | BR77: 0 | BS77: 0 | BT77: 0 | BU77: 0 | BV77: 0 | BW77: 0 | BX77: 13.915943 | BY77: 0 | BZ77: 0 | CA77: -0.985078
